<?xml version="1.0" ?>
<robot name="tree0">
	<material name="blue">
		<color rgba="0 0 0.8 1"/>
	</material>
	<material name="green">
		<color rgba="0 0.6 0 0.8"/>
	</material>
	<material name="brown">
		<color rgba="0.3 0.15 0.05 1.0"/>
	</material>
	<link name="base_link">
		<visual>
			<origin rpy="0 0 0" xyz="0 0 0"/>
			<geometry>
				<box size="1 1 0.02"/>
			</geometry>
			<material name="green"/>
		</visual>
		<collision>
			<origin rpy="0 0 0" xyz="0 0 0"/>
			<geometry>
				<box size="1 1 0.02"/>
			</geometry>
		</collision>
	</link>
	<joint name="joint0_base" type="fixed">
		<parent link="base_link"/>
		<origin rpy="0 0 0" xyz="0 0 0.01"/>
		<child link="link0_base"/>
	</joint>
	<link name="link0_base">
		<inertial>
			<mass value="0.001"/>
			<inertia ixx="0.001" ixy="0" ixz="0" iyy="0.001" iyz="0" izz="0.001"/>
		</inertial>
	</link>
	<joint name="joint0_x_to_1" type="revolute">
		<safety_controller k_position="100.0" k_velocity="40.0" soft_lower_limit="-2.8973" soft_upper_limit="2.8973"/>
		<parent link="link0_base"/>
		<child link="link0_x_to_1"/>
		<origin rpy="0 0 0" xyz="0 0 0"/>
		<axis xyz="1 0 0"/>
		<dynamics damping="10.0"/>
		<limit effort="10" lower="-3.1416" upper="3.1416" velocity="3"/>
		<limit effort="87" lower="-2.9671" upper="2.9671" velocity="2.1750"/>
	</joint>
	<link name="link0_x_to_1">
		<inertial>
			<mass value="0.001"/>
			<inertia ixx="0.001" ixy="0" ixz="0" iyy="0.001" iyz="0" izz="0.001"/>
		</inertial>
	</link>
	<joint name="joint0_y_to_1" type="revolute">
		<safety_controller k_position="100.0" k_velocity="40.0" soft_lower_limit="-2.8973" soft_upper_limit="2.8973"/>
		<parent link="link0_x_to_1"/>
		<child link="link0_y_to_1"/>
		<origin rpy="0 0 0" xyz="0 0 0"/>
		<axis xyz="0 1 0"/>
		<dynamics damping="10.0"/>
		<limit effort="10" lower="-3.1416" upper="3.1416" velocity="3"/>
		<limit effort="87" lower="-2.9671" upper="2.9671" velocity="2.1750"/>
	</joint>
	<link name="link0_y_to_1">
		<inertial>
			<mass value="0.001"/>
			<inertia ixx="0.001" ixy="0" ixz="0" iyy="0.001" iyz="0" izz="0.001"/>
		</inertial>
	</link>
	<joint name="joint0_z_to_1" type="revolute">
		<safety_controller k_position="100.0" k_velocity="40.0" soft_lower_limit="-2.8973" soft_upper_limit="2.8973"/>
		<parent link="link0_y_to_1"/>
		<child link="link_0_to_1"/>
		<origin rpy="0 0 0" xyz="0 0 0"/>
		<axis xyz="0 0 1"/>
		<dynamics damping="10.0"/>
		<limit effort="10" lower="-3.1416" upper="3.1416" velocity="3"/>
		<limit effort="87" lower="-2.9671" upper="2.9671" velocity="2.1750"/>
	</joint>
	<link name="link_0_to_1">
		<visual>
			<origin rpy="-0.07068670045067607 0.0 1.9224209686311704" xyz="-0.01657661031609756 -0.006081472754599516 0.24937568381773573"/>
			<geometry>
				<cylinder length="0.49999999999999994" radius="0.019767502251488673"/>
			</geometry>
			<material name="brown"/>
		</visual>
		<collision>
			<origin rpy="-0.07068670045067607 0.0 1.9224209686311704" xyz="-0.01657661031609756 -0.006081472754599516 0.24937568381773573"/>
			<geometry>
				<cylinder length="0.49999999999999994" radius="0.019767502251488673"/>
			</geometry>
		</collision>
	</link>
	<joint name="joint1_base" type="fixed">
		<parent link="link_0_to_1"/>
		<origin rpy="0 0 0" xyz="-0.03315322063219512 -0.012162945509199032 0.49875136763547145"/>
		<child link="link1_base"/>
	</joint>
	<link name="link1_base">
		<inertial>
			<mass value="0.001"/>
			<inertia ixx="0.001" ixy="0" ixz="0" iyy="0.001" iyz="0" izz="0.001"/>
		</inertial>
	</link>
	<joint name="joint1_x_to_2" type="revolute">
		<safety_controller k_position="100.0" k_velocity="40.0" soft_lower_limit="-2.8973" soft_upper_limit="2.8973"/>
		<parent link="link1_base"/>
		<child link="link1_x_to_2"/>
		<origin rpy="0 0 0" xyz="0 0 0"/>
		<axis xyz="1 0 0"/>
		<dynamics damping="10.0"/>
		<limit effort="10" lower="-3.1416" upper="3.1416" velocity="3"/>
		<limit effort="87" lower="-2.9671" upper="2.9671" velocity="2.1750"/>
	</joint>
	<link name="link1_x_to_2">
		<inertial>
			<mass value="0.001"/>
			<inertia ixx="0.001" ixy="0" ixz="0" iyy="0.001" iyz="0" izz="0.001"/>
		</inertial>
	</link>
	<joint name="joint1_y_to_2" type="revolute">
		<safety_controller k_position="100.0" k_velocity="40.0" soft_lower_limit="-2.8973" soft_upper_limit="2.8973"/>
		<parent link="link1_x_to_2"/>
		<child link="link1_y_to_2"/>
		<origin rpy="0 0 0" xyz="0 0 0"/>
		<axis xyz="0 1 0"/>
		<dynamics damping="10.0"/>
		<limit effort="10" lower="-3.1416" upper="3.1416" velocity="3"/>
		<limit effort="87" lower="-2.9671" upper="2.9671" velocity="2.1750"/>
	</joint>
	<link name="link1_y_to_2">
		<inertial>
			<mass value="0.001"/>
			<inertia ixx="0.001" ixy="0" ixz="0" iyy="0.001" iyz="0" izz="0.001"/>
		</inertial>
	</link>
	<joint name="joint1_z_to_2" type="revolute">
		<safety_controller k_position="100.0" k_velocity="40.0" soft_lower_limit="-2.8973" soft_upper_limit="2.8973"/>
		<parent link="link1_y_to_2"/>
		<child link="link_1_to_2"/>
		<origin rpy="0 0 0" xyz="0 0 0"/>
		<axis xyz="0 0 1"/>
		<dynamics damping="10.0"/>
		<limit effort="10" lower="-3.1416" upper="3.1416" velocity="3"/>
		<limit effort="87" lower="-2.9671" upper="2.9671" velocity="2.1750"/>
	</joint>
	<joint name="joint1_x_to_3" type="revolute">
		<safety_controller k_position="100.0" k_velocity="40.0" soft_lower_limit="-2.8973" soft_upper_limit="2.8973"/>
		<parent link="link1_base"/>
		<child link="link1_x_to_3"/>
		<origin rpy="0 0 0" xyz="0 0 0"/>
		<axis xyz="1 0 0"/>
		<dynamics damping="10.0"/>
		<limit effort="10" lower="-3.1416" upper="3.1416" velocity="3"/>
		<limit effort="87" lower="-2.9671" upper="2.9671" velocity="2.1750"/>
	</joint>
	<link name="link1_x_to_3">
		<inertial>
			<mass value="0.001"/>
			<inertia ixx="0.001" ixy="0" ixz="0" iyy="0.001" iyz="0" izz="0.001"/>
		</inertial>
	</link>
	<joint name="joint1_y_to_3" type="revolute">
		<safety_controller k_position="100.0" k_velocity="40.0" soft_lower_limit="-2.8973" soft_upper_limit="2.8973"/>
		<parent link="link1_x_to_3"/>
		<child link="link1_y_to_3"/>
		<origin rpy="0 0 0" xyz="0 0 0"/>
		<axis xyz="0 1 0"/>
		<dynamics damping="10.0"/>
		<limit effort="10" lower="-3.1416" upper="3.1416" velocity="3"/>
		<limit effort="87" lower="-2.9671" upper="2.9671" velocity="2.1750"/>
	</joint>
	<link name="link1_y_to_3">
		<inertial>
			<mass value="0.001"/>
			<inertia ixx="0.001" ixy="0" ixz="0" iyy="0.001" iyz="0" izz="0.001"/>
		</inertial>
	</link>
	<joint name="joint1_z_to_3" type="revolute">
		<safety_controller k_position="100.0" k_velocity="40.0" soft_lower_limit="-2.8973" soft_upper_limit="2.8973"/>
		<parent link="link1_y_to_3"/>
		<child link="link_1_to_3"/>
		<origin rpy="0 0 0" xyz="0 0 0"/>
		<axis xyz="0 0 1"/>
		<dynamics damping="10.0"/>
		<limit effort="10" lower="-3.1416" upper="3.1416" velocity="3"/>
		<limit effort="87" lower="-2.9671" upper="2.9671" velocity="2.1750"/>
	</joint>
	<joint name="joint1_x_to_7" type="revolute">
		<safety_controller k_position="100.0" k_velocity="40.0" soft_lower_limit="-2.8973" soft_upper_limit="2.8973"/>
		<parent link="link1_base"/>
		<child link="link1_x_to_7"/>
		<origin rpy="0 0 0" xyz="0 0 0"/>
		<axis xyz="1 0 0"/>
		<dynamics damping="10.0"/>
		<limit effort="10" lower="-3.1416" upper="3.1416" velocity="3"/>
		<limit effort="87" lower="-2.9671" upper="2.9671" velocity="2.1750"/>
	</joint>
	<link name="link1_x_to_7">
		<inertial>
			<mass value="0.001"/>
			<inertia ixx="0.001" ixy="0" ixz="0" iyy="0.001" iyz="0" izz="0.001"/>
		</inertial>
	</link>
	<joint name="joint1_y_to_7" type="revolute">
		<safety_controller k_position="100.0" k_velocity="40.0" soft_lower_limit="-2.8973" soft_upper_limit="2.8973"/>
		<parent link="link1_x_to_7"/>
		<child link="link1_y_to_7"/>
		<origin rpy="0 0 0" xyz="0 0 0"/>
		<axis xyz="0 1 0"/>
		<dynamics damping="10.0"/>
		<limit effort="10" lower="-3.1416" upper="3.1416" velocity="3"/>
		<limit effort="87" lower="-2.9671" upper="2.9671" velocity="2.1750"/>
	</joint>
	<link name="link1_y_to_7">
		<inertial>
			<mass value="0.001"/>
			<inertia ixx="0.001" ixy="0" ixz="0" iyy="0.001" iyz="0" izz="0.001"/>
		</inertial>
	</link>
	<joint name="joint1_z_to_7" type="revolute">
		<safety_controller k_position="100.0" k_velocity="40.0" soft_lower_limit="-2.8973" soft_upper_limit="2.8973"/>
		<parent link="link1_y_to_7"/>
		<child link="link_1_to_7"/>
		<origin rpy="0 0 0" xyz="0 0 0"/>
		<axis xyz="0 0 1"/>
		<dynamics damping="10.0"/>
		<limit effort="10" lower="-3.1416" upper="3.1416" velocity="3"/>
		<limit effort="87" lower="-2.9671" upper="2.9671" velocity="2.1750"/>
	</joint>
	<joint name="joint1_x_to_15" type="revolute">
		<safety_controller k_position="100.0" k_velocity="40.0" soft_lower_limit="-2.8973" soft_upper_limit="2.8973"/>
		<parent link="link1_base"/>
		<child link="link1_x_to_15"/>
		<origin rpy="0 0 0" xyz="0 0 0"/>
		<axis xyz="1 0 0"/>
		<dynamics damping="10.0"/>
		<limit effort="10" lower="-3.1416" upper="3.1416" velocity="3"/>
		<limit effort="87" lower="-2.9671" upper="2.9671" velocity="2.1750"/>
	</joint>
	<link name="link1_x_to_15">
		<inertial>
			<mass value="0.001"/>
			<inertia ixx="0.001" ixy="0" ixz="0" iyy="0.001" iyz="0" izz="0.001"/>
		</inertial>
	</link>
	<joint name="joint1_y_to_15" type="revolute">
		<safety_controller k_position="100.0" k_velocity="40.0" soft_lower_limit="-2.8973" soft_upper_limit="2.8973"/>
		<parent link="link1_x_to_15"/>
		<child link="link1_y_to_15"/>
		<origin rpy="0 0 0" xyz="0 0 0"/>
		<axis xyz="0 1 0"/>
		<dynamics damping="10.0"/>
		<limit effort="10" lower="-3.1416" upper="3.1416" velocity="3"/>
		<limit effort="87" lower="-2.9671" upper="2.9671" velocity="2.1750"/>
	</joint>
	<link name="link1_y_to_15">
		<inertial>
			<mass value="0.001"/>
			<inertia ixx="0.001" ixy="0" ixz="0" iyy="0.001" iyz="0" izz="0.001"/>
		</inertial>
	</link>
	<joint name="joint1_z_to_15" type="revolute">
		<safety_controller k_position="100.0" k_velocity="40.0" soft_lower_limit="-2.8973" soft_upper_limit="2.8973"/>
		<parent link="link1_y_to_15"/>
		<child link="link_1_to_15"/>
		<origin rpy="0 0 0" xyz="0 0 0"/>
		<axis xyz="0 0 1"/>
		<dynamics damping="10.0"/>
		<limit effort="10" lower="-3.1416" upper="3.1416" velocity="3"/>
		<limit effort="87" lower="-2.9671" upper="2.9671" velocity="2.1750"/>
	</joint>
	<link name="link_1_to_2">
		<visual>
			<origin rpy="-0.07109109846405816 0.0 1.9064146513430897" xyz="-0.010898578467747656 -0.0038015824437255957 0.1620895399410644"/>
			<geometry>
				<cylinder length="0.325" radius="0.015470731700886888"/>
			</geometry>
			<material name="brown"/>
		</visual>
		<collision>
			<origin rpy="-0.07109109846405816 0.0 1.9064146513430897" xyz="-0.010898578467747656 -0.0038015824437255957 0.1620895399410644"/>
			<geometry>
				<cylinder length="0.325" radius="0.015470731700886888"/>
			</geometry>
		</collision>
	</link>
	<link name="link_1_to_3">
		<visual>
			<origin rpy="-1.8874217475119686 2.220446049250313e-16 2.5243495273945693" xyz="-0.05809570154716315 -0.08185315234710039 -0.03288755900922602"/>
			<geometry>
				<cylinder length="0.21125000000000005" radius="0.009680000000000005"/>
			</geometry>
			<material name="brown"/>
		</visual>
		<collision>
			<origin rpy="-1.8874217475119686 2.220446049250313e-16 2.5243495273945693" xyz="-0.05809570154716315 -0.08185315234710039 -0.03288755900922602"/>
			<geometry>
				<cylinder length="0.21125000000000005" radius="0.009680000000000005"/>
			</geometry>
		</collision>
	</link>
	<link name="link_1_to_7">
		<visual>
			<origin rpy="-1.6962353809226909 2.220446049250313e-16 -0.6339877735152396" xyz="0.04034982778847735 0.054879784121804526 -0.008589607455923381"/>
			<geometry>
				<cylinder length="0.13731250000000003" radius="0.008800000000000002"/>
			</geometry>
			<material name="brown"/>
		</visual>
		<collision>
			<origin rpy="-1.6962353809226909 2.220446049250313e-16 -0.6339877735152396" xyz="0.04034982778847735 0.054879784121804526 -0.008589607455923381"/>
			<geometry>
				<cylinder length="0.13731250000000003" radius="0.008800000000000002"/>
			</geometry>
		</collision>
	</link>
	<link name="link_1_to_15">
		<visual>
			<origin rpy="-1.5707229069046882 2.220446049250313e-16 1.0649823684612654" xyz="-0.03903844144019336 0.021622445739363023 3.2764773161830796e-06"/>
			<geometry>
				<cylinder length="0.08925312500000004" radius="0.008"/>
			</geometry>
			<material name="brown"/>
		</visual>
		<collision>
			<origin rpy="-1.5707229069046882 2.220446049250313e-16 1.0649823684612654" xyz="-0.03903844144019336 0.021622445739363023 3.2764773161830796e-06"/>
			<geometry>
				<cylinder length="0.08925312500000004" radius="0.008"/>
			</geometry>
		</collision>
	</link>
	<joint name="joint2_base" type="fixed">
		<parent link="link_1_to_2"/>
		<origin rpy="0 0 0" xyz="-0.02179715693549531 -0.0076031648874511915 0.3241790798821288"/>
		<child link="link2_base"/>
	</joint>
	<link name="link2_base">
		<inertial>
			<mass value="0.001"/>
			<inertia ixx="0.001" ixy="0" ixz="0" iyy="0.001" iyz="0" izz="0.001"/>
		</inertial>
	</link>
	<joint name="joint2_x_to_4" type="revolute">
		<safety_controller k_position="100.0" k_velocity="40.0" soft_lower_limit="-2.8973" soft_upper_limit="2.8973"/>
		<parent link="link2_base"/>
		<child link="link2_x_to_4"/>
		<origin rpy="0 0 0" xyz="0 0 0"/>
		<axis xyz="1 0 0"/>
		<dynamics damping="10.0"/>
		<limit effort="10" lower="-3.1416" upper="3.1416" velocity="3"/>
		<limit effort="87" lower="-2.9671" upper="2.9671" velocity="2.1750"/>
	</joint>
	<link name="link2_x_to_4">
		<inertial>
			<mass value="0.001"/>
			<inertia ixx="0.001" ixy="0" ixz="0" iyy="0.001" iyz="0" izz="0.001"/>
		</inertial>
	</link>
	<joint name="joint2_y_to_4" type="revolute">
		<safety_controller k_position="100.0" k_velocity="40.0" soft_lower_limit="-2.8973" soft_upper_limit="2.8973"/>
		<parent link="link2_x_to_4"/>
		<child link="link2_y_to_4"/>
		<origin rpy="0 0 0" xyz="0 0 0"/>
		<axis xyz="0 1 0"/>
		<dynamics damping="10.0"/>
		<limit effort="10" lower="-3.1416" upper="3.1416" velocity="3"/>
		<limit effort="87" lower="-2.9671" upper="2.9671" velocity="2.1750"/>
	</joint>
	<link name="link2_y_to_4">
		<inertial>
			<mass value="0.001"/>
			<inertia ixx="0.001" ixy="0" ixz="0" iyy="0.001" iyz="0" izz="0.001"/>
		</inertial>
	</link>
	<joint name="joint2_z_to_4" type="revolute">
		<safety_controller k_position="100.0" k_velocity="40.0" soft_lower_limit="-2.8973" soft_upper_limit="2.8973"/>
		<parent link="link2_y_to_4"/>
		<child link="link_2_to_4"/>
		<origin rpy="0 0 0" xyz="0 0 0"/>
		<axis xyz="0 0 1"/>
		<dynamics damping="10.0"/>
		<limit effort="10" lower="-3.1416" upper="3.1416" velocity="3"/>
		<limit effort="87" lower="-2.9671" upper="2.9671" velocity="2.1750"/>
	</joint>
	<joint name="joint2_x_to_8" type="revolute">
		<safety_controller k_position="100.0" k_velocity="40.0" soft_lower_limit="-2.8973" soft_upper_limit="2.8973"/>
		<parent link="link2_base"/>
		<child link="link2_x_to_8"/>
		<origin rpy="0 0 0" xyz="0 0 0"/>
		<axis xyz="1 0 0"/>
		<dynamics damping="10.0"/>
		<limit effort="10" lower="-3.1416" upper="3.1416" velocity="3"/>
		<limit effort="87" lower="-2.9671" upper="2.9671" velocity="2.1750"/>
	</joint>
	<link name="link2_x_to_8">
		<inertial>
			<mass value="0.001"/>
			<inertia ixx="0.001" ixy="0" ixz="0" iyy="0.001" iyz="0" izz="0.001"/>
		</inertial>
	</link>
	<joint name="joint2_y_to_8" type="revolute">
		<safety_controller k_position="100.0" k_velocity="40.0" soft_lower_limit="-2.8973" soft_upper_limit="2.8973"/>
		<parent link="link2_x_to_8"/>
		<child link="link2_y_to_8"/>
		<origin rpy="0 0 0" xyz="0 0 0"/>
		<axis xyz="0 1 0"/>
		<dynamics damping="10.0"/>
		<limit effort="10" lower="-3.1416" upper="3.1416" velocity="3"/>
		<limit effort="87" lower="-2.9671" upper="2.9671" velocity="2.1750"/>
	</joint>
	<link name="link2_y_to_8">
		<inertial>
			<mass value="0.001"/>
			<inertia ixx="0.001" ixy="0" ixz="0" iyy="0.001" iyz="0" izz="0.001"/>
		</inertial>
	</link>
	<joint name="joint2_z_to_8" type="revolute">
		<safety_controller k_position="100.0" k_velocity="40.0" soft_lower_limit="-2.8973" soft_upper_limit="2.8973"/>
		<parent link="link2_y_to_8"/>
		<child link="link_2_to_8"/>
		<origin rpy="0 0 0" xyz="0 0 0"/>
		<axis xyz="0 0 1"/>
		<dynamics damping="10.0"/>
		<limit effort="10" lower="-3.1416" upper="3.1416" velocity="3"/>
		<limit effort="87" lower="-2.9671" upper="2.9671" velocity="2.1750"/>
	</joint>
	<joint name="joint2_x_to_14" type="revolute">
		<safety_controller k_position="100.0" k_velocity="40.0" soft_lower_limit="-2.8973" soft_upper_limit="2.8973"/>
		<parent link="link2_base"/>
		<child link="link2_x_to_14"/>
		<origin rpy="0 0 0" xyz="0 0 0"/>
		<axis xyz="1 0 0"/>
		<dynamics damping="10.0"/>
		<limit effort="10" lower="-3.1416" upper="3.1416" velocity="3"/>
		<limit effort="87" lower="-2.9671" upper="2.9671" velocity="2.1750"/>
	</joint>
	<link name="link2_x_to_14">
		<inertial>
			<mass value="0.001"/>
			<inertia ixx="0.001" ixy="0" ixz="0" iyy="0.001" iyz="0" izz="0.001"/>
		</inertial>
	</link>
	<joint name="joint2_y_to_14" type="revolute">
		<safety_controller k_position="100.0" k_velocity="40.0" soft_lower_limit="-2.8973" soft_upper_limit="2.8973"/>
		<parent link="link2_x_to_14"/>
		<child link="link2_y_to_14"/>
		<origin rpy="0 0 0" xyz="0 0 0"/>
		<axis xyz="0 1 0"/>
		<dynamics damping="10.0"/>
		<limit effort="10" lower="-3.1416" upper="3.1416" velocity="3"/>
		<limit effort="87" lower="-2.9671" upper="2.9671" velocity="2.1750"/>
	</joint>
	<link name="link2_y_to_14">
		<inertial>
			<mass value="0.001"/>
			<inertia ixx="0.001" ixy="0" ixz="0" iyy="0.001" iyz="0" izz="0.001"/>
		</inertial>
	</link>
	<joint name="joint2_z_to_14" type="revolute">
		<safety_controller k_position="100.0" k_velocity="40.0" soft_lower_limit="-2.8973" soft_upper_limit="2.8973"/>
		<parent link="link2_y_to_14"/>
		<child link="link_2_to_14"/>
		<origin rpy="0 0 0" xyz="0 0 0"/>
		<axis xyz="0 0 1"/>
		<dynamics damping="10.0"/>
		<limit effort="10" lower="-3.1416" upper="3.1416" velocity="3"/>
		<limit effort="87" lower="-2.9671" upper="2.9671" velocity="2.1750"/>
	</joint>
	<link name="link_2_to_4">
		<visual>
			<origin rpy="-0.11563729170751277 0.0 -0.5368104578908708" xyz="0.006232396307345303 0.010472815255965077 0.10491957873477487"/>
			<geometry>
				<cylinder length="0.21125000000000008" radius="0.011668009211849495"/>
			</geometry>
			<material name="brown"/>
		</visual>
		<collision>
			<origin rpy="-0.11563729170751277 0.0 -0.5368104578908708" xyz="0.006232396307345303 0.010472815255965077 0.10491957873477487"/>
			<geometry>
				<cylinder length="0.21125000000000008" radius="0.011668009211849495"/>
			</geometry>
		</collision>
	</link>
	<link name="link_2_to_8">
		<visual>
			<origin rpy="-2.107010513904886 0.0 -3.1393294079185647" xyz="0.0001335772642988703 -0.05902012226223055 -0.035075461355887017"/>
			<geometry>
				<cylinder length="0.13731250000000006" radius="0.008800000000000002"/>
			</geometry>
			<material name="brown"/>
		</visual>
		<collision>
			<origin rpy="-2.107010513904886 0.0 -3.1393294079185647" xyz="0.0001335772642988703 -0.05902012226223055 -0.035075461355887017"/>
			<geometry>
				<cylinder length="0.13731250000000006" radius="0.008800000000000002"/>
			</geometry>
		</collision>
	</link>
	<link name="link_2_to_14">
		<visual>
			<origin rpy="-1.518605994448154 2.220446049250313e-16 0.685726820149468" xyz="-0.02822065507495542 0.03449210112746771 0.0023280179379336907"/>
			<geometry>
				<cylinder length="0.08925312500000003" radius="0.008"/>
			</geometry>
			<material name="brown"/>
		</visual>
		<collision>
			<origin rpy="-1.518605994448154 2.220446049250313e-16 0.685726820149468" xyz="-0.02822065507495542 0.03449210112746771 0.0023280179379336907"/>
			<geometry>
				<cylinder length="0.08925312500000003" radius="0.008"/>
			</geometry>
		</collision>
	</link>
	<joint name="joint3_base" type="fixed">
		<parent link="link_1_to_3"/>
		<origin rpy="0 0 0" xyz="-0.1161914030943263 -0.16370630469420078 -0.06577511801845204"/>
		<child link="link3_base"/>
	</joint>
	<link name="link3_base">
		<inertial>
			<mass value="0.001"/>
			<inertia ixx="0.001" ixy="0" ixz="0" iyy="0.001" iyz="0" izz="0.001"/>
		</inertial>
	</link>
	<joint name="joint3_x_to_5" type="revolute">
		<safety_controller k_position="100.0" k_velocity="40.0" soft_lower_limit="-2.8973" soft_upper_limit="2.8973"/>
		<parent link="link3_base"/>
		<child link="link3_x_to_5"/>
		<origin rpy="0 0 0" xyz="0 0 0"/>
		<axis xyz="1 0 0"/>
		<dynamics damping="10.0"/>
		<limit effort="10" lower="-3.1416" upper="3.1416" velocity="3"/>
		<limit effort="87" lower="-2.9671" upper="2.9671" velocity="2.1750"/>
	</joint>
	<link name="link3_x_to_5">
		<inertial>
			<mass value="0.001"/>
			<inertia ixx="0.001" ixy="0" ixz="0" iyy="0.001" iyz="0" izz="0.001"/>
		</inertial>
	</link>
	<joint name="joint3_y_to_5" type="revolute">
		<safety_controller k_position="100.0" k_velocity="40.0" soft_lower_limit="-2.8973" soft_upper_limit="2.8973"/>
		<parent link="link3_x_to_5"/>
		<child link="link3_y_to_5"/>
		<origin rpy="0 0 0" xyz="0 0 0"/>
		<axis xyz="0 1 0"/>
		<dynamics damping="10.0"/>
		<limit effort="10" lower="-3.1416" upper="3.1416" velocity="3"/>
		<limit effort="87" lower="-2.9671" upper="2.9671" velocity="2.1750"/>
	</joint>
	<link name="link3_y_to_5">
		<inertial>
			<mass value="0.001"/>
			<inertia ixx="0.001" ixy="0" ixz="0" iyy="0.001" iyz="0" izz="0.001"/>
		</inertial>
	</link>
	<joint name="joint3_z_to_5" type="revolute">
		<safety_controller k_position="100.0" k_velocity="40.0" soft_lower_limit="-2.8973" soft_upper_limit="2.8973"/>
		<parent link="link3_y_to_5"/>
		<child link="link_3_to_5"/>
		<origin rpy="0 0 0" xyz="0 0 0"/>
		<axis xyz="0 0 1"/>
		<dynamics damping="10.0"/>
		<limit effort="10" lower="-3.1416" upper="3.1416" velocity="3"/>
		<limit effort="87" lower="-2.9671" upper="2.9671" velocity="2.1750"/>
	</joint>
	<link name="link_3_to_5">
		<visual>
			<origin rpy="-1.1580463959755163 0.0 2.445900239138623" xyz="-0.040307648690754955 -0.04827544559162984 0.02754007033423786"/>
			<geometry>
				<cylinder length="0.1373125" radius="0.008800000000000002"/>
			</geometry>
			<material name="brown"/>
		</visual>
		<collision>
			<origin rpy="-1.1580463959755163 0.0 2.445900239138623" xyz="-0.040307648690754955 -0.04827544559162984 0.02754007033423786"/>
			<geometry>
				<cylinder length="0.1373125" radius="0.008800000000000002"/>
			</geometry>
		</collision>
	</link>
	<joint name="joint4_base" type="fixed">
		<parent link="link_2_to_4"/>
		<origin rpy="0 0 0" xyz="0.012464792614690606 0.020945630511930154 0.20983915746954973"/>
		<child link="link4_base"/>
	</joint>
	<link name="link4_base">
		<inertial>
			<mass value="0.001"/>
			<inertia ixx="0.001" ixy="0" ixz="0" iyy="0.001" iyz="0" izz="0.001"/>
		</inertial>
	</link>
	<joint name="joint4_x_to_6" type="revolute">
		<safety_controller k_position="100.0" k_velocity="40.0" soft_lower_limit="-2.8973" soft_upper_limit="2.8973"/>
		<parent link="link4_base"/>
		<child link="link4_x_to_6"/>
		<origin rpy="0 0 0" xyz="0 0 0"/>
		<axis xyz="1 0 0"/>
		<dynamics damping="10.0"/>
		<limit effort="10" lower="-3.1416" upper="3.1416" velocity="3"/>
		<limit effort="87" lower="-2.9671" upper="2.9671" velocity="2.1750"/>
	</joint>
	<link name="link4_x_to_6">
		<inertial>
			<mass value="0.001"/>
			<inertia ixx="0.001" ixy="0" ixz="0" iyy="0.001" iyz="0" izz="0.001"/>
		</inertial>
	</link>
	<joint name="joint4_y_to_6" type="revolute">
		<safety_controller k_position="100.0" k_velocity="40.0" soft_lower_limit="-2.8973" soft_upper_limit="2.8973"/>
		<parent link="link4_x_to_6"/>
		<child link="link4_y_to_6"/>
		<origin rpy="0 0 0" xyz="0 0 0"/>
		<axis xyz="0 1 0"/>
		<dynamics damping="10.0"/>
		<limit effort="10" lower="-3.1416" upper="3.1416" velocity="3"/>
		<limit effort="87" lower="-2.9671" upper="2.9671" velocity="2.1750"/>
	</joint>
	<link name="link4_y_to_6">
		<inertial>
			<mass value="0.001"/>
			<inertia ixx="0.001" ixy="0" ixz="0" iyy="0.001" iyz="0" izz="0.001"/>
		</inertial>
	</link>
	<joint name="joint4_z_to_6" type="revolute">
		<safety_controller k_position="100.0" k_velocity="40.0" soft_lower_limit="-2.8973" soft_upper_limit="2.8973"/>
		<parent link="link4_y_to_6"/>
		<child link="link_4_to_6"/>
		<origin rpy="0 0 0" xyz="0 0 0"/>
		<axis xyz="0 0 1"/>
		<dynamics damping="10.0"/>
		<limit effort="10" lower="-3.1416" upper="3.1416" velocity="3"/>
		<limit effort="87" lower="-2.9671" upper="2.9671" velocity="2.1750"/>
	</joint>
	<joint name="joint4_x_to_10" type="revolute">
		<safety_controller k_position="100.0" k_velocity="40.0" soft_lower_limit="-2.8973" soft_upper_limit="2.8973"/>
		<parent link="link4_base"/>
		<child link="link4_x_to_10"/>
		<origin rpy="0 0 0" xyz="0 0 0"/>
		<axis xyz="1 0 0"/>
		<dynamics damping="10.0"/>
		<limit effort="10" lower="-3.1416" upper="3.1416" velocity="3"/>
		<limit effort="87" lower="-2.9671" upper="2.9671" velocity="2.1750"/>
	</joint>
	<link name="link4_x_to_10">
		<inertial>
			<mass value="0.001"/>
			<inertia ixx="0.001" ixy="0" ixz="0" iyy="0.001" iyz="0" izz="0.001"/>
		</inertial>
	</link>
	<joint name="joint4_y_to_10" type="revolute">
		<safety_controller k_position="100.0" k_velocity="40.0" soft_lower_limit="-2.8973" soft_upper_limit="2.8973"/>
		<parent link="link4_x_to_10"/>
		<child link="link4_y_to_10"/>
		<origin rpy="0 0 0" xyz="0 0 0"/>
		<axis xyz="0 1 0"/>
		<dynamics damping="10.0"/>
		<limit effort="10" lower="-3.1416" upper="3.1416" velocity="3"/>
		<limit effort="87" lower="-2.9671" upper="2.9671" velocity="2.1750"/>
	</joint>
	<link name="link4_y_to_10">
		<inertial>
			<mass value="0.001"/>
			<inertia ixx="0.001" ixy="0" ixz="0" iyy="0.001" iyz="0" izz="0.001"/>
		</inertial>
	</link>
	<joint name="joint4_z_to_10" type="revolute">
		<safety_controller k_position="100.0" k_velocity="40.0" soft_lower_limit="-2.8973" soft_upper_limit="2.8973"/>
		<parent link="link4_y_to_10"/>
		<child link="link_4_to_10"/>
		<origin rpy="0 0 0" xyz="0 0 0"/>
		<axis xyz="0 0 1"/>
		<dynamics damping="10.0"/>
		<limit effort="10" lower="-3.1416" upper="3.1416" velocity="3"/>
		<limit effort="87" lower="-2.9671" upper="2.9671" velocity="2.1750"/>
	</joint>
	<link name="link_4_to_6">
		<visual>
			<origin rpy="-0.43773763473946864 0.0 0.03223625513042553" xyz="-0.0009380028290969407 0.02908768050351883 0.06218285662206524"/>
			<geometry>
				<cylinder length="0.1373125000000001" radius="0.008800000000000002"/>
			</geometry>
			<material name="brown"/>
		</visual>
		<collision>
			<origin rpy="-0.43773763473946864 0.0 0.03223625513042553" xyz="-0.0009380028290969407 0.02908768050351883 0.06218285662206524"/>
			<geometry>
				<cylinder length="0.1373125000000001" radius="0.008800000000000002"/>
			</geometry>
		</collision>
	</link>
	<link name="link_4_to_10">
		<visual>
			<origin rpy="-1.283892777809097 0.0 -2.5932608045783243" xyz="0.022311386162851124 -0.03652739854020086 0.012628589942819235"/>
			<geometry>
				<cylinder length="0.08925312500000003" radius="0.008"/>
			</geometry>
			<material name="brown"/>
		</visual>
		<collision>
			<origin rpy="-1.283892777809097 0.0 -2.5932608045783243" xyz="0.022311386162851124 -0.03652739854020086 0.012628589942819235"/>
			<geometry>
				<cylinder length="0.08925312500000003" radius="0.008"/>
			</geometry>
		</collision>
	</link>
	<joint name="joint5_base" type="fixed">
		<parent link="link_3_to_5"/>
		<origin rpy="0 0 0" xyz="-0.08061529738150991 -0.09655089118325969 0.05508014066847572"/>
		<child link="link5_base"/>
	</joint>
	<link name="link5_base">
		<inertial>
			<mass value="0.001"/>
			<inertia ixx="0.001" ixy="0" ixz="0" iyy="0.001" iyz="0" izz="0.001"/>
		</inertial>
	</link>
	<joint name="joint5_x_to_9" type="revolute">
		<safety_controller k_position="100.0" k_velocity="40.0" soft_lower_limit="-2.8973" soft_upper_limit="2.8973"/>
		<parent link="link5_base"/>
		<child link="link5_x_to_9"/>
		<origin rpy="0 0 0" xyz="0 0 0"/>
		<axis xyz="1 0 0"/>
		<dynamics damping="10.0"/>
		<limit effort="10" lower="-3.1416" upper="3.1416" velocity="3"/>
		<limit effort="87" lower="-2.9671" upper="2.9671" velocity="2.1750"/>
	</joint>
	<link name="link5_x_to_9">
		<inertial>
			<mass value="0.001"/>
			<inertia ixx="0.001" ixy="0" ixz="0" iyy="0.001" iyz="0" izz="0.001"/>
		</inertial>
	</link>
	<joint name="joint5_y_to_9" type="revolute">
		<safety_controller k_position="100.0" k_velocity="40.0" soft_lower_limit="-2.8973" soft_upper_limit="2.8973"/>
		<parent link="link5_x_to_9"/>
		<child link="link5_y_to_9"/>
		<origin rpy="0 0 0" xyz="0 0 0"/>
		<axis xyz="0 1 0"/>
		<dynamics damping="10.0"/>
		<limit effort="10" lower="-3.1416" upper="3.1416" velocity="3"/>
		<limit effort="87" lower="-2.9671" upper="2.9671" velocity="2.1750"/>
	</joint>
	<link name="link5_y_to_9">
		<inertial>
			<mass value="0.001"/>
			<inertia ixx="0.001" ixy="0" ixz="0" iyy="0.001" iyz="0" izz="0.001"/>
		</inertial>
	</link>
	<joint name="joint5_z_to_9" type="revolute">
		<safety_controller k_position="100.0" k_velocity="40.0" soft_lower_limit="-2.8973" soft_upper_limit="2.8973"/>
		<parent link="link5_y_to_9"/>
		<child link="link_5_to_9"/>
		<origin rpy="0 0 0" xyz="0 0 0"/>
		<axis xyz="0 0 1"/>
		<dynamics damping="10.0"/>
		<limit effort="10" lower="-3.1416" upper="3.1416" velocity="3"/>
		<limit effort="87" lower="-2.9671" upper="2.9671" velocity="2.1750"/>
	</joint>
	<link name="link_5_to_9">
		<visual>
			<origin rpy="-1.3090719893410299 0.0 2.2146790998105623" xyz="-0.034475578877032176 -0.02587724956902654 0.011546969143556934"/>
			<geometry>
				<cylinder length="0.08925312500000003" radius="0.008"/>
			</geometry>
			<material name="brown"/>
		</visual>
		<collision>
			<origin rpy="-1.3090719893410299 0.0 2.2146790998105623" xyz="-0.034475578877032176 -0.02587724956902654 0.011546969143556934"/>
			<geometry>
				<cylinder length="0.08925312500000003" radius="0.008"/>
			</geometry>
		</collision>
	</link>
	<joint name="joint6_base" type="fixed">
		<parent link="link_4_to_6"/>
		<origin rpy="0 0 0" xyz="-0.0018760056581938814 0.05817536100703766 0.12436571324413048"/>
		<child link="link6_base"/>
	</joint>
	<link name="link6_base">
		<inertial>
			<mass value="0.001"/>
			<inertia ixx="0.001" ixy="0" ixz="0" iyy="0.001" iyz="0" izz="0.001"/>
		</inertial>
	</link>
	<joint name="joint6_x_to_11" type="revolute">
		<safety_controller k_position="100.0" k_velocity="40.0" soft_lower_limit="-2.8973" soft_upper_limit="2.8973"/>
		<parent link="link6_base"/>
		<child link="link6_x_to_11"/>
		<origin rpy="0 0 0" xyz="0 0 0"/>
		<axis xyz="1 0 0"/>
		<dynamics damping="10.0"/>
		<limit effort="10" lower="-3.1416" upper="3.1416" velocity="3"/>
		<limit effort="87" lower="-2.9671" upper="2.9671" velocity="2.1750"/>
	</joint>
	<link name="link6_x_to_11">
		<inertial>
			<mass value="0.001"/>
			<inertia ixx="0.001" ixy="0" ixz="0" iyy="0.001" iyz="0" izz="0.001"/>
		</inertial>
	</link>
	<joint name="joint6_y_to_11" type="revolute">
		<safety_controller k_position="100.0" k_velocity="40.0" soft_lower_limit="-2.8973" soft_upper_limit="2.8973"/>
		<parent link="link6_x_to_11"/>
		<child link="link6_y_to_11"/>
		<origin rpy="0 0 0" xyz="0 0 0"/>
		<axis xyz="0 1 0"/>
		<dynamics damping="10.0"/>
		<limit effort="10" lower="-3.1416" upper="3.1416" velocity="3"/>
		<limit effort="87" lower="-2.9671" upper="2.9671" velocity="2.1750"/>
	</joint>
	<link name="link6_y_to_11">
		<inertial>
			<mass value="0.001"/>
			<inertia ixx="0.001" ixy="0" ixz="0" iyy="0.001" iyz="0" izz="0.001"/>
		</inertial>
	</link>
	<joint name="joint6_z_to_11" type="revolute">
		<safety_controller k_position="100.0" k_velocity="40.0" soft_lower_limit="-2.8973" soft_upper_limit="2.8973"/>
		<parent link="link6_y_to_11"/>
		<child link="link_6_to_11"/>
		<origin rpy="0 0 0" xyz="0 0 0"/>
		<axis xyz="0 0 1"/>
		<dynamics damping="10.0"/>
		<limit effort="10" lower="-3.1416" upper="3.1416" velocity="3"/>
		<limit effort="87" lower="-2.9671" upper="2.9671" velocity="2.1750"/>
	</joint>
	<link name="link_6_to_11">
		<visual>
			<origin rpy="-1.349473996862357 0.0 0.3872721880181559" xyz="-0.016442748622602425 0.04031372335328914 0.009796418105347704"/>
			<geometry>
				<cylinder length="0.08925312500000004" radius="0.008"/>
			</geometry>
			<material name="brown"/>
		</visual>
		<collision>
			<origin rpy="-1.349473996862357 0.0 0.3872721880181559" xyz="-0.016442748622602425 0.04031372335328914 0.009796418105347704"/>
			<geometry>
				<cylinder length="0.08925312500000004" radius="0.008"/>
			</geometry>
		</collision>
	</link>
	<joint name="joint7_base" type="fixed">
		<parent link="link_1_to_7"/>
		<origin rpy="0 0 0" xyz="0.0806996555769547 0.10975956824360905 -0.017179214911846763"/>
		<child link="link7_base"/>
	</joint>
	<link name="link7_base">
		<inertial>
			<mass value="0.001"/>
			<inertia ixx="0.001" ixy="0" ixz="0" iyy="0.001" iyz="0" izz="0.001"/>
		</inertial>
	</link>
	<joint name="joint7_x_to_12" type="revolute">
		<safety_controller k_position="100.0" k_velocity="40.0" soft_lower_limit="-2.8973" soft_upper_limit="2.8973"/>
		<parent link="link7_base"/>
		<child link="link7_x_to_12"/>
		<origin rpy="0 0 0" xyz="0 0 0"/>
		<axis xyz="1 0 0"/>
		<dynamics damping="10.0"/>
		<limit effort="10" lower="-3.1416" upper="3.1416" velocity="3"/>
		<limit effort="87" lower="-2.9671" upper="2.9671" velocity="2.1750"/>
	</joint>
	<link name="link7_x_to_12">
		<inertial>
			<mass value="0.001"/>
			<inertia ixx="0.001" ixy="0" ixz="0" iyy="0.001" iyz="0" izz="0.001"/>
		</inertial>
	</link>
	<joint name="joint7_y_to_12" type="revolute">
		<safety_controller k_position="100.0" k_velocity="40.0" soft_lower_limit="-2.8973" soft_upper_limit="2.8973"/>
		<parent link="link7_x_to_12"/>
		<child link="link7_y_to_12"/>
		<origin rpy="0 0 0" xyz="0 0 0"/>
		<axis xyz="0 1 0"/>
		<dynamics damping="10.0"/>
		<limit effort="10" lower="-3.1416" upper="3.1416" velocity="3"/>
		<limit effort="87" lower="-2.9671" upper="2.9671" velocity="2.1750"/>
	</joint>
	<link name="link7_y_to_12">
		<inertial>
			<mass value="0.001"/>
			<inertia ixx="0.001" ixy="0" ixz="0" iyy="0.001" iyz="0" izz="0.001"/>
		</inertial>
	</link>
	<joint name="joint7_z_to_12" type="revolute">
		<safety_controller k_position="100.0" k_velocity="40.0" soft_lower_limit="-2.8973" soft_upper_limit="2.8973"/>
		<parent link="link7_y_to_12"/>
		<child link="link_7_to_12"/>
		<origin rpy="0 0 0" xyz="0 0 0"/>
		<axis xyz="0 0 1"/>
		<dynamics damping="10.0"/>
		<limit effort="10" lower="-3.1416" upper="3.1416" velocity="3"/>
		<limit effort="87" lower="-2.9671" upper="2.9671" velocity="2.1750"/>
	</joint>
	<link name="link_7_to_12">
		<visual>
			<origin rpy="-1.527317462165826 0.0 -0.6083708646909594" xyz="0.025481376849892077 0.036585066276364375 0.0019397009960862022"/>
			<geometry>
				<cylinder length="0.08925312500000003" radius="0.008"/>
			</geometry>
			<material name="brown"/>
		</visual>
		<collision>
			<origin rpy="-1.527317462165826 0.0 -0.6083708646909594" xyz="0.025481376849892077 0.036585066276364375 0.0019397009960862022"/>
			<geometry>
				<cylinder length="0.08925312500000003" radius="0.008"/>
			</geometry>
		</collision>
	</link>
	<joint name="joint8_base" type="fixed">
		<parent link="link_2_to_8"/>
		<origin rpy="0 0 0" xyz="0.0002671545285977406 -0.1180402445244611 -0.07015092271177403"/>
		<child link="link8_base"/>
	</joint>
	<link name="link8_base">
		<inertial>
			<mass value="0.001"/>
			<inertia ixx="0.001" ixy="0" ixz="0" iyy="0.001" iyz="0" izz="0.001"/>
		</inertial>
	</link>
	<joint name="joint8_x_to_13" type="revolute">
		<safety_controller k_position="100.0" k_velocity="40.0" soft_lower_limit="-2.8973" soft_upper_limit="2.8973"/>
		<parent link="link8_base"/>
		<child link="link8_x_to_13"/>
		<origin rpy="0 0 0" xyz="0 0 0"/>
		<axis xyz="1 0 0"/>
		<dynamics damping="10.0"/>
		<limit effort="10" lower="-3.1416" upper="3.1416" velocity="3"/>
		<limit effort="87" lower="-2.9671" upper="2.9671" velocity="2.1750"/>
	</joint>
	<link name="link8_x_to_13">
		<inertial>
			<mass value="0.001"/>
			<inertia ixx="0.001" ixy="0" ixz="0" iyy="0.001" iyz="0" izz="0.001"/>
		</inertial>
	</link>
	<joint name="joint8_y_to_13" type="revolute">
		<safety_controller k_position="100.0" k_velocity="40.0" soft_lower_limit="-2.8973" soft_upper_limit="2.8973"/>
		<parent link="link8_x_to_13"/>
		<child link="link8_y_to_13"/>
		<origin rpy="0 0 0" xyz="0 0 0"/>
		<axis xyz="0 1 0"/>
		<dynamics damping="10.0"/>
		<limit effort="10" lower="-3.1416" upper="3.1416" velocity="3"/>
		<limit effort="87" lower="-2.9671" upper="2.9671" velocity="2.1750"/>
	</joint>
	<link name="link8_y_to_13">
		<inertial>
			<mass value="0.001"/>
			<inertia ixx="0.001" ixy="0" ixz="0" iyy="0.001" iyz="0" izz="0.001"/>
		</inertial>
	</link>
	<joint name="joint8_z_to_13" type="revolute">
		<safety_controller k_position="100.0" k_velocity="40.0" soft_lower_limit="-2.8973" soft_upper_limit="2.8973"/>
		<parent link="link8_y_to_13"/>
		<child link="link_8_to_13"/>
		<origin rpy="0 0 0" xyz="0 0 0"/>
		<axis xyz="0 0 1"/>
		<dynamics damping="10.0"/>
		<limit effort="10" lower="-3.1416" upper="3.1416" velocity="3"/>
		<limit effort="87" lower="-2.9671" upper="2.9671" velocity="2.1750"/>
	</joint>
	<link name="link_8_to_13">
		<visual>
			<origin rpy="-1.3666202324337196 2.220446049250313e-16 -2.4867046731792994" xyz="0.026616130626494677 -0.03465885593862805 0.009048501315975344"/>
			<geometry>
				<cylinder length="0.08925312500000006" radius="0.008"/>
			</geometry>
			<material name="brown"/>
		</visual>
		<collision>
			<origin rpy="-1.3666202324337196 2.220446049250313e-16 -2.4867046731792994" xyz="0.026616130626494677 -0.03465885593862805 0.009048501315975344"/>
			<geometry>
				<cylinder length="0.08925312500000006" radius="0.008"/>
			</geometry>
		</collision>
	</link>
	<joint name="joint9_base" type="fixed">
		<parent link="link_5_to_9"/>
		<origin rpy="0 0 0" xyz="-0.06895115775406435 -0.05175449913805308 0.02309393828711387"/>
		<child link="link9_tip"/>
	</joint>
	<link name="link9_tip">
		<visual>
			<origin rpy="0 0 0" xyz="0 0 0"/>
			<geometry>
				<box size="0.016 0.016 0.016"/>
			</geometry>
			<material name="green"/>
		</visual>
		<collision>
			<origin rpy="0 0 0" xyz="0 0 0"/>
			<geometry>
				<box size="0.016 0.016 0.016"/>
			</geometry>
		</collision>
	</link>
	<joint name="joint10_base" type="fixed">
		<parent link="link_4_to_10"/>
		<origin rpy="0 0 0" xyz="0.04462277232570225 -0.07305479708040172 0.02525717988563847"/>
		<child link="link10_tip"/>
	</joint>
	<link name="link10_tip">
		<visual>
			<origin rpy="0 0 0" xyz="0 0 0"/>
			<geometry>
				<box size="0.016 0.016 0.016"/>
			</geometry>
			<material name="green"/>
		</visual>
		<collision>
			<origin rpy="0 0 0" xyz="0 0 0"/>
			<geometry>
				<box size="0.016 0.016 0.016"/>
			</geometry>
		</collision>
	</link>
	<joint name="joint11_base" type="fixed">
		<parent link="link_6_to_11"/>
		<origin rpy="0 0 0" xyz="-0.03288549724520485 0.08062744670657827 0.019592836210695408"/>
		<child link="link11_tip"/>
	</joint>
	<link name="link11_tip">
		<visual>
			<origin rpy="0 0 0" xyz="0 0 0"/>
			<geometry>
				<box size="0.016 0.016 0.016"/>
			</geometry>
			<material name="green"/>
		</visual>
		<collision>
			<origin rpy="0 0 0" xyz="0 0 0"/>
			<geometry>
				<box size="0.016 0.016 0.016"/>
			</geometry>
		</collision>
	</link>
	<joint name="joint12_base" type="fixed">
		<parent link="link_7_to_12"/>
		<origin rpy="0 0 0" xyz="0.050962753699784154 0.07317013255272875 0.0038794019921724043"/>
		<child link="link12_tip"/>
	</joint>
	<link name="link12_tip">
		<visual>
			<origin rpy="0 0 0" xyz="0 0 0"/>
			<geometry>
				<box size="0.016 0.016 0.016"/>
			</geometry>
			<material name="green"/>
		</visual>
		<collision>
			<origin rpy="0 0 0" xyz="0 0 0"/>
			<geometry>
				<box size="0.016 0.016 0.016"/>
			</geometry>
		</collision>
	</link>
	<joint name="joint13_base" type="fixed">
		<parent link="link_8_to_13"/>
		<origin rpy="0 0 0" xyz="0.053232261252989355 -0.0693177118772561 0.018097002631950687"/>
		<child link="link13_tip"/>
	</joint>
	<link name="link13_tip">
		<visual>
			<origin rpy="0 0 0" xyz="0 0 0"/>
			<geometry>
				<box size="0.016 0.016 0.016"/>
			</geometry>
			<material name="green"/>
		</visual>
		<collision>
			<origin rpy="0 0 0" xyz="0 0 0"/>
			<geometry>
				<box size="0.016 0.016 0.016"/>
			</geometry>
		</collision>
	</link>
	<joint name="joint14_base" type="fixed">
		<parent link="link_2_to_14"/>
		<origin rpy="0 0 0" xyz="-0.05644131014991084 0.06898420225493541 0.0046560358758673814"/>
		<child link="link14_tip"/>
	</joint>
	<link name="link14_tip">
		<visual>
			<origin rpy="0 0 0" xyz="0 0 0"/>
			<geometry>
				<box size="0.016 0.016 0.016"/>
			</geometry>
			<material name="green"/>
		</visual>
		<collision>
			<origin rpy="0 0 0" xyz="0 0 0"/>
			<geometry>
				<box size="0.016 0.016 0.016"/>
			</geometry>
		</collision>
	</link>
	<joint name="joint15_base" type="fixed">
		<parent link="link_1_to_15"/>
		<origin rpy="0 0 0" xyz="-0.07807688288038672 0.043244891478726045 6.552954632366159e-06"/>
		<child link="link15_tip"/>
	</joint>
	<link name="link15_tip">
		<visual>
			<origin rpy="0 0 0" xyz="0 0 0"/>
			<geometry>
				<box size="0.016 0.016 0.016"/>
			</geometry>
			<material name="green"/>
		</visual>
		<collision>
			<origin rpy="0 0 0" xyz="0 0 0"/>
			<geometry>
				<box size="0.016 0.016 0.016"/>
			</geometry>
		</collision>
	</link>
</robot>
