<?xml version="1.0" ?>
<robot name="tree0">
	<material name="blue">
		<color rgba="0 0 0.8 1"/>
	</material>
	<material name="green">
		<color rgba="0 0.6 0 0.8"/>
	</material>
	<material name="brown">
		<color rgba="0.3 0.15 0.05 1.0"/>
	</material>
	<link name="base_link">
		<visual>
			<origin rpy="0 0 0" xyz="0 0 0"/>
			<geometry>
				<box size="1 1 0.02"/>
			</geometry>
			<material name="green"/>
		</visual>
		<collision>
			<origin rpy="0 0 0" xyz="0 0 0"/>
			<geometry>
				<box size="1 1 0.02"/>
			</geometry>
		</collision>
	</link>
	<joint name="joint0_base" type="fixed">
		<parent link="base_link"/>
		<origin rpy="0 0 0" xyz="0 0 0.01"/>
		<child link="link0_base"/>
	</joint>
	<link name="link0_base">
		<inertial>
			<mass value="0.001"/>
			<inertia ixx="0.001" ixy="0" ixz="0" iyy="0.001" iyz="0" izz="0.001"/>
		</inertial>
	</link>
	<joint name="joint0_x_to_1" type="revolute">
		<safety_controller k_position="100.0" k_velocity="40.0" soft_lower_limit="-2.8973" soft_upper_limit="2.8973"/>
		<parent link="link0_base"/>
		<child link="link0_x_to_1"/>
		<origin rpy="0 0 0" xyz="0 0 0"/>
		<axis xyz="1 0 0"/>
		<dynamics damping="10.0"/>
		<limit effort="10" lower="-3.1416" upper="3.1416" velocity="3"/>
		<limit effort="87" lower="-2.9671" upper="2.9671" velocity="2.1750"/>
	</joint>
	<link name="link0_x_to_1">
		<inertial>
			<mass value="0.001"/>
			<inertia ixx="0.001" ixy="0" ixz="0" iyy="0.001" iyz="0" izz="0.001"/>
		</inertial>
	</link>
	<joint name="joint0_y_to_1" type="revolute">
		<safety_controller k_position="100.0" k_velocity="40.0" soft_lower_limit="-2.8973" soft_upper_limit="2.8973"/>
		<parent link="link0_x_to_1"/>
		<child link="link0_y_to_1"/>
		<origin rpy="0 0 0" xyz="0 0 0"/>
		<axis xyz="0 1 0"/>
		<dynamics damping="10.0"/>
		<limit effort="10" lower="-3.1416" upper="3.1416" velocity="3"/>
		<limit effort="87" lower="-2.9671" upper="2.9671" velocity="2.1750"/>
	</joint>
	<link name="link0_y_to_1">
		<inertial>
			<mass value="0.001"/>
			<inertia ixx="0.001" ixy="0" ixz="0" iyy="0.001" iyz="0" izz="0.001"/>
		</inertial>
	</link>
	<joint name="joint0_z_to_1" type="revolute">
		<safety_controller k_position="100.0" k_velocity="40.0" soft_lower_limit="-2.8973" soft_upper_limit="2.8973"/>
		<parent link="link0_y_to_1"/>
		<child link="link_0_to_1"/>
		<origin rpy="0 0 0" xyz="0 0 0"/>
		<axis xyz="0 0 1"/>
		<dynamics damping="10.0"/>
		<limit effort="10" lower="-3.1416" upper="3.1416" velocity="3"/>
		<limit effort="87" lower="-2.9671" upper="2.9671" velocity="2.1750"/>
	</joint>
	<link name="link_0_to_1">
		<visual>
			<origin rpy="-0.06468593403052776 0.0 2.129156245247978" xyz="-0.013705879182800598 -0.008561612329699781 0.24947714859309744"/>
			<geometry>
				<cylinder length="0.5" radius="0.021992941343080656"/>
			</geometry>
			<material name="brown"/>
		</visual>
		<collision>
			<origin rpy="-0.06468593403052776 0.0 2.129156245247978" xyz="-0.013705879182800598 -0.008561612329699781 0.24947714859309744"/>
			<geometry>
				<cylinder length="0.5" radius="0.021992941343080656"/>
			</geometry>
		</collision>
	</link>
	<joint name="joint1_base" type="fixed">
		<parent link="link_0_to_1"/>
		<origin rpy="0 0 0" xyz="-0.027411758365601196 -0.017123224659399562 0.4989542971861949"/>
		<child link="link1_base"/>
	</joint>
	<link name="link1_base">
		<inertial>
			<mass value="0.001"/>
			<inertia ixx="0.001" ixy="0" ixz="0" iyy="0.001" iyz="0" izz="0.001"/>
		</inertial>
	</link>
	<joint name="joint1_x_to_2" type="revolute">
		<safety_controller k_position="100.0" k_velocity="40.0" soft_lower_limit="-2.8973" soft_upper_limit="2.8973"/>
		<parent link="link1_base"/>
		<child link="link1_x_to_2"/>
		<origin rpy="0 0 0" xyz="0 0 0"/>
		<axis xyz="1 0 0"/>
		<dynamics damping="10.0"/>
		<limit effort="10" lower="-3.1416" upper="3.1416" velocity="3"/>
		<limit effort="87" lower="-2.9671" upper="2.9671" velocity="2.1750"/>
	</joint>
	<link name="link1_x_to_2">
		<inertial>
			<mass value="0.001"/>
			<inertia ixx="0.001" ixy="0" ixz="0" iyy="0.001" iyz="0" izz="0.001"/>
		</inertial>
	</link>
	<joint name="joint1_y_to_2" type="revolute">
		<safety_controller k_position="100.0" k_velocity="40.0" soft_lower_limit="-2.8973" soft_upper_limit="2.8973"/>
		<parent link="link1_x_to_2"/>
		<child link="link1_y_to_2"/>
		<origin rpy="0 0 0" xyz="0 0 0"/>
		<axis xyz="0 1 0"/>
		<dynamics damping="10.0"/>
		<limit effort="10" lower="-3.1416" upper="3.1416" velocity="3"/>
		<limit effort="87" lower="-2.9671" upper="2.9671" velocity="2.1750"/>
	</joint>
	<link name="link1_y_to_2">
		<inertial>
			<mass value="0.001"/>
			<inertia ixx="0.001" ixy="0" ixz="0" iyy="0.001" iyz="0" izz="0.001"/>
		</inertial>
	</link>
	<joint name="joint1_z_to_2" type="revolute">
		<safety_controller k_position="100.0" k_velocity="40.0" soft_lower_limit="-2.8973" soft_upper_limit="2.8973"/>
		<parent link="link1_y_to_2"/>
		<child link="link_1_to_2"/>
		<origin rpy="0 0 0" xyz="0 0 0"/>
		<axis xyz="0 0 1"/>
		<dynamics damping="10.0"/>
		<limit effort="10" lower="-3.1416" upper="3.1416" velocity="3"/>
		<limit effort="87" lower="-2.9671" upper="2.9671" velocity="2.1750"/>
	</joint>
	<joint name="joint1_x_to_4" type="revolute">
		<safety_controller k_position="100.0" k_velocity="40.0" soft_lower_limit="-2.8973" soft_upper_limit="2.8973"/>
		<parent link="link1_base"/>
		<child link="link1_x_to_4"/>
		<origin rpy="0 0 0" xyz="0 0 0"/>
		<axis xyz="1 0 0"/>
		<dynamics damping="10.0"/>
		<limit effort="10" lower="-3.1416" upper="3.1416" velocity="3"/>
		<limit effort="87" lower="-2.9671" upper="2.9671" velocity="2.1750"/>
	</joint>
	<link name="link1_x_to_4">
		<inertial>
			<mass value="0.001"/>
			<inertia ixx="0.001" ixy="0" ixz="0" iyy="0.001" iyz="0" izz="0.001"/>
		</inertial>
	</link>
	<joint name="joint1_y_to_4" type="revolute">
		<safety_controller k_position="100.0" k_velocity="40.0" soft_lower_limit="-2.8973" soft_upper_limit="2.8973"/>
		<parent link="link1_x_to_4"/>
		<child link="link1_y_to_4"/>
		<origin rpy="0 0 0" xyz="0 0 0"/>
		<axis xyz="0 1 0"/>
		<dynamics damping="10.0"/>
		<limit effort="10" lower="-3.1416" upper="3.1416" velocity="3"/>
		<limit effort="87" lower="-2.9671" upper="2.9671" velocity="2.1750"/>
	</joint>
	<link name="link1_y_to_4">
		<inertial>
			<mass value="0.001"/>
			<inertia ixx="0.001" ixy="0" ixz="0" iyy="0.001" iyz="0" izz="0.001"/>
		</inertial>
	</link>
	<joint name="joint1_z_to_4" type="revolute">
		<safety_controller k_position="100.0" k_velocity="40.0" soft_lower_limit="-2.8973" soft_upper_limit="2.8973"/>
		<parent link="link1_y_to_4"/>
		<child link="link_1_to_4"/>
		<origin rpy="0 0 0" xyz="0 0 0"/>
		<axis xyz="0 0 1"/>
		<dynamics damping="10.0"/>
		<limit effort="10" lower="-3.1416" upper="3.1416" velocity="3"/>
		<limit effort="87" lower="-2.9671" upper="2.9671" velocity="2.1750"/>
	</joint>
	<joint name="joint1_x_to_8" type="revolute">
		<safety_controller k_position="100.0" k_velocity="40.0" soft_lower_limit="-2.8973" soft_upper_limit="2.8973"/>
		<parent link="link1_base"/>
		<child link="link1_x_to_8"/>
		<origin rpy="0 0 0" xyz="0 0 0"/>
		<axis xyz="1 0 0"/>
		<dynamics damping="10.0"/>
		<limit effort="10" lower="-3.1416" upper="3.1416" velocity="3"/>
		<limit effort="87" lower="-2.9671" upper="2.9671" velocity="2.1750"/>
	</joint>
	<link name="link1_x_to_8">
		<inertial>
			<mass value="0.001"/>
			<inertia ixx="0.001" ixy="0" ixz="0" iyy="0.001" iyz="0" izz="0.001"/>
		</inertial>
	</link>
	<joint name="joint1_y_to_8" type="revolute">
		<safety_controller k_position="100.0" k_velocity="40.0" soft_lower_limit="-2.8973" soft_upper_limit="2.8973"/>
		<parent link="link1_x_to_8"/>
		<child link="link1_y_to_8"/>
		<origin rpy="0 0 0" xyz="0 0 0"/>
		<axis xyz="0 1 0"/>
		<dynamics damping="10.0"/>
		<limit effort="10" lower="-3.1416" upper="3.1416" velocity="3"/>
		<limit effort="87" lower="-2.9671" upper="2.9671" velocity="2.1750"/>
	</joint>
	<link name="link1_y_to_8">
		<inertial>
			<mass value="0.001"/>
			<inertia ixx="0.001" ixy="0" ixz="0" iyy="0.001" iyz="0" izz="0.001"/>
		</inertial>
	</link>
	<joint name="joint1_z_to_8" type="revolute">
		<safety_controller k_position="100.0" k_velocity="40.0" soft_lower_limit="-2.8973" soft_upper_limit="2.8973"/>
		<parent link="link1_y_to_8"/>
		<child link="link_1_to_8"/>
		<origin rpy="0 0 0" xyz="0 0 0"/>
		<axis xyz="0 0 1"/>
		<dynamics damping="10.0"/>
		<limit effort="10" lower="-3.1416" upper="3.1416" velocity="3"/>
		<limit effort="87" lower="-2.9671" upper="2.9671" velocity="2.1750"/>
	</joint>
	<joint name="joint1_x_to_16" type="revolute">
		<safety_controller k_position="100.0" k_velocity="40.0" soft_lower_limit="-2.8973" soft_upper_limit="2.8973"/>
		<parent link="link1_base"/>
		<child link="link1_x_to_16"/>
		<origin rpy="0 0 0" xyz="0 0 0"/>
		<axis xyz="1 0 0"/>
		<dynamics damping="10.0"/>
		<limit effort="10" lower="-3.1416" upper="3.1416" velocity="3"/>
		<limit effort="87" lower="-2.9671" upper="2.9671" velocity="2.1750"/>
	</joint>
	<link name="link1_x_to_16">
		<inertial>
			<mass value="0.001"/>
			<inertia ixx="0.001" ixy="0" ixz="0" iyy="0.001" iyz="0" izz="0.001"/>
		</inertial>
	</link>
	<joint name="joint1_y_to_16" type="revolute">
		<safety_controller k_position="100.0" k_velocity="40.0" soft_lower_limit="-2.8973" soft_upper_limit="2.8973"/>
		<parent link="link1_x_to_16"/>
		<child link="link1_y_to_16"/>
		<origin rpy="0 0 0" xyz="0 0 0"/>
		<axis xyz="0 1 0"/>
		<dynamics damping="10.0"/>
		<limit effort="10" lower="-3.1416" upper="3.1416" velocity="3"/>
		<limit effort="87" lower="-2.9671" upper="2.9671" velocity="2.1750"/>
	</joint>
	<link name="link1_y_to_16">
		<inertial>
			<mass value="0.001"/>
			<inertia ixx="0.001" ixy="0" ixz="0" iyy="0.001" iyz="0" izz="0.001"/>
		</inertial>
	</link>
	<joint name="joint1_z_to_16" type="revolute">
		<safety_controller k_position="100.0" k_velocity="40.0" soft_lower_limit="-2.8973" soft_upper_limit="2.8973"/>
		<parent link="link1_y_to_16"/>
		<child link="link_1_to_16"/>
		<origin rpy="0 0 0" xyz="0 0 0"/>
		<axis xyz="0 0 1"/>
		<dynamics damping="10.0"/>
		<limit effort="10" lower="-3.1416" upper="3.1416" velocity="3"/>
		<limit effort="87" lower="-2.9671" upper="2.9671" velocity="2.1750"/>
	</joint>
	<link name="link_1_to_2">
		<visual>
			<origin rpy="-0.0944807500133786 0.0 2.096278200556855" xyz="-0.013261962988273535 -0.007690132286248555 0.1617752521343041"/>
			<geometry>
				<cylinder length="0.325" radius="0.017336234306744133"/>
			</geometry>
			<material name="brown"/>
		</visual>
		<collision>
			<origin rpy="-0.0944807500133786 0.0 2.096278200556855" xyz="-0.013261962988273535 -0.007690132286248555 0.1617752521343041"/>
			<geometry>
				<cylinder length="0.325" radius="0.017336234306744133"/>
			</geometry>
		</collision>
	</link>
	<link name="link_1_to_4">
		<visual>
			<origin rpy="-1.235071376399753 0.0 0.7629703171237266" xyz="-0.06891926347289055 0.07208215187824192 0.03479855065884735"/>
			<geometry>
				<cylinder length="0.21125000000000008" radius="0.011668009211849495"/>
			</geometry>
			<material name="brown"/>
		</visual>
		<collision>
			<origin rpy="-1.235071376399753 0.0 0.7629703171237266" xyz="-0.06891926347289055 0.07208215187824192 0.03479855065884735"/>
			<geometry>
				<cylinder length="0.21125000000000008" radius="0.011668009211849495"/>
			</geometry>
		</collision>
	</link>
	<link name="link_1_to_8">
		<visual>
			<origin rpy="-1.4238742640203517 0.0 -2.0713222434211844" xyz="0.05958526659749254 -0.032592280460190456 0.010050866777175482"/>
			<geometry>
				<cylinder length="0.13731250000000003" radius="0.008800000000000002"/>
			</geometry>
			<material name="brown"/>
		</visual>
		<collision>
			<origin rpy="-1.4238742640203517 0.0 -2.0713222434211844" xyz="0.05958526659749254 -0.032592280460190456 0.010050866777175482"/>
			<geometry>
				<cylinder length="0.13731250000000003" radius="0.008800000000000002"/>
			</geometry>
		</collision>
	</link>
	<link name="link_1_to_16">
		<visual>
			<origin rpy="-2.08761390694696 2.220446049250313e-16 2.103802831994884" xyz="-0.033416204766988304 -0.019714317273103934 -0.02205069236991236"/>
			<geometry>
				<cylinder length="0.08925312500000003" radius="0.008"/>
			</geometry>
			<material name="brown"/>
		</visual>
		<collision>
			<origin rpy="-2.08761390694696 2.220446049250313e-16 2.103802831994884" xyz="-0.033416204766988304 -0.019714317273103934 -0.02205069236991236"/>
			<geometry>
				<cylinder length="0.08925312500000003" radius="0.008"/>
			</geometry>
		</collision>
	</link>
	<joint name="joint2_base" type="fixed">
		<parent link="link_1_to_2"/>
		<origin rpy="0 0 0" xyz="-0.02652392597654707 -0.01538026457249711 0.3235505042686082"/>
		<child link="link2_base"/>
	</joint>
	<link name="link2_base">
		<inertial>
			<mass value="0.001"/>
			<inertia ixx="0.001" ixy="0" ixz="0" iyy="0.001" iyz="0" izz="0.001"/>
		</inertial>
	</link>
	<joint name="joint2_x_to_3" type="revolute">
		<safety_controller k_position="100.0" k_velocity="40.0" soft_lower_limit="-2.8973" soft_upper_limit="2.8973"/>
		<parent link="link2_base"/>
		<child link="link2_x_to_3"/>
		<origin rpy="0 0 0" xyz="0 0 0"/>
		<axis xyz="1 0 0"/>
		<dynamics damping="10.0"/>
		<limit effort="10" lower="-3.1416" upper="3.1416" velocity="3"/>
		<limit effort="87" lower="-2.9671" upper="2.9671" velocity="2.1750"/>
	</joint>
	<link name="link2_x_to_3">
		<inertial>
			<mass value="0.001"/>
			<inertia ixx="0.001" ixy="0" ixz="0" iyy="0.001" iyz="0" izz="0.001"/>
		</inertial>
	</link>
	<joint name="joint2_y_to_3" type="revolute">
		<safety_controller k_position="100.0" k_velocity="40.0" soft_lower_limit="-2.8973" soft_upper_limit="2.8973"/>
		<parent link="link2_x_to_3"/>
		<child link="link2_y_to_3"/>
		<origin rpy="0 0 0" xyz="0 0 0"/>
		<axis xyz="0 1 0"/>
		<dynamics damping="10.0"/>
		<limit effort="10" lower="-3.1416" upper="3.1416" velocity="3"/>
		<limit effort="87" lower="-2.9671" upper="2.9671" velocity="2.1750"/>
	</joint>
	<link name="link2_y_to_3">
		<inertial>
			<mass value="0.001"/>
			<inertia ixx="0.001" ixy="0" ixz="0" iyy="0.001" iyz="0" izz="0.001"/>
		</inertial>
	</link>
	<joint name="joint2_z_to_3" type="revolute">
		<safety_controller k_position="100.0" k_velocity="40.0" soft_lower_limit="-2.8973" soft_upper_limit="2.8973"/>
		<parent link="link2_y_to_3"/>
		<child link="link_2_to_3"/>
		<origin rpy="0 0 0" xyz="0 0 0"/>
		<axis xyz="0 0 1"/>
		<dynamics damping="10.0"/>
		<limit effort="10" lower="-3.1416" upper="3.1416" velocity="3"/>
		<limit effort="87" lower="-2.9671" upper="2.9671" velocity="2.1750"/>
	</joint>
	<joint name="joint2_x_to_7" type="revolute">
		<safety_controller k_position="100.0" k_velocity="40.0" soft_lower_limit="-2.8973" soft_upper_limit="2.8973"/>
		<parent link="link2_base"/>
		<child link="link2_x_to_7"/>
		<origin rpy="0 0 0" xyz="0 0 0"/>
		<axis xyz="1 0 0"/>
		<dynamics damping="10.0"/>
		<limit effort="10" lower="-3.1416" upper="3.1416" velocity="3"/>
		<limit effort="87" lower="-2.9671" upper="2.9671" velocity="2.1750"/>
	</joint>
	<link name="link2_x_to_7">
		<inertial>
			<mass value="0.001"/>
			<inertia ixx="0.001" ixy="0" ixz="0" iyy="0.001" iyz="0" izz="0.001"/>
		</inertial>
	</link>
	<joint name="joint2_y_to_7" type="revolute">
		<safety_controller k_position="100.0" k_velocity="40.0" soft_lower_limit="-2.8973" soft_upper_limit="2.8973"/>
		<parent link="link2_x_to_7"/>
		<child link="link2_y_to_7"/>
		<origin rpy="0 0 0" xyz="0 0 0"/>
		<axis xyz="0 1 0"/>
		<dynamics damping="10.0"/>
		<limit effort="10" lower="-3.1416" upper="3.1416" velocity="3"/>
		<limit effort="87" lower="-2.9671" upper="2.9671" velocity="2.1750"/>
	</joint>
	<link name="link2_y_to_7">
		<inertial>
			<mass value="0.001"/>
			<inertia ixx="0.001" ixy="0" ixz="0" iyy="0.001" iyz="0" izz="0.001"/>
		</inertial>
	</link>
	<joint name="joint2_z_to_7" type="revolute">
		<safety_controller k_position="100.0" k_velocity="40.0" soft_lower_limit="-2.8973" soft_upper_limit="2.8973"/>
		<parent link="link2_y_to_7"/>
		<child link="link_2_to_7"/>
		<origin rpy="0 0 0" xyz="0 0 0"/>
		<axis xyz="0 0 1"/>
		<dynamics damping="10.0"/>
		<limit effort="10" lower="-3.1416" upper="3.1416" velocity="3"/>
		<limit effort="87" lower="-2.9671" upper="2.9671" velocity="2.1750"/>
	</joint>
	<joint name="joint2_x_to_12" type="revolute">
		<safety_controller k_position="100.0" k_velocity="40.0" soft_lower_limit="-2.8973" soft_upper_limit="2.8973"/>
		<parent link="link2_base"/>
		<child link="link2_x_to_12"/>
		<origin rpy="0 0 0" xyz="0 0 0"/>
		<axis xyz="1 0 0"/>
		<dynamics damping="10.0"/>
		<limit effort="10" lower="-3.1416" upper="3.1416" velocity="3"/>
		<limit effort="87" lower="-2.9671" upper="2.9671" velocity="2.1750"/>
	</joint>
	<link name="link2_x_to_12">
		<inertial>
			<mass value="0.001"/>
			<inertia ixx="0.001" ixy="0" ixz="0" iyy="0.001" iyz="0" izz="0.001"/>
		</inertial>
	</link>
	<joint name="joint2_y_to_12" type="revolute">
		<safety_controller k_position="100.0" k_velocity="40.0" soft_lower_limit="-2.8973" soft_upper_limit="2.8973"/>
		<parent link="link2_x_to_12"/>
		<child link="link2_y_to_12"/>
		<origin rpy="0 0 0" xyz="0 0 0"/>
		<axis xyz="0 1 0"/>
		<dynamics damping="10.0"/>
		<limit effort="10" lower="-3.1416" upper="3.1416" velocity="3"/>
		<limit effort="87" lower="-2.9671" upper="2.9671" velocity="2.1750"/>
	</joint>
	<link name="link2_y_to_12">
		<inertial>
			<mass value="0.001"/>
			<inertia ixx="0.001" ixy="0" ixz="0" iyy="0.001" iyz="0" izz="0.001"/>
		</inertial>
	</link>
	<joint name="joint2_z_to_12" type="revolute">
		<safety_controller k_position="100.0" k_velocity="40.0" soft_lower_limit="-2.8973" soft_upper_limit="2.8973"/>
		<parent link="link2_y_to_12"/>
		<child link="link_2_to_12"/>
		<origin rpy="0 0 0" xyz="0 0 0"/>
		<axis xyz="0 0 1"/>
		<dynamics damping="10.0"/>
		<limit effort="10" lower="-3.1416" upper="3.1416" velocity="3"/>
		<limit effort="87" lower="-2.9671" upper="2.9671" velocity="2.1750"/>
	</joint>
	<link name="link_2_to_3">
		<visual>
			<origin rpy="-0.23918349040601286 0.0 -2.9515778890791724" xyz="0.004726284635840586 -0.02457317177848754 0.10261803977510953"/>
			<geometry>
				<cylinder length="0.21125" radius="0.013960975840575722"/>
			</geometry>
			<material name="brown"/>
		</visual>
		<collision>
			<origin rpy="-0.23918349040601286 0.0 -2.9515778890791724" xyz="0.004726284635840586 -0.02457317177848754 0.10261803977510953"/>
			<geometry>
				<cylinder length="0.21125" radius="0.013960975840575722"/>
			</geometry>
		</collision>
	</link>
	<link name="link_2_to_7">
		<visual>
			<origin rpy="-1.7109419339702356 0.0 2.845661130029439" xyz="-0.019825986157643485 -0.06502795592417376 -0.009590405896683751"/>
			<geometry>
				<cylinder length="0.13731250000000006" radius="0.008800000000000002"/>
			</geometry>
			<material name="brown"/>
		</visual>
		<collision>
			<origin rpy="-1.7109419339702356 0.0 2.845661130029439" xyz="-0.019825986157643485 -0.06502795592417376 -0.009590405896683751"/>
			<geometry>
				<cylinder length="0.13731250000000006" radius="0.008800000000000002"/>
			</geometry>
		</collision>
	</link>
	<link name="link_2_to_12">
		<visual>
			<origin rpy="-1.5833532004261681 0.0 -0.5474807827015248" xyz="0.023227984792052795 0.038100876694831066 -0.0005603553799601868"/>
			<geometry>
				<cylinder length="0.08925312500000003" radius="0.008"/>
			</geometry>
			<material name="brown"/>
		</visual>
		<collision>
			<origin rpy="-1.5833532004261681 0.0 -0.5474807827015248" xyz="0.023227984792052795 0.038100876694831066 -0.0005603553799601868"/>
			<geometry>
				<cylinder length="0.08925312500000003" radius="0.008"/>
			</geometry>
		</collision>
	</link>
	<joint name="joint3_base" type="fixed">
		<parent link="link_2_to_3"/>
		<origin rpy="0 0 0" xyz="0.009452569271681172 -0.04914634355697508 0.20523607955021905"/>
		<child link="link3_base"/>
	</joint>
	<link name="link3_base">
		<inertial>
			<mass value="0.001"/>
			<inertia ixx="0.001" ixy="0" ixz="0" iyy="0.001" iyz="0" izz="0.001"/>
		</inertial>
	</link>
	<joint name="joint3_x_to_5" type="revolute">
		<safety_controller k_position="100.0" k_velocity="40.0" soft_lower_limit="-2.8973" soft_upper_limit="2.8973"/>
		<parent link="link3_base"/>
		<child link="link3_x_to_5"/>
		<origin rpy="0 0 0" xyz="0 0 0"/>
		<axis xyz="1 0 0"/>
		<dynamics damping="10.0"/>
		<limit effort="10" lower="-3.1416" upper="3.1416" velocity="3"/>
		<limit effort="87" lower="-2.9671" upper="2.9671" velocity="2.1750"/>
	</joint>
	<link name="link3_x_to_5">
		<inertial>
			<mass value="0.001"/>
			<inertia ixx="0.001" ixy="0" ixz="0" iyy="0.001" iyz="0" izz="0.001"/>
		</inertial>
	</link>
	<joint name="joint3_y_to_5" type="revolute">
		<safety_controller k_position="100.0" k_velocity="40.0" soft_lower_limit="-2.8973" soft_upper_limit="2.8973"/>
		<parent link="link3_x_to_5"/>
		<child link="link3_y_to_5"/>
		<origin rpy="0 0 0" xyz="0 0 0"/>
		<axis xyz="0 1 0"/>
		<dynamics damping="10.0"/>
		<limit effort="10" lower="-3.1416" upper="3.1416" velocity="3"/>
		<limit effort="87" lower="-2.9671" upper="2.9671" velocity="2.1750"/>
	</joint>
	<link name="link3_y_to_5">
		<inertial>
			<mass value="0.001"/>
			<inertia ixx="0.001" ixy="0" ixz="0" iyy="0.001" iyz="0" izz="0.001"/>
		</inertial>
	</link>
	<joint name="joint3_z_to_5" type="revolute">
		<safety_controller k_position="100.0" k_velocity="40.0" soft_lower_limit="-2.8973" soft_upper_limit="2.8973"/>
		<parent link="link3_y_to_5"/>
		<child link="link_3_to_5"/>
		<origin rpy="0 0 0" xyz="0 0 0"/>
		<axis xyz="0 0 1"/>
		<dynamics damping="10.0"/>
		<limit effort="10" lower="-3.1416" upper="3.1416" velocity="3"/>
		<limit effort="87" lower="-2.9671" upper="2.9671" velocity="2.1750"/>
	</joint>
	<joint name="joint3_x_to_9" type="revolute">
		<safety_controller k_position="100.0" k_velocity="40.0" soft_lower_limit="-2.8973" soft_upper_limit="2.8973"/>
		<parent link="link3_base"/>
		<child link="link3_x_to_9"/>
		<origin rpy="0 0 0" xyz="0 0 0"/>
		<axis xyz="1 0 0"/>
		<dynamics damping="10.0"/>
		<limit effort="10" lower="-3.1416" upper="3.1416" velocity="3"/>
		<limit effort="87" lower="-2.9671" upper="2.9671" velocity="2.1750"/>
	</joint>
	<link name="link3_x_to_9">
		<inertial>
			<mass value="0.001"/>
			<inertia ixx="0.001" ixy="0" ixz="0" iyy="0.001" iyz="0" izz="0.001"/>
		</inertial>
	</link>
	<joint name="joint3_y_to_9" type="revolute">
		<safety_controller k_position="100.0" k_velocity="40.0" soft_lower_limit="-2.8973" soft_upper_limit="2.8973"/>
		<parent link="link3_x_to_9"/>
		<child link="link3_y_to_9"/>
		<origin rpy="0 0 0" xyz="0 0 0"/>
		<axis xyz="0 1 0"/>
		<dynamics damping="10.0"/>
		<limit effort="10" lower="-3.1416" upper="3.1416" velocity="3"/>
		<limit effort="87" lower="-2.9671" upper="2.9671" velocity="2.1750"/>
	</joint>
	<link name="link3_y_to_9">
		<inertial>
			<mass value="0.001"/>
			<inertia ixx="0.001" ixy="0" ixz="0" iyy="0.001" iyz="0" izz="0.001"/>
		</inertial>
	</link>
	<joint name="joint3_z_to_9" type="revolute">
		<safety_controller k_position="100.0" k_velocity="40.0" soft_lower_limit="-2.8973" soft_upper_limit="2.8973"/>
		<parent link="link3_y_to_9"/>
		<child link="link_3_to_9"/>
		<origin rpy="0 0 0" xyz="0 0 0"/>
		<axis xyz="0 0 1"/>
		<dynamics damping="10.0"/>
		<limit effort="10" lower="-3.1416" upper="3.1416" velocity="3"/>
		<limit effort="87" lower="-2.9671" upper="2.9671" velocity="2.1750"/>
	</joint>
	<link name="link_3_to_5">
		<visual>
			<origin rpy="-0.34347834095619323 0.0 -2.057215930902548" xyz="0.02043922309257641 -0.010808217519534334 0.06464596860968841"/>
			<geometry>
				<cylinder length="0.13731249999999995" radius="0.011087305239074889"/>
			</geometry>
			<material name="brown"/>
		</visual>
		<collision>
			<origin rpy="-0.34347834095619323 0.0 -2.057215930902548" xyz="0.02043922309257641 -0.010808217519534334 0.06464596860968841"/>
			<geometry>
				<cylinder length="0.13731249999999995" radius="0.011087305239074889"/>
			</geometry>
		</collision>
	</link>
	<link name="link_3_to_9">
		<visual>
			<origin rpy="-1.326172939463421 2.220446049250313e-16 1.0714908188899919" xyz="-0.03801194847083118 0.02073175740419406 0.010808149191740779"/>
			<geometry>
				<cylinder length="0.08925312500000003" radius="0.008800000000000002"/>
			</geometry>
			<material name="brown"/>
		</visual>
		<collision>
			<origin rpy="-1.326172939463421 2.220446049250313e-16 1.0714908188899919" xyz="-0.03801194847083118 0.02073175740419406 0.010808149191740779"/>
			<geometry>
				<cylinder length="0.08925312500000003" radius="0.008800000000000002"/>
			</geometry>
		</collision>
	</link>
	<joint name="joint4_base" type="fixed">
		<parent link="link_1_to_4"/>
		<origin rpy="0 0 0" xyz="-0.1378385269457811 0.14416430375648384 0.0695971013176947"/>
		<child link="link4_base"/>
	</joint>
	<link name="link4_base">
		<inertial>
			<mass value="0.001"/>
			<inertia ixx="0.001" ixy="0" ixz="0" iyy="0.001" iyz="0" izz="0.001"/>
		</inertial>
	</link>
	<joint name="joint4_x_to_6" type="revolute">
		<safety_controller k_position="100.0" k_velocity="40.0" soft_lower_limit="-2.8973" soft_upper_limit="2.8973"/>
		<parent link="link4_base"/>
		<child link="link4_x_to_6"/>
		<origin rpy="0 0 0" xyz="0 0 0"/>
		<axis xyz="1 0 0"/>
		<dynamics damping="10.0"/>
		<limit effort="10" lower="-3.1416" upper="3.1416" velocity="3"/>
		<limit effort="87" lower="-2.9671" upper="2.9671" velocity="2.1750"/>
	</joint>
	<link name="link4_x_to_6">
		<inertial>
			<mass value="0.001"/>
			<inertia ixx="0.001" ixy="0" ixz="0" iyy="0.001" iyz="0" izz="0.001"/>
		</inertial>
	</link>
	<joint name="joint4_y_to_6" type="revolute">
		<safety_controller k_position="100.0" k_velocity="40.0" soft_lower_limit="-2.8973" soft_upper_limit="2.8973"/>
		<parent link="link4_x_to_6"/>
		<child link="link4_y_to_6"/>
		<origin rpy="0 0 0" xyz="0 0 0"/>
		<axis xyz="0 1 0"/>
		<dynamics damping="10.0"/>
		<limit effort="10" lower="-3.1416" upper="3.1416" velocity="3"/>
		<limit effort="87" lower="-2.9671" upper="2.9671" velocity="2.1750"/>
	</joint>
	<link name="link4_y_to_6">
		<inertial>
			<mass value="0.001"/>
			<inertia ixx="0.001" ixy="0" ixz="0" iyy="0.001" iyz="0" izz="0.001"/>
		</inertial>
	</link>
	<joint name="joint4_z_to_6" type="revolute">
		<safety_controller k_position="100.0" k_velocity="40.0" soft_lower_limit="-2.8973" soft_upper_limit="2.8973"/>
		<parent link="link4_y_to_6"/>
		<child link="link_4_to_6"/>
		<origin rpy="0 0 0" xyz="0 0 0"/>
		<axis xyz="0 0 1"/>
		<dynamics damping="10.0"/>
		<limit effort="10" lower="-3.1416" upper="3.1416" velocity="3"/>
		<limit effort="87" lower="-2.9671" upper="2.9671" velocity="2.1750"/>
	</joint>
	<joint name="joint4_x_to_13" type="revolute">
		<safety_controller k_position="100.0" k_velocity="40.0" soft_lower_limit="-2.8973" soft_upper_limit="2.8973"/>
		<parent link="link4_base"/>
		<child link="link4_x_to_13"/>
		<origin rpy="0 0 0" xyz="0 0 0"/>
		<axis xyz="1 0 0"/>
		<dynamics damping="10.0"/>
		<limit effort="10" lower="-3.1416" upper="3.1416" velocity="3"/>
		<limit effort="87" lower="-2.9671" upper="2.9671" velocity="2.1750"/>
	</joint>
	<link name="link4_x_to_13">
		<inertial>
			<mass value="0.001"/>
			<inertia ixx="0.001" ixy="0" ixz="0" iyy="0.001" iyz="0" izz="0.001"/>
		</inertial>
	</link>
	<joint name="joint4_y_to_13" type="revolute">
		<safety_controller k_position="100.0" k_velocity="40.0" soft_lower_limit="-2.8973" soft_upper_limit="2.8973"/>
		<parent link="link4_x_to_13"/>
		<child link="link4_y_to_13"/>
		<origin rpy="0 0 0" xyz="0 0 0"/>
		<axis xyz="0 1 0"/>
		<dynamics damping="10.0"/>
		<limit effort="10" lower="-3.1416" upper="3.1416" velocity="3"/>
		<limit effort="87" lower="-2.9671" upper="2.9671" velocity="2.1750"/>
	</joint>
	<link name="link4_y_to_13">
		<inertial>
			<mass value="0.001"/>
			<inertia ixx="0.001" ixy="0" ixz="0" iyy="0.001" iyz="0" izz="0.001"/>
		</inertial>
	</link>
	<joint name="joint4_z_to_13" type="revolute">
		<safety_controller k_position="100.0" k_velocity="40.0" soft_lower_limit="-2.8973" soft_upper_limit="2.8973"/>
		<parent link="link4_y_to_13"/>
		<child link="link_4_to_13"/>
		<origin rpy="0 0 0" xyz="0 0 0"/>
		<axis xyz="0 0 1"/>
		<dynamics damping="10.0"/>
		<limit effort="10" lower="-3.1416" upper="3.1416" velocity="3"/>
		<limit effort="87" lower="-2.9671" upper="2.9671" velocity="2.1750"/>
	</joint>
	<link name="link_4_to_6">
		<visual>
			<origin rpy="-1.6191837604531658 0.0 1.100631674329004" xyz="-0.061134975956634474 0.03106714732242173 -0.003320803530950045"/>
			<geometry>
				<cylinder length="0.1373125" radius="0.008800000000000002"/>
			</geometry>
			<material name="brown"/>
		</visual>
		<collision>
			<origin rpy="-1.6191837604531658 0.0 1.100631674329004" xyz="-0.061134975956634474 0.03106714732242173 -0.003320803530950045"/>
			<geometry>
				<cylinder length="0.1373125" radius="0.008800000000000002"/>
			</geometry>
		</collision>
	</link>
	<link name="link_4_to_13">
		<visual>
			<origin rpy="-2.2583852400999844 0.0 2.984345895654244" xyz="-0.00540056169707033 -0.034060961329239595 -0.028323398935343025"/>
			<geometry>
				<cylinder length="0.08925312500000006" radius="0.008"/>
			</geometry>
			<material name="brown"/>
		</visual>
		<collision>
			<origin rpy="-2.2583852400999844 0.0 2.984345895654244" xyz="-0.00540056169707033 -0.034060961329239595 -0.028323398935343025"/>
			<geometry>
				<cylinder length="0.08925312500000006" radius="0.008"/>
			</geometry>
		</collision>
	</link>
	<joint name="joint5_base" type="fixed">
		<parent link="link_3_to_5"/>
		<origin rpy="0 0 0" xyz="0.04087844618515282 -0.021616435039068668 0.12929193721937682"/>
		<child link="link5_base"/>
	</joint>
	<link name="link5_base">
		<inertial>
			<mass value="0.001"/>
			<inertia ixx="0.001" ixy="0" ixz="0" iyy="0.001" iyz="0" izz="0.001"/>
		</inertial>
	</link>
	<joint name="joint5_x_to_10" type="revolute">
		<safety_controller k_position="100.0" k_velocity="40.0" soft_lower_limit="-2.8973" soft_upper_limit="2.8973"/>
		<parent link="link5_base"/>
		<child link="link5_x_to_10"/>
		<origin rpy="0 0 0" xyz="0 0 0"/>
		<axis xyz="1 0 0"/>
		<dynamics damping="10.0"/>
		<limit effort="10" lower="-3.1416" upper="3.1416" velocity="3"/>
		<limit effort="87" lower="-2.9671" upper="2.9671" velocity="2.1750"/>
	</joint>
	<link name="link5_x_to_10">
		<inertial>
			<mass value="0.001"/>
			<inertia ixx="0.001" ixy="0" ixz="0" iyy="0.001" iyz="0" izz="0.001"/>
		</inertial>
	</link>
	<joint name="joint5_y_to_10" type="revolute">
		<safety_controller k_position="100.0" k_velocity="40.0" soft_lower_limit="-2.8973" soft_upper_limit="2.8973"/>
		<parent link="link5_x_to_10"/>
		<child link="link5_y_to_10"/>
		<origin rpy="0 0 0" xyz="0 0 0"/>
		<axis xyz="0 1 0"/>
		<dynamics damping="10.0"/>
		<limit effort="10" lower="-3.1416" upper="3.1416" velocity="3"/>
		<limit effort="87" lower="-2.9671" upper="2.9671" velocity="2.1750"/>
	</joint>
	<link name="link5_y_to_10">
		<inertial>
			<mass value="0.001"/>
			<inertia ixx="0.001" ixy="0" ixz="0" iyy="0.001" iyz="0" izz="0.001"/>
		</inertial>
	</link>
	<joint name="joint5_z_to_10" type="revolute">
		<safety_controller k_position="100.0" k_velocity="40.0" soft_lower_limit="-2.8973" soft_upper_limit="2.8973"/>
		<parent link="link5_y_to_10"/>
		<child link="link_5_to_10"/>
		<origin rpy="0 0 0" xyz="0 0 0"/>
		<axis xyz="0 0 1"/>
		<dynamics damping="10.0"/>
		<limit effort="10" lower="-3.1416" upper="3.1416" velocity="3"/>
		<limit effort="87" lower="-2.9671" upper="2.9671" velocity="2.1750"/>
	</joint>
	<joint name="joint5_x_to_18" type="revolute">
		<safety_controller k_position="100.0" k_velocity="40.0" soft_lower_limit="-2.8973" soft_upper_limit="2.8973"/>
		<parent link="link5_base"/>
		<child link="link5_x_to_18"/>
		<origin rpy="0 0 0" xyz="0 0 0"/>
		<axis xyz="1 0 0"/>
		<dynamics damping="10.0"/>
		<limit effort="10" lower="-3.1416" upper="3.1416" velocity="3"/>
		<limit effort="87" lower="-2.9671" upper="2.9671" velocity="2.1750"/>
	</joint>
	<link name="link5_x_to_18">
		<inertial>
			<mass value="0.001"/>
			<inertia ixx="0.001" ixy="0" ixz="0" iyy="0.001" iyz="0" izz="0.001"/>
		</inertial>
	</link>
	<joint name="joint5_y_to_18" type="revolute">
		<safety_controller k_position="100.0" k_velocity="40.0" soft_lower_limit="-2.8973" soft_upper_limit="2.8973"/>
		<parent link="link5_x_to_18"/>
		<child link="link5_y_to_18"/>
		<origin rpy="0 0 0" xyz="0 0 0"/>
		<axis xyz="0 1 0"/>
		<dynamics damping="10.0"/>
		<limit effort="10" lower="-3.1416" upper="3.1416" velocity="3"/>
		<limit effort="87" lower="-2.9671" upper="2.9671" velocity="2.1750"/>
	</joint>
	<link name="link5_y_to_18">
		<inertial>
			<mass value="0.001"/>
			<inertia ixx="0.001" ixy="0" ixz="0" iyy="0.001" iyz="0" izz="0.001"/>
		</inertial>
	</link>
	<joint name="joint5_z_to_18" type="revolute">
		<safety_controller k_position="100.0" k_velocity="40.0" soft_lower_limit="-2.8973" soft_upper_limit="2.8973"/>
		<parent link="link5_y_to_18"/>
		<child link="link_5_to_18"/>
		<origin rpy="0 0 0" xyz="0 0 0"/>
		<axis xyz="0 0 1"/>
		<dynamics damping="10.0"/>
		<limit effort="10" lower="-3.1416" upper="3.1416" velocity="3"/>
		<limit effort="87" lower="-2.9671" upper="2.9671" velocity="2.1750"/>
	</joint>
	<link name="link_5_to_10">
		<visual>
			<origin rpy="-0.9755776496353595 0.0 -1.7292722029014715" xyz="0.036488903498884805 -0.005831511583673336 0.02502166011009188"/>
			<geometry>
				<cylinder length="0.08925312500000003" radius="0.008"/>
			</geometry>
			<material name="brown"/>
		</visual>
		<collision>
			<origin rpy="-0.9755776496353595 0.0 -1.7292722029014715" xyz="0.036488903498884805 -0.005831511583673336 0.02502166011009188"/>
			<geometry>
				<cylinder length="0.08925312500000003" radius="0.008"/>
			</geometry>
		</collision>
	</link>
	<link name="link_5_to_18">
		<visual>
			<origin rpy="-0.8694268053605536 0.0 2.09783618512411" xyz="-0.019153199793388503 -0.011146157331840094 0.018717360215792067"/>
			<geometry>
				<cylinder length="0.058014531249999966" radius="0.008"/>
			</geometry>
			<material name="brown"/>
		</visual>
		<collision>
			<origin rpy="-0.8694268053605536 0.0 2.09783618512411" xyz="-0.019153199793388503 -0.011146157331840094 0.018717360215792067"/>
			<geometry>
				<cylinder length="0.058014531249999966" radius="0.008"/>
			</geometry>
		</collision>
	</link>
	<joint name="joint6_base" type="fixed">
		<parent link="link_4_to_6"/>
		<origin rpy="0 0 0" xyz="-0.12226995191326895 0.06213429464484346 -0.00664160706190009"/>
		<child link="link6_base"/>
	</joint>
	<link name="link6_base">
		<inertial>
			<mass value="0.001"/>
			<inertia ixx="0.001" ixy="0" ixz="0" iyy="0.001" iyz="0" izz="0.001"/>
		</inertial>
	</link>
	<joint name="joint6_x_to_11" type="revolute">
		<safety_controller k_position="100.0" k_velocity="40.0" soft_lower_limit="-2.8973" soft_upper_limit="2.8973"/>
		<parent link="link6_base"/>
		<child link="link6_x_to_11"/>
		<origin rpy="0 0 0" xyz="0 0 0"/>
		<axis xyz="1 0 0"/>
		<dynamics damping="10.0"/>
		<limit effort="10" lower="-3.1416" upper="3.1416" velocity="3"/>
		<limit effort="87" lower="-2.9671" upper="2.9671" velocity="2.1750"/>
	</joint>
	<link name="link6_x_to_11">
		<inertial>
			<mass value="0.001"/>
			<inertia ixx="0.001" ixy="0" ixz="0" iyy="0.001" iyz="0" izz="0.001"/>
		</inertial>
	</link>
	<joint name="joint6_y_to_11" type="revolute">
		<safety_controller k_position="100.0" k_velocity="40.0" soft_lower_limit="-2.8973" soft_upper_limit="2.8973"/>
		<parent link="link6_x_to_11"/>
		<child link="link6_y_to_11"/>
		<origin rpy="0 0 0" xyz="0 0 0"/>
		<axis xyz="0 1 0"/>
		<dynamics damping="10.0"/>
		<limit effort="10" lower="-3.1416" upper="3.1416" velocity="3"/>
		<limit effort="87" lower="-2.9671" upper="2.9671" velocity="2.1750"/>
	</joint>
	<link name="link6_y_to_11">
		<inertial>
			<mass value="0.001"/>
			<inertia ixx="0.001" ixy="0" ixz="0" iyy="0.001" iyz="0" izz="0.001"/>
		</inertial>
	</link>
	<joint name="joint6_z_to_11" type="revolute">
		<safety_controller k_position="100.0" k_velocity="40.0" soft_lower_limit="-2.8973" soft_upper_limit="2.8973"/>
		<parent link="link6_y_to_11"/>
		<child link="link_6_to_11"/>
		<origin rpy="0 0 0" xyz="0 0 0"/>
		<axis xyz="0 0 1"/>
		<dynamics damping="10.0"/>
		<limit effort="10" lower="-3.1416" upper="3.1416" velocity="3"/>
		<limit effort="87" lower="-2.9671" upper="2.9671" velocity="2.1750"/>
	</joint>
	<link name="link_6_to_11">
		<visual>
			<origin rpy="-1.4914377746263188 0.0 0.6221418808579139" xyz="-0.025925485492361983 0.03615084192534533 0.003537783294724317"/>
			<geometry>
				<cylinder length="0.08925312500000003" radius="0.008"/>
			</geometry>
			<material name="brown"/>
		</visual>
		<collision>
			<origin rpy="-1.4914377746263188 0.0 0.6221418808579139" xyz="-0.025925485492361983 0.03615084192534533 0.003537783294724317"/>
			<geometry>
				<cylinder length="0.08925312500000003" radius="0.008"/>
			</geometry>
		</collision>
	</link>
	<joint name="joint7_base" type="fixed">
		<parent link="link_2_to_7"/>
		<origin rpy="0 0 0" xyz="-0.03965197231528697 -0.13005591184834753 -0.019180811793367503"/>
		<child link="link7_base"/>
	</joint>
	<link name="link7_base">
		<inertial>
			<mass value="0.001"/>
			<inertia ixx="0.001" ixy="0" ixz="0" iyy="0.001" iyz="0" izz="0.001"/>
		</inertial>
	</link>
	<joint name="joint7_x_to_15" type="revolute">
		<safety_controller k_position="100.0" k_velocity="40.0" soft_lower_limit="-2.8973" soft_upper_limit="2.8973"/>
		<parent link="link7_base"/>
		<child link="link7_x_to_15"/>
		<origin rpy="0 0 0" xyz="0 0 0"/>
		<axis xyz="1 0 0"/>
		<dynamics damping="10.0"/>
		<limit effort="10" lower="-3.1416" upper="3.1416" velocity="3"/>
		<limit effort="87" lower="-2.9671" upper="2.9671" velocity="2.1750"/>
	</joint>
	<link name="link7_x_to_15">
		<inertial>
			<mass value="0.001"/>
			<inertia ixx="0.001" ixy="0" ixz="0" iyy="0.001" iyz="0" izz="0.001"/>
		</inertial>
	</link>
	<joint name="joint7_y_to_15" type="revolute">
		<safety_controller k_position="100.0" k_velocity="40.0" soft_lower_limit="-2.8973" soft_upper_limit="2.8973"/>
		<parent link="link7_x_to_15"/>
		<child link="link7_y_to_15"/>
		<origin rpy="0 0 0" xyz="0 0 0"/>
		<axis xyz="0 1 0"/>
		<dynamics damping="10.0"/>
		<limit effort="10" lower="-3.1416" upper="3.1416" velocity="3"/>
		<limit effort="87" lower="-2.9671" upper="2.9671" velocity="2.1750"/>
	</joint>
	<link name="link7_y_to_15">
		<inertial>
			<mass value="0.001"/>
			<inertia ixx="0.001" ixy="0" ixz="0" iyy="0.001" iyz="0" izz="0.001"/>
		</inertial>
	</link>
	<joint name="joint7_z_to_15" type="revolute">
		<safety_controller k_position="100.0" k_velocity="40.0" soft_lower_limit="-2.8973" soft_upper_limit="2.8973"/>
		<parent link="link7_y_to_15"/>
		<child link="link_7_to_15"/>
		<origin rpy="0 0 0" xyz="0 0 0"/>
		<axis xyz="0 0 1"/>
		<dynamics damping="10.0"/>
		<limit effort="10" lower="-3.1416" upper="3.1416" velocity="3"/>
		<limit effort="87" lower="-2.9671" upper="2.9671" velocity="2.1750"/>
	</joint>
	<link name="link_7_to_15">
		<visual>
			<origin rpy="-1.498101675925098 0.0 2.3472904885164825" xyz="-0.031751382367123326 -0.03119092910903451 0.0032412558767120347"/>
			<geometry>
				<cylinder length="0.08925312500000002" radius="0.008"/>
			</geometry>
			<material name="brown"/>
		</visual>
		<collision>
			<origin rpy="-1.498101675925098 0.0 2.3472904885164825" xyz="-0.031751382367123326 -0.03119092910903451 0.0032412558767120347"/>
			<geometry>
				<cylinder length="0.08925312500000002" radius="0.008"/>
			</geometry>
		</collision>
	</link>
	<joint name="joint8_base" type="fixed">
		<parent link="link_1_to_8"/>
		<origin rpy="0 0 0" xyz="0.11917053319498508 -0.06518456092038091 0.020101733554350965"/>
		<child link="link8_base"/>
	</joint>
	<link name="link8_base">
		<inertial>
			<mass value="0.001"/>
			<inertia ixx="0.001" ixy="0" ixz="0" iyy="0.001" iyz="0" izz="0.001"/>
		</inertial>
	</link>
	<joint name="joint8_x_to_14" type="revolute">
		<safety_controller k_position="100.0" k_velocity="40.0" soft_lower_limit="-2.8973" soft_upper_limit="2.8973"/>
		<parent link="link8_base"/>
		<child link="link8_x_to_14"/>
		<origin rpy="0 0 0" xyz="0 0 0"/>
		<axis xyz="1 0 0"/>
		<dynamics damping="10.0"/>
		<limit effort="10" lower="-3.1416" upper="3.1416" velocity="3"/>
		<limit effort="87" lower="-2.9671" upper="2.9671" velocity="2.1750"/>
	</joint>
	<link name="link8_x_to_14">
		<inertial>
			<mass value="0.001"/>
			<inertia ixx="0.001" ixy="0" ixz="0" iyy="0.001" iyz="0" izz="0.001"/>
		</inertial>
	</link>
	<joint name="joint8_y_to_14" type="revolute">
		<safety_controller k_position="100.0" k_velocity="40.0" soft_lower_limit="-2.8973" soft_upper_limit="2.8973"/>
		<parent link="link8_x_to_14"/>
		<child link="link8_y_to_14"/>
		<origin rpy="0 0 0" xyz="0 0 0"/>
		<axis xyz="0 1 0"/>
		<dynamics damping="10.0"/>
		<limit effort="10" lower="-3.1416" upper="3.1416" velocity="3"/>
		<limit effort="87" lower="-2.9671" upper="2.9671" velocity="2.1750"/>
	</joint>
	<link name="link8_y_to_14">
		<inertial>
			<mass value="0.001"/>
			<inertia ixx="0.001" ixy="0" ixz="0" iyy="0.001" iyz="0" izz="0.001"/>
		</inertial>
	</link>
	<joint name="joint8_z_to_14" type="revolute">
		<safety_controller k_position="100.0" k_velocity="40.0" soft_lower_limit="-2.8973" soft_upper_limit="2.8973"/>
		<parent link="link8_y_to_14"/>
		<child link="link_8_to_14"/>
		<origin rpy="0 0 0" xyz="0 0 0"/>
		<axis xyz="0 0 1"/>
		<dynamics damping="10.0"/>
		<limit effort="10" lower="-3.1416" upper="3.1416" velocity="3"/>
		<limit effort="87" lower="-2.9671" upper="2.9671" velocity="2.1750"/>
	</joint>
	<link name="link_8_to_14">
		<visual>
			<origin rpy="-1.2487655418423942 2.220446049250313e-16 -1.7845918896882926" xyz="0.04136871887594308 -0.008981714392422166 0.014124021583902913"/>
			<geometry>
				<cylinder length="0.08925312500000004" radius="0.008"/>
			</geometry>
			<material name="brown"/>
		</visual>
		<collision>
			<origin rpy="-1.2487655418423942 2.220446049250313e-16 -1.7845918896882926" xyz="0.04136871887594308 -0.008981714392422166 0.014124021583902913"/>
			<geometry>
				<cylinder length="0.08925312500000004" radius="0.008"/>
			</geometry>
		</collision>
	</link>
	<joint name="joint9_base" type="fixed">
		<parent link="link_3_to_9"/>
		<origin rpy="0 0 0" xyz="-0.07602389694166237 0.04146351480838812 0.021616298383481558"/>
		<child link="link9_base"/>
	</joint>
	<link name="link9_base">
		<inertial>
			<mass value="0.001"/>
			<inertia ixx="0.001" ixy="0" ixz="0" iyy="0.001" iyz="0" izz="0.001"/>
		</inertial>
	</link>
	<joint name="joint9_x_to_17" type="revolute">
		<safety_controller k_position="100.0" k_velocity="40.0" soft_lower_limit="-2.8973" soft_upper_limit="2.8973"/>
		<parent link="link9_base"/>
		<child link="link9_x_to_17"/>
		<origin rpy="0 0 0" xyz="0 0 0"/>
		<axis xyz="1 0 0"/>
		<dynamics damping="10.0"/>
		<limit effort="10" lower="-3.1416" upper="3.1416" velocity="3"/>
		<limit effort="87" lower="-2.9671" upper="2.9671" velocity="2.1750"/>
	</joint>
	<link name="link9_x_to_17">
		<inertial>
			<mass value="0.001"/>
			<inertia ixx="0.001" ixy="0" ixz="0" iyy="0.001" iyz="0" izz="0.001"/>
		</inertial>
	</link>
	<joint name="joint9_y_to_17" type="revolute">
		<safety_controller k_position="100.0" k_velocity="40.0" soft_lower_limit="-2.8973" soft_upper_limit="2.8973"/>
		<parent link="link9_x_to_17"/>
		<child link="link9_y_to_17"/>
		<origin rpy="0 0 0" xyz="0 0 0"/>
		<axis xyz="0 1 0"/>
		<dynamics damping="10.0"/>
		<limit effort="10" lower="-3.1416" upper="3.1416" velocity="3"/>
		<limit effort="87" lower="-2.9671" upper="2.9671" velocity="2.1750"/>
	</joint>
	<link name="link9_y_to_17">
		<inertial>
			<mass value="0.001"/>
			<inertia ixx="0.001" ixy="0" ixz="0" iyy="0.001" iyz="0" izz="0.001"/>
		</inertial>
	</link>
	<joint name="joint9_z_to_17" type="revolute">
		<safety_controller k_position="100.0" k_velocity="40.0" soft_lower_limit="-2.8973" soft_upper_limit="2.8973"/>
		<parent link="link9_y_to_17"/>
		<child link="link_9_to_17"/>
		<origin rpy="0 0 0" xyz="0 0 0"/>
		<axis xyz="0 0 1"/>
		<dynamics damping="10.0"/>
		<limit effort="10" lower="-3.1416" upper="3.1416" velocity="3"/>
		<limit effort="87" lower="-2.9671" upper="2.9671" velocity="2.1750"/>
	</joint>
	<link name="link_9_to_17">
		<visual>
			<origin rpy="-1.3122393120848697 2.220446049250313e-16 0.9187887722410144" xyz="-0.022290511776352426 0.017016063721088357 0.007416745865098884"/>
			<geometry>
				<cylinder length="0.05801453125000001" radius="0.008"/>
			</geometry>
			<material name="brown"/>
		</visual>
		<collision>
			<origin rpy="-1.3122393120848697 2.220446049250313e-16 0.9187887722410144" xyz="-0.022290511776352426 0.017016063721088357 0.007416745865098884"/>
			<geometry>
				<cylinder length="0.05801453125000001" radius="0.008"/>
			</geometry>
		</collision>
	</link>
	<joint name="joint10_base" type="fixed">
		<parent link="link_5_to_10"/>
		<origin rpy="0 0 0" xyz="0.07297780699776961 -0.011663023167346673 0.05004332022018376"/>
		<child link="link10_tip"/>
	</joint>
	<link name="link10_tip">
		<visual>
			<origin rpy="0 0 0" xyz="0 0 0"/>
			<geometry>
				<box size="0.016 0.016 0.016"/>
			</geometry>
			<material name="green"/>
		</visual>
		<collision>
			<origin rpy="0 0 0" xyz="0 0 0"/>
			<geometry>
				<box size="0.016 0.016 0.016"/>
			</geometry>
		</collision>
	</link>
	<joint name="joint11_base" type="fixed">
		<parent link="link_6_to_11"/>
		<origin rpy="0 0 0" xyz="-0.051850970984723965 0.07230168385069066 0.007075566589448634"/>
		<child link="link11_tip"/>
	</joint>
	<link name="link11_tip">
		<visual>
			<origin rpy="0 0 0" xyz="0 0 0"/>
			<geometry>
				<box size="0.016 0.016 0.016"/>
			</geometry>
			<material name="green"/>
		</visual>
		<collision>
			<origin rpy="0 0 0" xyz="0 0 0"/>
			<geometry>
				<box size="0.016 0.016 0.016"/>
			</geometry>
		</collision>
	</link>
	<joint name="joint12_base" type="fixed">
		<parent link="link_2_to_12"/>
		<origin rpy="0 0 0" xyz="0.04645596958410559 0.07620175338966213 -0.0011207107599203736"/>
		<child link="link12_tip"/>
	</joint>
	<link name="link12_tip">
		<visual>
			<origin rpy="0 0 0" xyz="0 0 0"/>
			<geometry>
				<box size="0.016 0.016 0.016"/>
			</geometry>
			<material name="green"/>
		</visual>
		<collision>
			<origin rpy="0 0 0" xyz="0 0 0"/>
			<geometry>
				<box size="0.016 0.016 0.016"/>
			</geometry>
		</collision>
	</link>
	<joint name="joint13_base" type="fixed">
		<parent link="link_4_to_13"/>
		<origin rpy="0 0 0" xyz="-0.01080112339414066 -0.06812192265847919 -0.05664679787068605"/>
		<child link="link13_tip"/>
	</joint>
	<link name="link13_tip">
		<visual>
			<origin rpy="0 0 0" xyz="0 0 0"/>
			<geometry>
				<box size="0.016 0.016 0.016"/>
			</geometry>
			<material name="green"/>
		</visual>
		<collision>
			<origin rpy="0 0 0" xyz="0 0 0"/>
			<geometry>
				<box size="0.016 0.016 0.016"/>
			</geometry>
		</collision>
	</link>
	<joint name="joint14_base" type="fixed">
		<parent link="link_8_to_14"/>
		<origin rpy="0 0 0" xyz="0.08273743775188616 -0.017963428784844332 0.028248043167805825"/>
		<child link="link14_tip"/>
	</joint>
	<link name="link14_tip">
		<visual>
			<origin rpy="0 0 0" xyz="0 0 0"/>
			<geometry>
				<box size="0.016 0.016 0.016"/>
			</geometry>
			<material name="green"/>
		</visual>
		<collision>
			<origin rpy="0 0 0" xyz="0 0 0"/>
			<geometry>
				<box size="0.016 0.016 0.016"/>
			</geometry>
		</collision>
	</link>
	<joint name="joint15_base" type="fixed">
		<parent link="link_7_to_15"/>
		<origin rpy="0 0 0" xyz="-0.06350276473424665 -0.06238185821806902 0.0064825117534240695"/>
		<child link="link15_tip"/>
	</joint>
	<link name="link15_tip">
		<visual>
			<origin rpy="0 0 0" xyz="0 0 0"/>
			<geometry>
				<box size="0.016 0.016 0.016"/>
			</geometry>
			<material name="green"/>
		</visual>
		<collision>
			<origin rpy="0 0 0" xyz="0 0 0"/>
			<geometry>
				<box size="0.016 0.016 0.016"/>
			</geometry>
		</collision>
	</link>
	<joint name="joint16_base" type="fixed">
		<parent link="link_1_to_16"/>
		<origin rpy="0 0 0" xyz="-0.06683240953397661 -0.03942863454620787 -0.04410138473982472"/>
		<child link="link16_tip"/>
	</joint>
	<link name="link16_tip">
		<visual>
			<origin rpy="0 0 0" xyz="0 0 0"/>
			<geometry>
				<box size="0.016 0.016 0.016"/>
			</geometry>
			<material name="green"/>
		</visual>
		<collision>
			<origin rpy="0 0 0" xyz="0 0 0"/>
			<geometry>
				<box size="0.016 0.016 0.016"/>
			</geometry>
		</collision>
	</link>
	<joint name="joint17_base" type="fixed">
		<parent link="link_9_to_17"/>
		<origin rpy="0 0 0" xyz="-0.04458102355270485 0.034032127442176714 0.014833491730197768"/>
		<child link="link17_tip"/>
	</joint>
	<link name="link17_tip">
		<visual>
			<origin rpy="0 0 0" xyz="0 0 0"/>
			<geometry>
				<box size="0.016 0.016 0.016"/>
			</geometry>
			<material name="green"/>
		</visual>
		<collision>
			<origin rpy="0 0 0" xyz="0 0 0"/>
			<geometry>
				<box size="0.016 0.016 0.016"/>
			</geometry>
		</collision>
	</link>
	<joint name="joint18_base" type="fixed">
		<parent link="link_5_to_18"/>
		<origin rpy="0 0 0" xyz="-0.03830639958677701 -0.022292314663680188 0.037434720431584134"/>
		<child link="link18_tip"/>
	</joint>
	<link name="link18_tip">
		<visual>
			<origin rpy="0 0 0" xyz="0 0 0"/>
			<geometry>
				<box size="0.016 0.016 0.016"/>
			</geometry>
			<material name="green"/>
		</visual>
		<collision>
			<origin rpy="0 0 0" xyz="0 0 0"/>
			<geometry>
				<box size="0.016 0.016 0.016"/>
			</geometry>
		</collision>
	</link>
</robot>
