<?xml version="1.0" ?>
<robot name="tree0">
	<material name="blue">
		<color rgba="0 0 0.8 1"/>
	</material>
	<material name="green">
		<color rgba="0 0.6 0 0.8"/>
	</material>
	<material name="brown">
		<color rgba="0.3 0.15 0.05 1.0"/>
	</material>
	<link name="base_link">
		<visual>
			<origin rpy="0 0 0" xyz="0 0 0"/>
			<geometry>
				<box size="1 1 0.02"/>
			</geometry>
			<material name="green"/>
		</visual>
		<collision>
			<origin rpy="0 0 0" xyz="0 0 0"/>
			<geometry>
				<box size="1 1 0.02"/>
			</geometry>
		</collision>
	</link>
	<joint name="joint0_base" type="fixed">
		<parent link="base_link"/>
		<origin rpy="0 0 0" xyz="0 0 0.01"/>
		<child link="link0_base"/>
	</joint>
	<link name="link0_base">
		<inertial>
			<mass value="0.001"/>
			<inertia ixx="0.001" ixy="0" ixz="0" iyy="0.001" iyz="0" izz="0.001"/>
		</inertial>
	</link>
	<joint name="joint0_x_to_1" type="revolute">
		<safety_controller k_position="100.0" k_velocity="40.0" soft_lower_limit="-2.8973" soft_upper_limit="2.8973"/>
		<parent link="link0_base"/>
		<child link="link0_x_to_1"/>
		<origin rpy="0 0 0" xyz="0 0 0"/>
		<axis xyz="1 0 0"/>
		<dynamics damping="10.0"/>
		<limit effort="10" lower="-3.1416" upper="3.1416" velocity="3"/>
		<limit effort="87" lower="-2.9671" upper="2.9671" velocity="2.1750"/>
	</joint>
	<link name="link0_x_to_1">
		<inertial>
			<mass value="0.001"/>
			<inertia ixx="0.001" ixy="0" ixz="0" iyy="0.001" iyz="0" izz="0.001"/>
		</inertial>
	</link>
	<joint name="joint0_y_to_1" type="revolute">
		<safety_controller k_position="100.0" k_velocity="40.0" soft_lower_limit="-2.8973" soft_upper_limit="2.8973"/>
		<parent link="link0_x_to_1"/>
		<child link="link0_y_to_1"/>
		<origin rpy="0 0 0" xyz="0 0 0"/>
		<axis xyz="0 1 0"/>
		<dynamics damping="10.0"/>
		<limit effort="10" lower="-3.1416" upper="3.1416" velocity="3"/>
		<limit effort="87" lower="-2.9671" upper="2.9671" velocity="2.1750"/>
	</joint>
	<link name="link0_y_to_1">
		<inertial>
			<mass value="0.001"/>
			<inertia ixx="0.001" ixy="0" ixz="0" iyy="0.001" iyz="0" izz="0.001"/>
		</inertial>
	</link>
	<joint name="joint0_z_to_1" type="revolute">
		<safety_controller k_position="100.0" k_velocity="40.0" soft_lower_limit="-2.8973" soft_upper_limit="2.8973"/>
		<parent link="link0_y_to_1"/>
		<child link="link_0_to_1"/>
		<origin rpy="0 0 0" xyz="0 0 0"/>
		<axis xyz="0 0 1"/>
		<dynamics damping="10.0"/>
		<limit effort="10" lower="-3.1416" upper="3.1416" velocity="3"/>
		<limit effort="87" lower="-2.9671" upper="2.9671" velocity="2.1750"/>
	</joint>
	<link name="link_0_to_1">
		<visual>
			<origin rpy="-0.02849087851830513 0.0 -1.5057452637882354" xyz="0.007106693003812901 0.0004629511329563823 0.24989854059357378"/>
			<geometry>
				<cylinder length="0.49999999999999994" radius="0.022552050582124256"/>
			</geometry>
			<material name="brown"/>
		</visual>
		<collision>
			<origin rpy="-0.02849087851830513 0.0 -1.5057452637882354" xyz="0.007106693003812901 0.0004629511329563823 0.24989854059357378"/>
			<geometry>
				<cylinder length="0.49999999999999994" radius="0.022552050582124256"/>
			</geometry>
		</collision>
	</link>
	<joint name="joint1_base" type="fixed">
		<parent link="link_0_to_1"/>
		<origin rpy="0 0 0" xyz="0.014213386007625802 0.0009259022659127646 0.49979708118714755"/>
		<child link="link1_base"/>
	</joint>
	<link name="link1_base">
		<inertial>
			<mass value="0.001"/>
			<inertia ixx="0.001" ixy="0" ixz="0" iyy="0.001" iyz="0" izz="0.001"/>
		</inertial>
	</link>
	<joint name="joint1_x_to_2" type="revolute">
		<safety_controller k_position="100.0" k_velocity="40.0" soft_lower_limit="-2.8973" soft_upper_limit="2.8973"/>
		<parent link="link1_base"/>
		<child link="link1_x_to_2"/>
		<origin rpy="0 0 0" xyz="0 0 0"/>
		<axis xyz="1 0 0"/>
		<dynamics damping="10.0"/>
		<limit effort="10" lower="-3.1416" upper="3.1416" velocity="3"/>
		<limit effort="87" lower="-2.9671" upper="2.9671" velocity="2.1750"/>
	</joint>
	<link name="link1_x_to_2">
		<inertial>
			<mass value="0.001"/>
			<inertia ixx="0.001" ixy="0" ixz="0" iyy="0.001" iyz="0" izz="0.001"/>
		</inertial>
	</link>
	<joint name="joint1_y_to_2" type="revolute">
		<safety_controller k_position="100.0" k_velocity="40.0" soft_lower_limit="-2.8973" soft_upper_limit="2.8973"/>
		<parent link="link1_x_to_2"/>
		<child link="link1_y_to_2"/>
		<origin rpy="0 0 0" xyz="0 0 0"/>
		<axis xyz="0 1 0"/>
		<dynamics damping="10.0"/>
		<limit effort="10" lower="-3.1416" upper="3.1416" velocity="3"/>
		<limit effort="87" lower="-2.9671" upper="2.9671" velocity="2.1750"/>
	</joint>
	<link name="link1_y_to_2">
		<inertial>
			<mass value="0.001"/>
			<inertia ixx="0.001" ixy="0" ixz="0" iyy="0.001" iyz="0" izz="0.001"/>
		</inertial>
	</link>
	<joint name="joint1_z_to_2" type="revolute">
		<safety_controller k_position="100.0" k_velocity="40.0" soft_lower_limit="-2.8973" soft_upper_limit="2.8973"/>
		<parent link="link1_y_to_2"/>
		<child link="link_1_to_2"/>
		<origin rpy="0 0 0" xyz="0 0 0"/>
		<axis xyz="0 0 1"/>
		<dynamics damping="10.0"/>
		<limit effort="10" lower="-3.1416" upper="3.1416" velocity="3"/>
		<limit effort="87" lower="-2.9671" upper="2.9671" velocity="2.1750"/>
	</joint>
	<joint name="joint1_x_to_4" type="revolute">
		<safety_controller k_position="100.0" k_velocity="40.0" soft_lower_limit="-2.8973" soft_upper_limit="2.8973"/>
		<parent link="link1_base"/>
		<child link="link1_x_to_4"/>
		<origin rpy="0 0 0" xyz="0 0 0"/>
		<axis xyz="1 0 0"/>
		<dynamics damping="10.0"/>
		<limit effort="10" lower="-3.1416" upper="3.1416" velocity="3"/>
		<limit effort="87" lower="-2.9671" upper="2.9671" velocity="2.1750"/>
	</joint>
	<link name="link1_x_to_4">
		<inertial>
			<mass value="0.001"/>
			<inertia ixx="0.001" ixy="0" ixz="0" iyy="0.001" iyz="0" izz="0.001"/>
		</inertial>
	</link>
	<joint name="joint1_y_to_4" type="revolute">
		<safety_controller k_position="100.0" k_velocity="40.0" soft_lower_limit="-2.8973" soft_upper_limit="2.8973"/>
		<parent link="link1_x_to_4"/>
		<child link="link1_y_to_4"/>
		<origin rpy="0 0 0" xyz="0 0 0"/>
		<axis xyz="0 1 0"/>
		<dynamics damping="10.0"/>
		<limit effort="10" lower="-3.1416" upper="3.1416" velocity="3"/>
		<limit effort="87" lower="-2.9671" upper="2.9671" velocity="2.1750"/>
	</joint>
	<link name="link1_y_to_4">
		<inertial>
			<mass value="0.001"/>
			<inertia ixx="0.001" ixy="0" ixz="0" iyy="0.001" iyz="0" izz="0.001"/>
		</inertial>
	</link>
	<joint name="joint1_z_to_4" type="revolute">
		<safety_controller k_position="100.0" k_velocity="40.0" soft_lower_limit="-2.8973" soft_upper_limit="2.8973"/>
		<parent link="link1_y_to_4"/>
		<child link="link_1_to_4"/>
		<origin rpy="0 0 0" xyz="0 0 0"/>
		<axis xyz="0 0 1"/>
		<dynamics damping="10.0"/>
		<limit effort="10" lower="-3.1416" upper="3.1416" velocity="3"/>
		<limit effort="87" lower="-2.9671" upper="2.9671" velocity="2.1750"/>
	</joint>
	<joint name="joint1_x_to_6" type="revolute">
		<safety_controller k_position="100.0" k_velocity="40.0" soft_lower_limit="-2.8973" soft_upper_limit="2.8973"/>
		<parent link="link1_base"/>
		<child link="link1_x_to_6"/>
		<origin rpy="0 0 0" xyz="0 0 0"/>
		<axis xyz="1 0 0"/>
		<dynamics damping="10.0"/>
		<limit effort="10" lower="-3.1416" upper="3.1416" velocity="3"/>
		<limit effort="87" lower="-2.9671" upper="2.9671" velocity="2.1750"/>
	</joint>
	<link name="link1_x_to_6">
		<inertial>
			<mass value="0.001"/>
			<inertia ixx="0.001" ixy="0" ixz="0" iyy="0.001" iyz="0" izz="0.001"/>
		</inertial>
	</link>
	<joint name="joint1_y_to_6" type="revolute">
		<safety_controller k_position="100.0" k_velocity="40.0" soft_lower_limit="-2.8973" soft_upper_limit="2.8973"/>
		<parent link="link1_x_to_6"/>
		<child link="link1_y_to_6"/>
		<origin rpy="0 0 0" xyz="0 0 0"/>
		<axis xyz="0 1 0"/>
		<dynamics damping="10.0"/>
		<limit effort="10" lower="-3.1416" upper="3.1416" velocity="3"/>
		<limit effort="87" lower="-2.9671" upper="2.9671" velocity="2.1750"/>
	</joint>
	<link name="link1_y_to_6">
		<inertial>
			<mass value="0.001"/>
			<inertia ixx="0.001" ixy="0" ixz="0" iyy="0.001" iyz="0" izz="0.001"/>
		</inertial>
	</link>
	<joint name="joint1_z_to_6" type="revolute">
		<safety_controller k_position="100.0" k_velocity="40.0" soft_lower_limit="-2.8973" soft_upper_limit="2.8973"/>
		<parent link="link1_y_to_6"/>
		<child link="link_1_to_6"/>
		<origin rpy="0 0 0" xyz="0 0 0"/>
		<axis xyz="0 0 1"/>
		<dynamics damping="10.0"/>
		<limit effort="10" lower="-3.1416" upper="3.1416" velocity="3"/>
		<limit effort="87" lower="-2.9671" upper="2.9671" velocity="2.1750"/>
	</joint>
	<joint name="joint1_x_to_13" type="revolute">
		<safety_controller k_position="100.0" k_velocity="40.0" soft_lower_limit="-2.8973" soft_upper_limit="2.8973"/>
		<parent link="link1_base"/>
		<child link="link1_x_to_13"/>
		<origin rpy="0 0 0" xyz="0 0 0"/>
		<axis xyz="1 0 0"/>
		<dynamics damping="10.0"/>
		<limit effort="10" lower="-3.1416" upper="3.1416" velocity="3"/>
		<limit effort="87" lower="-2.9671" upper="2.9671" velocity="2.1750"/>
	</joint>
	<link name="link1_x_to_13">
		<inertial>
			<mass value="0.001"/>
			<inertia ixx="0.001" ixy="0" ixz="0" iyy="0.001" iyz="0" izz="0.001"/>
		</inertial>
	</link>
	<joint name="joint1_y_to_13" type="revolute">
		<safety_controller k_position="100.0" k_velocity="40.0" soft_lower_limit="-2.8973" soft_upper_limit="2.8973"/>
		<parent link="link1_x_to_13"/>
		<child link="link1_y_to_13"/>
		<origin rpy="0 0 0" xyz="0 0 0"/>
		<axis xyz="0 1 0"/>
		<dynamics damping="10.0"/>
		<limit effort="10" lower="-3.1416" upper="3.1416" velocity="3"/>
		<limit effort="87" lower="-2.9671" upper="2.9671" velocity="2.1750"/>
	</joint>
	<link name="link1_y_to_13">
		<inertial>
			<mass value="0.001"/>
			<inertia ixx="0.001" ixy="0" ixz="0" iyy="0.001" iyz="0" izz="0.001"/>
		</inertial>
	</link>
	<joint name="joint1_z_to_13" type="revolute">
		<safety_controller k_position="100.0" k_velocity="40.0" soft_lower_limit="-2.8973" soft_upper_limit="2.8973"/>
		<parent link="link1_y_to_13"/>
		<child link="link_1_to_13"/>
		<origin rpy="0 0 0" xyz="0 0 0"/>
		<axis xyz="0 0 1"/>
		<dynamics damping="10.0"/>
		<limit effort="10" lower="-3.1416" upper="3.1416" velocity="3"/>
		<limit effort="87" lower="-2.9671" upper="2.9671" velocity="2.1750"/>
	</joint>
	<link name="link_1_to_2">
		<visual>
			<origin rpy="-0.029725992137669643 0.0 -1.8792032039587756" xyz="0.004601886234961544 -0.0014660312128046754 0.16242820997463328"/>
			<geometry>
				<cylinder length="0.325" radius="0.017768564847994217"/>
			</geometry>
			<material name="brown"/>
		</visual>
		<collision>
			<origin rpy="-0.029725992137669643 0.0 -1.8792032039587756" xyz="0.004601886234961544 -0.0014660312128046754 0.16242820997463328"/>
			<geometry>
				<cylinder length="0.325" radius="0.017768564847994217"/>
			</geometry>
		</collision>
	</link>
	<link name="link_1_to_4">
		<visual>
			<origin rpy="-0.6003604667630348 0.0 -0.4416395689133482" xyz="0.025505049752086662 0.05394639875904644 0.08715457029366583"/>
			<geometry>
				<cylinder length="0.21125000000000002" radius="0.011668009211849495"/>
			</geometry>
			<material name="brown"/>
		</visual>
		<collision>
			<origin rpy="-0.6003604667630348 0.0 -0.4416395689133482" xyz="0.025505049752086662 0.05394639875904644 0.08715457029366583"/>
			<geometry>
				<cylinder length="0.21125000000000002" radius="0.011668009211849495"/>
			</geometry>
		</collision>
	</link>
	<link name="link_1_to_6">
		<visual>
			<origin rpy="-1.3822439092606884 0.0 2.640952160694431" xyz="-0.03237008392195339 -0.059162944861476614 0.01286873289279386"/>
			<geometry>
				<cylinder length="0.13731250000000003" radius="0.009680000000000005"/>
			</geometry>
			<material name="brown"/>
		</visual>
		<collision>
			<origin rpy="-1.3822439092606884 0.0 2.640952160694431" xyz="-0.03237008392195339 -0.059162944861476614 0.01286873289279386"/>
			<geometry>
				<cylinder length="0.13731250000000003" radius="0.009680000000000005"/>
			</geometry>
		</collision>
	</link>
	<link name="link_1_to_13">
		<visual>
			<origin rpy="-1.4648934252138213 2.220446049250313e-16 -0.9173237266992712" xyz="0.03523397397419674 0.026978596709864355 0.0047172532387535215"/>
			<geometry>
				<cylinder length="0.08925312500000003" radius="0.008"/>
			</geometry>
			<material name="brown"/>
		</visual>
		<collision>
			<origin rpy="-1.4648934252138213 2.220446049250313e-16 -0.9173237266992712" xyz="0.03523397397419674 0.026978596709864355 0.0047172532387535215"/>
			<geometry>
				<cylinder length="0.08925312500000003" radius="0.008"/>
			</geometry>
		</collision>
	</link>
	<joint name="joint2_base" type="fixed">
		<parent link="link_1_to_2"/>
		<origin rpy="0 0 0" xyz="0.009203772469923087 -0.0029320624256093508 0.32485641994926656"/>
		<child link="link2_base"/>
	</joint>
	<link name="link2_base">
		<inertial>
			<mass value="0.001"/>
			<inertia ixx="0.001" ixy="0" ixz="0" iyy="0.001" iyz="0" izz="0.001"/>
		</inertial>
	</link>
	<joint name="joint2_x_to_3" type="revolute">
		<safety_controller k_position="100.0" k_velocity="40.0" soft_lower_limit="-2.8973" soft_upper_limit="2.8973"/>
		<parent link="link2_base"/>
		<child link="link2_x_to_3"/>
		<origin rpy="0 0 0" xyz="0 0 0"/>
		<axis xyz="1 0 0"/>
		<dynamics damping="10.0"/>
		<limit effort="10" lower="-3.1416" upper="3.1416" velocity="3"/>
		<limit effort="87" lower="-2.9671" upper="2.9671" velocity="2.1750"/>
	</joint>
	<link name="link2_x_to_3">
		<inertial>
			<mass value="0.001"/>
			<inertia ixx="0.001" ixy="0" ixz="0" iyy="0.001" iyz="0" izz="0.001"/>
		</inertial>
	</link>
	<joint name="joint2_y_to_3" type="revolute">
		<safety_controller k_position="100.0" k_velocity="40.0" soft_lower_limit="-2.8973" soft_upper_limit="2.8973"/>
		<parent link="link2_x_to_3"/>
		<child link="link2_y_to_3"/>
		<origin rpy="0 0 0" xyz="0 0 0"/>
		<axis xyz="0 1 0"/>
		<dynamics damping="10.0"/>
		<limit effort="10" lower="-3.1416" upper="3.1416" velocity="3"/>
		<limit effort="87" lower="-2.9671" upper="2.9671" velocity="2.1750"/>
	</joint>
	<link name="link2_y_to_3">
		<inertial>
			<mass value="0.001"/>
			<inertia ixx="0.001" ixy="0" ixz="0" iyy="0.001" iyz="0" izz="0.001"/>
		</inertial>
	</link>
	<joint name="joint2_z_to_3" type="revolute">
		<safety_controller k_position="100.0" k_velocity="40.0" soft_lower_limit="-2.8973" soft_upper_limit="2.8973"/>
		<parent link="link2_y_to_3"/>
		<child link="link_2_to_3"/>
		<origin rpy="0 0 0" xyz="0 0 0"/>
		<axis xyz="0 0 1"/>
		<dynamics damping="10.0"/>
		<limit effort="10" lower="-3.1416" upper="3.1416" velocity="3"/>
		<limit effort="87" lower="-2.9671" upper="2.9671" velocity="2.1750"/>
	</joint>
	<joint name="joint2_x_to_5" type="revolute">
		<safety_controller k_position="100.0" k_velocity="40.0" soft_lower_limit="-2.8973" soft_upper_limit="2.8973"/>
		<parent link="link2_base"/>
		<child link="link2_x_to_5"/>
		<origin rpy="0 0 0" xyz="0 0 0"/>
		<axis xyz="1 0 0"/>
		<dynamics damping="10.0"/>
		<limit effort="10" lower="-3.1416" upper="3.1416" velocity="3"/>
		<limit effort="87" lower="-2.9671" upper="2.9671" velocity="2.1750"/>
	</joint>
	<link name="link2_x_to_5">
		<inertial>
			<mass value="0.001"/>
			<inertia ixx="0.001" ixy="0" ixz="0" iyy="0.001" iyz="0" izz="0.001"/>
		</inertial>
	</link>
	<joint name="joint2_y_to_5" type="revolute">
		<safety_controller k_position="100.0" k_velocity="40.0" soft_lower_limit="-2.8973" soft_upper_limit="2.8973"/>
		<parent link="link2_x_to_5"/>
		<child link="link2_y_to_5"/>
		<origin rpy="0 0 0" xyz="0 0 0"/>
		<axis xyz="0 1 0"/>
		<dynamics damping="10.0"/>
		<limit effort="10" lower="-3.1416" upper="3.1416" velocity="3"/>
		<limit effort="87" lower="-2.9671" upper="2.9671" velocity="2.1750"/>
	</joint>
	<link name="link2_y_to_5">
		<inertial>
			<mass value="0.001"/>
			<inertia ixx="0.001" ixy="0" ixz="0" iyy="0.001" iyz="0" izz="0.001"/>
		</inertial>
	</link>
	<joint name="joint2_z_to_5" type="revolute">
		<safety_controller k_position="100.0" k_velocity="40.0" soft_lower_limit="-2.8973" soft_upper_limit="2.8973"/>
		<parent link="link2_y_to_5"/>
		<child link="link_2_to_5"/>
		<origin rpy="0 0 0" xyz="0 0 0"/>
		<axis xyz="0 0 1"/>
		<dynamics damping="10.0"/>
		<limit effort="10" lower="-3.1416" upper="3.1416" velocity="3"/>
		<limit effort="87" lower="-2.9671" upper="2.9671" velocity="2.1750"/>
	</joint>
	<joint name="joint2_x_to_15" type="revolute">
		<safety_controller k_position="100.0" k_velocity="40.0" soft_lower_limit="-2.8973" soft_upper_limit="2.8973"/>
		<parent link="link2_base"/>
		<child link="link2_x_to_15"/>
		<origin rpy="0 0 0" xyz="0 0 0"/>
		<axis xyz="1 0 0"/>
		<dynamics damping="10.0"/>
		<limit effort="10" lower="-3.1416" upper="3.1416" velocity="3"/>
		<limit effort="87" lower="-2.9671" upper="2.9671" velocity="2.1750"/>
	</joint>
	<link name="link2_x_to_15">
		<inertial>
			<mass value="0.001"/>
			<inertia ixx="0.001" ixy="0" ixz="0" iyy="0.001" iyz="0" izz="0.001"/>
		</inertial>
	</link>
	<joint name="joint2_y_to_15" type="revolute">
		<safety_controller k_position="100.0" k_velocity="40.0" soft_lower_limit="-2.8973" soft_upper_limit="2.8973"/>
		<parent link="link2_x_to_15"/>
		<child link="link2_y_to_15"/>
		<origin rpy="0 0 0" xyz="0 0 0"/>
		<axis xyz="0 1 0"/>
		<dynamics damping="10.0"/>
		<limit effort="10" lower="-3.1416" upper="3.1416" velocity="3"/>
		<limit effort="87" lower="-2.9671" upper="2.9671" velocity="2.1750"/>
	</joint>
	<link name="link2_y_to_15">
		<inertial>
			<mass value="0.001"/>
			<inertia ixx="0.001" ixy="0" ixz="0" iyy="0.001" iyz="0" izz="0.001"/>
		</inertial>
	</link>
	<joint name="joint2_z_to_15" type="revolute">
		<safety_controller k_position="100.0" k_velocity="40.0" soft_lower_limit="-2.8973" soft_upper_limit="2.8973"/>
		<parent link="link2_y_to_15"/>
		<child link="link_2_to_15"/>
		<origin rpy="0 0 0" xyz="0 0 0"/>
		<axis xyz="0 0 1"/>
		<dynamics damping="10.0"/>
		<limit effort="10" lower="-3.1416" upper="3.1416" velocity="3"/>
		<limit effort="87" lower="-2.9671" upper="2.9671" velocity="2.1750"/>
	</joint>
	<link name="link_2_to_3">
		<visual>
			<origin rpy="-0.0910395907496579 0.0 -2.6074430018278942" xyz="0.004888864338790731 -0.008265129722301798 0.10518758130668476"/>
			<geometry>
				<cylinder length="0.21124999999999994" radius="0.014087513802040924"/>
			</geometry>
			<material name="brown"/>
		</visual>
		<collision>
			<origin rpy="-0.0910395907496579 0.0 -2.6074430018278942" xyz="0.004888864338790731 -0.008265129722301798 0.10518758130668476"/>
			<geometry>
				<cylinder length="0.21124999999999994" radius="0.014087513802040924"/>
			</geometry>
		</collision>
	</link>
	<link name="link_2_to_5">
		<visual>
			<origin rpy="-1.729900571577675 0.0 2.824553355990033" xyz="-0.021133574227110083 -0.06441066134692784 -0.010877472560347212"/>
			<geometry>
				<cylinder length="0.13731250000000003" radius="0.009680000000000005"/>
			</geometry>
			<material name="brown"/>
		</visual>
		<collision>
			<origin rpy="-1.729900571577675 0.0 2.824553355990033" xyz="-0.021133574227110083 -0.06441066134692784 -0.010877472560347212"/>
			<geometry>
				<cylinder length="0.13731250000000003" radius="0.009680000000000005"/>
			</geometry>
		</collision>
	</link>
	<link name="link_2_to_15">
		<visual>
			<origin rpy="-1.224730505581329 0.0 -1.425436844449587" xyz="0.04153811839363279 0.006080848018841811 0.015137307827176538"/>
			<geometry>
				<cylinder length="0.08925312500000003" radius="0.008"/>
			</geometry>
			<material name="brown"/>
		</visual>
		<collision>
			<origin rpy="-1.224730505581329 0.0 -1.425436844449587" xyz="0.04153811839363279 0.006080848018841811 0.015137307827176538"/>
			<geometry>
				<cylinder length="0.08925312500000003" radius="0.008"/>
			</geometry>
		</collision>
	</link>
	<joint name="joint3_base" type="fixed">
		<parent link="link_2_to_3"/>
		<origin rpy="0 0 0" xyz="0.009777728677581463 -0.016530259444603596 0.21037516261336953"/>
		<child link="link3_base"/>
	</joint>
	<link name="link3_base">
		<inertial>
			<mass value="0.001"/>
			<inertia ixx="0.001" ixy="0" ixz="0" iyy="0.001" iyz="0" izz="0.001"/>
		</inertial>
	</link>
	<joint name="joint3_x_to_7" type="revolute">
		<safety_controller k_position="100.0" k_velocity="40.0" soft_lower_limit="-2.8973" soft_upper_limit="2.8973"/>
		<parent link="link3_base"/>
		<child link="link3_x_to_7"/>
		<origin rpy="0 0 0" xyz="0 0 0"/>
		<axis xyz="1 0 0"/>
		<dynamics damping="10.0"/>
		<limit effort="10" lower="-3.1416" upper="3.1416" velocity="3"/>
		<limit effort="87" lower="-2.9671" upper="2.9671" velocity="2.1750"/>
	</joint>
	<link name="link3_x_to_7">
		<inertial>
			<mass value="0.001"/>
			<inertia ixx="0.001" ixy="0" ixz="0" iyy="0.001" iyz="0" izz="0.001"/>
		</inertial>
	</link>
	<joint name="joint3_y_to_7" type="revolute">
		<safety_controller k_position="100.0" k_velocity="40.0" soft_lower_limit="-2.8973" soft_upper_limit="2.8973"/>
		<parent link="link3_x_to_7"/>
		<child link="link3_y_to_7"/>
		<origin rpy="0 0 0" xyz="0 0 0"/>
		<axis xyz="0 1 0"/>
		<dynamics damping="10.0"/>
		<limit effort="10" lower="-3.1416" upper="3.1416" velocity="3"/>
		<limit effort="87" lower="-2.9671" upper="2.9671" velocity="2.1750"/>
	</joint>
	<link name="link3_y_to_7">
		<inertial>
			<mass value="0.001"/>
			<inertia ixx="0.001" ixy="0" ixz="0" iyy="0.001" iyz="0" izz="0.001"/>
		</inertial>
	</link>
	<joint name="joint3_z_to_7" type="revolute">
		<safety_controller k_position="100.0" k_velocity="40.0" soft_lower_limit="-2.8973" soft_upper_limit="2.8973"/>
		<parent link="link3_y_to_7"/>
		<child link="link_3_to_7"/>
		<origin rpy="0 0 0" xyz="0 0 0"/>
		<axis xyz="0 0 1"/>
		<dynamics damping="10.0"/>
		<limit effort="10" lower="-3.1416" upper="3.1416" velocity="3"/>
		<limit effort="87" lower="-2.9671" upper="2.9671" velocity="2.1750"/>
	</joint>
	<joint name="joint3_x_to_16" type="revolute">
		<safety_controller k_position="100.0" k_velocity="40.0" soft_lower_limit="-2.8973" soft_upper_limit="2.8973"/>
		<parent link="link3_base"/>
		<child link="link3_x_to_16"/>
		<origin rpy="0 0 0" xyz="0 0 0"/>
		<axis xyz="1 0 0"/>
		<dynamics damping="10.0"/>
		<limit effort="10" lower="-3.1416" upper="3.1416" velocity="3"/>
		<limit effort="87" lower="-2.9671" upper="2.9671" velocity="2.1750"/>
	</joint>
	<link name="link3_x_to_16">
		<inertial>
			<mass value="0.001"/>
			<inertia ixx="0.001" ixy="0" ixz="0" iyy="0.001" iyz="0" izz="0.001"/>
		</inertial>
	</link>
	<joint name="joint3_y_to_16" type="revolute">
		<safety_controller k_position="100.0" k_velocity="40.0" soft_lower_limit="-2.8973" soft_upper_limit="2.8973"/>
		<parent link="link3_x_to_16"/>
		<child link="link3_y_to_16"/>
		<origin rpy="0 0 0" xyz="0 0 0"/>
		<axis xyz="0 1 0"/>
		<dynamics damping="10.0"/>
		<limit effort="10" lower="-3.1416" upper="3.1416" velocity="3"/>
		<limit effort="87" lower="-2.9671" upper="2.9671" velocity="2.1750"/>
	</joint>
	<link name="link3_y_to_16">
		<inertial>
			<mass value="0.001"/>
			<inertia ixx="0.001" ixy="0" ixz="0" iyy="0.001" iyz="0" izz="0.001"/>
		</inertial>
	</link>
	<joint name="joint3_z_to_16" type="revolute">
		<safety_controller k_position="100.0" k_velocity="40.0" soft_lower_limit="-2.8973" soft_upper_limit="2.8973"/>
		<parent link="link3_y_to_16"/>
		<child link="link_3_to_16"/>
		<origin rpy="0 0 0" xyz="0 0 0"/>
		<axis xyz="0 0 1"/>
		<dynamics damping="10.0"/>
		<limit effort="10" lower="-3.1416" upper="3.1416" velocity="3"/>
		<limit effort="87" lower="-2.9671" upper="2.9671" velocity="2.1750"/>
	</joint>
	<link name="link_3_to_7">
		<visual>
			<origin rpy="-0.16990495502860195 0.0 -1.019013082732617" xyz="0.00988611603300047 0.006085512051559103 0.06766765783529738"/>
			<geometry>
				<cylinder length="0.13731250000000006" radius="0.011668009211849495"/>
			</geometry>
			<material name="brown"/>
		</visual>
		<collision>
			<origin rpy="-0.16990495502860195 0.0 -1.019013082732617" xyz="0.00988611603300047 0.006085512051559103 0.06766765783529738"/>
			<geometry>
				<cylinder length="0.13731250000000006" radius="0.011668009211849495"/>
			</geometry>
		</collision>
	</link>
	<link name="link_3_to_16">
		<visual>
			<origin rpy="-1.8419219382582501 2.220446049250313e-16 -0.7949495999931796" xyz="0.030692016410688642 0.030111240297924752 -0.011951711882950411"/>
			<geometry>
				<cylinder length="0.089253125" radius="0.008"/>
			</geometry>
			<material name="brown"/>
		</visual>
		<collision>
			<origin rpy="-1.8419219382582501 2.220446049250313e-16 -0.7949495999931796" xyz="0.030692016410688642 0.030111240297924752 -0.011951711882950411"/>
			<geometry>
				<cylinder length="0.089253125" radius="0.008"/>
			</geometry>
		</collision>
	</link>
	<joint name="joint4_base" type="fixed">
		<parent link="link_1_to_4"/>
		<origin rpy="0 0 0" xyz="0.051010099504173324 0.10789279751809289 0.17430914058733166"/>
		<child link="link4_base"/>
	</joint>
	<link name="link4_base">
		<inertial>
			<mass value="0.001"/>
			<inertia ixx="0.001" ixy="0" ixz="0" iyy="0.001" iyz="0" izz="0.001"/>
		</inertial>
	</link>
	<joint name="joint4_x_to_8" type="revolute">
		<safety_controller k_position="100.0" k_velocity="40.0" soft_lower_limit="-2.8973" soft_upper_limit="2.8973"/>
		<parent link="link4_base"/>
		<child link="link4_x_to_8"/>
		<origin rpy="0 0 0" xyz="0 0 0"/>
		<axis xyz="1 0 0"/>
		<dynamics damping="10.0"/>
		<limit effort="10" lower="-3.1416" upper="3.1416" velocity="3"/>
		<limit effort="87" lower="-2.9671" upper="2.9671" velocity="2.1750"/>
	</joint>
	<link name="link4_x_to_8">
		<inertial>
			<mass value="0.001"/>
			<inertia ixx="0.001" ixy="0" ixz="0" iyy="0.001" iyz="0" izz="0.001"/>
		</inertial>
	</link>
	<joint name="joint4_y_to_8" type="revolute">
		<safety_controller k_position="100.0" k_velocity="40.0" soft_lower_limit="-2.8973" soft_upper_limit="2.8973"/>
		<parent link="link4_x_to_8"/>
		<child link="link4_y_to_8"/>
		<origin rpy="0 0 0" xyz="0 0 0"/>
		<axis xyz="0 1 0"/>
		<dynamics damping="10.0"/>
		<limit effort="10" lower="-3.1416" upper="3.1416" velocity="3"/>
		<limit effort="87" lower="-2.9671" upper="2.9671" velocity="2.1750"/>
	</joint>
	<link name="link4_y_to_8">
		<inertial>
			<mass value="0.001"/>
			<inertia ixx="0.001" ixy="0" ixz="0" iyy="0.001" iyz="0" izz="0.001"/>
		</inertial>
	</link>
	<joint name="joint4_z_to_8" type="revolute">
		<safety_controller k_position="100.0" k_velocity="40.0" soft_lower_limit="-2.8973" soft_upper_limit="2.8973"/>
		<parent link="link4_y_to_8"/>
		<child link="link_4_to_8"/>
		<origin rpy="0 0 0" xyz="0 0 0"/>
		<axis xyz="0 0 1"/>
		<dynamics damping="10.0"/>
		<limit effort="10" lower="-3.1416" upper="3.1416" velocity="3"/>
		<limit effort="87" lower="-2.9671" upper="2.9671" velocity="2.1750"/>
	</joint>
	<joint name="joint4_x_to_12" type="revolute">
		<safety_controller k_position="100.0" k_velocity="40.0" soft_lower_limit="-2.8973" soft_upper_limit="2.8973"/>
		<parent link="link4_base"/>
		<child link="link4_x_to_12"/>
		<origin rpy="0 0 0" xyz="0 0 0"/>
		<axis xyz="1 0 0"/>
		<dynamics damping="10.0"/>
		<limit effort="10" lower="-3.1416" upper="3.1416" velocity="3"/>
		<limit effort="87" lower="-2.9671" upper="2.9671" velocity="2.1750"/>
	</joint>
	<link name="link4_x_to_12">
		<inertial>
			<mass value="0.001"/>
			<inertia ixx="0.001" ixy="0" ixz="0" iyy="0.001" iyz="0" izz="0.001"/>
		</inertial>
	</link>
	<joint name="joint4_y_to_12" type="revolute">
		<safety_controller k_position="100.0" k_velocity="40.0" soft_lower_limit="-2.8973" soft_upper_limit="2.8973"/>
		<parent link="link4_x_to_12"/>
		<child link="link4_y_to_12"/>
		<origin rpy="0 0 0" xyz="0 0 0"/>
		<axis xyz="0 1 0"/>
		<dynamics damping="10.0"/>
		<limit effort="10" lower="-3.1416" upper="3.1416" velocity="3"/>
		<limit effort="87" lower="-2.9671" upper="2.9671" velocity="2.1750"/>
	</joint>
	<link name="link4_y_to_12">
		<inertial>
			<mass value="0.001"/>
			<inertia ixx="0.001" ixy="0" ixz="0" iyy="0.001" iyz="0" izz="0.001"/>
		</inertial>
	</link>
	<joint name="joint4_z_to_12" type="revolute">
		<safety_controller k_position="100.0" k_velocity="40.0" soft_lower_limit="-2.8973" soft_upper_limit="2.8973"/>
		<parent link="link4_y_to_12"/>
		<child link="link_4_to_12"/>
		<origin rpy="0 0 0" xyz="0 0 0"/>
		<axis xyz="0 0 1"/>
		<dynamics damping="10.0"/>
		<limit effort="10" lower="-3.1416" upper="3.1416" velocity="3"/>
		<limit effort="87" lower="-2.9671" upper="2.9671" velocity="2.1750"/>
	</joint>
	<link name="link_4_to_8">
		<visual>
			<origin rpy="-1.5519734888347683 0.0 -0.3841660995247404" xyz="0.02572685334001734 0.06364070886691059 0.0012922291595800495"/>
			<geometry>
				<cylinder length="0.13731250000000003" radius="0.008800000000000002"/>
			</geometry>
			<material name="brown"/>
		</visual>
		<collision>
			<origin rpy="-1.5519734888347683 0.0 -0.3841660995247404" xyz="0.02572685334001734 0.06364070886691059 0.0012922291595800495"/>
			<geometry>
				<cylinder length="0.13731250000000003" radius="0.008800000000000002"/>
			</geometry>
		</collision>
	</link>
	<link name="link_4_to_12">
		<visual>
			<origin rpy="-1.5261079625315799 2.220446049250313e-16 -2.2878747711092187" xyz="0.03360275083050826 -0.029298646369424922 0.001993624364961255"/>
			<geometry>
				<cylinder length="0.08925312500000002" radius="0.008"/>
			</geometry>
			<material name="brown"/>
		</visual>
		<collision>
			<origin rpy="-1.5261079625315799 2.220446049250313e-16 -2.2878747711092187" xyz="0.03360275083050826 -0.029298646369424922 0.001993624364961255"/>
			<geometry>
				<cylinder length="0.08925312500000002" radius="0.008"/>
			</geometry>
		</collision>
	</link>
	<joint name="joint5_base" type="fixed">
		<parent link="link_2_to_5"/>
		<origin rpy="0 0 0" xyz="-0.042267148454220166 -0.12882132269385568 -0.021754945120694424"/>
		<child link="link5_base"/>
	</joint>
	<link name="link5_base">
		<inertial>
			<mass value="0.001"/>
			<inertia ixx="0.001" ixy="0" ixz="0" iyy="0.001" iyz="0" izz="0.001"/>
		</inertial>
	</link>
	<joint name="joint5_x_to_9" type="revolute">
		<safety_controller k_position="100.0" k_velocity="40.0" soft_lower_limit="-2.8973" soft_upper_limit="2.8973"/>
		<parent link="link5_base"/>
		<child link="link5_x_to_9"/>
		<origin rpy="0 0 0" xyz="0 0 0"/>
		<axis xyz="1 0 0"/>
		<dynamics damping="10.0"/>
		<limit effort="10" lower="-3.1416" upper="3.1416" velocity="3"/>
		<limit effort="87" lower="-2.9671" upper="2.9671" velocity="2.1750"/>
	</joint>
	<link name="link5_x_to_9">
		<inertial>
			<mass value="0.001"/>
			<inertia ixx="0.001" ixy="0" ixz="0" iyy="0.001" iyz="0" izz="0.001"/>
		</inertial>
	</link>
	<joint name="joint5_y_to_9" type="revolute">
		<safety_controller k_position="100.0" k_velocity="40.0" soft_lower_limit="-2.8973" soft_upper_limit="2.8973"/>
		<parent link="link5_x_to_9"/>
		<child link="link5_y_to_9"/>
		<origin rpy="0 0 0" xyz="0 0 0"/>
		<axis xyz="0 1 0"/>
		<dynamics damping="10.0"/>
		<limit effort="10" lower="-3.1416" upper="3.1416" velocity="3"/>
		<limit effort="87" lower="-2.9671" upper="2.9671" velocity="2.1750"/>
	</joint>
	<link name="link5_y_to_9">
		<inertial>
			<mass value="0.001"/>
			<inertia ixx="0.001" ixy="0" ixz="0" iyy="0.001" iyz="0" izz="0.001"/>
		</inertial>
	</link>
	<joint name="joint5_z_to_9" type="revolute">
		<safety_controller k_position="100.0" k_velocity="40.0" soft_lower_limit="-2.8973" soft_upper_limit="2.8973"/>
		<parent link="link5_y_to_9"/>
		<child link="link_5_to_9"/>
		<origin rpy="0 0 0" xyz="0 0 0"/>
		<axis xyz="0 0 1"/>
		<dynamics damping="10.0"/>
		<limit effort="10" lower="-3.1416" upper="3.1416" velocity="3"/>
		<limit effort="87" lower="-2.9671" upper="2.9671" velocity="2.1750"/>
	</joint>
	<link name="link_5_to_9">
		<visual>
			<origin rpy="-1.3916646675690916 0.0 2.887664423543117" xyz="-0.011031173702628377 -0.04250434538877523 0.007951346450793761"/>
			<geometry>
				<cylinder length="0.08925312500000006" radius="0.008800000000000002"/>
			</geometry>
			<material name="brown"/>
		</visual>
		<collision>
			<origin rpy="-1.3916646675690916 0.0 2.887664423543117" xyz="-0.011031173702628377 -0.04250434538877523 0.007951346450793761"/>
			<geometry>
				<cylinder length="0.08925312500000006" radius="0.008800000000000002"/>
			</geometry>
		</collision>
	</link>
	<joint name="joint6_base" type="fixed">
		<parent link="link_1_to_6"/>
		<origin rpy="0 0 0" xyz="-0.06474016784390678 -0.11832588972295323 0.02573746578558772"/>
		<child link="link6_base"/>
	</joint>
	<link name="link6_base">
		<inertial>
			<mass value="0.001"/>
			<inertia ixx="0.001" ixy="0" ixz="0" iyy="0.001" iyz="0" izz="0.001"/>
		</inertial>
	</link>
	<joint name="joint6_x_to_10" type="revolute">
		<safety_controller k_position="100.0" k_velocity="40.0" soft_lower_limit="-2.8973" soft_upper_limit="2.8973"/>
		<parent link="link6_base"/>
		<child link="link6_x_to_10"/>
		<origin rpy="0 0 0" xyz="0 0 0"/>
		<axis xyz="1 0 0"/>
		<dynamics damping="10.0"/>
		<limit effort="10" lower="-3.1416" upper="3.1416" velocity="3"/>
		<limit effort="87" lower="-2.9671" upper="2.9671" velocity="2.1750"/>
	</joint>
	<link name="link6_x_to_10">
		<inertial>
			<mass value="0.001"/>
			<inertia ixx="0.001" ixy="0" ixz="0" iyy="0.001" iyz="0" izz="0.001"/>
		</inertial>
	</link>
	<joint name="joint6_y_to_10" type="revolute">
		<safety_controller k_position="100.0" k_velocity="40.0" soft_lower_limit="-2.8973" soft_upper_limit="2.8973"/>
		<parent link="link6_x_to_10"/>
		<child link="link6_y_to_10"/>
		<origin rpy="0 0 0" xyz="0 0 0"/>
		<axis xyz="0 1 0"/>
		<dynamics damping="10.0"/>
		<limit effort="10" lower="-3.1416" upper="3.1416" velocity="3"/>
		<limit effort="87" lower="-2.9671" upper="2.9671" velocity="2.1750"/>
	</joint>
	<link name="link6_y_to_10">
		<inertial>
			<mass value="0.001"/>
			<inertia ixx="0.001" ixy="0" ixz="0" iyy="0.001" iyz="0" izz="0.001"/>
		</inertial>
	</link>
	<joint name="joint6_z_to_10" type="revolute">
		<safety_controller k_position="100.0" k_velocity="40.0" soft_lower_limit="-2.8973" soft_upper_limit="2.8973"/>
		<parent link="link6_y_to_10"/>
		<child link="link_6_to_10"/>
		<origin rpy="0 0 0" xyz="0 0 0"/>
		<axis xyz="0 0 1"/>
		<dynamics damping="10.0"/>
		<limit effort="10" lower="-3.1416" upper="3.1416" velocity="3"/>
		<limit effort="87" lower="-2.9671" upper="2.9671" velocity="2.1750"/>
	</joint>
	<link name="link_6_to_10">
		<visual>
			<origin rpy="-1.4309842780450455 2.220446049250313e-16 2.1417882075579255" xyz="-0.03718086336456494 -0.023883827629126213 0.006219023863448914"/>
			<geometry>
				<cylinder length="0.08925312500000002" radius="0.008800000000000002"/>
			</geometry>
			<material name="brown"/>
		</visual>
		<collision>
			<origin rpy="-1.4309842780450455 2.220446049250313e-16 2.1417882075579255" xyz="-0.03718086336456494 -0.023883827629126213 0.006219023863448914"/>
			<geometry>
				<cylinder length="0.08925312500000002" radius="0.008800000000000002"/>
			</geometry>
		</collision>
	</link>
	<joint name="joint7_base" type="fixed">
		<parent link="link_3_to_7"/>
		<origin rpy="0 0 0" xyz="0.01977223206600094 0.012171024103118206 0.13533531567059476"/>
		<child link="link7_base"/>
	</joint>
	<link name="link7_base">
		<inertial>
			<mass value="0.001"/>
			<inertia ixx="0.001" ixy="0" ixz="0" iyy="0.001" iyz="0" izz="0.001"/>
		</inertial>
	</link>
	<joint name="joint7_x_to_11" type="revolute">
		<safety_controller k_position="100.0" k_velocity="40.0" soft_lower_limit="-2.8973" soft_upper_limit="2.8973"/>
		<parent link="link7_base"/>
		<child link="link7_x_to_11"/>
		<origin rpy="0 0 0" xyz="0 0 0"/>
		<axis xyz="1 0 0"/>
		<dynamics damping="10.0"/>
		<limit effort="10" lower="-3.1416" upper="3.1416" velocity="3"/>
		<limit effort="87" lower="-2.9671" upper="2.9671" velocity="2.1750"/>
	</joint>
	<link name="link7_x_to_11">
		<inertial>
			<mass value="0.001"/>
			<inertia ixx="0.001" ixy="0" ixz="0" iyy="0.001" iyz="0" izz="0.001"/>
		</inertial>
	</link>
	<joint name="joint7_y_to_11" type="revolute">
		<safety_controller k_position="100.0" k_velocity="40.0" soft_lower_limit="-2.8973" soft_upper_limit="2.8973"/>
		<parent link="link7_x_to_11"/>
		<child link="link7_y_to_11"/>
		<origin rpy="0 0 0" xyz="0 0 0"/>
		<axis xyz="0 1 0"/>
		<dynamics damping="10.0"/>
		<limit effort="10" lower="-3.1416" upper="3.1416" velocity="3"/>
		<limit effort="87" lower="-2.9671" upper="2.9671" velocity="2.1750"/>
	</joint>
	<link name="link7_y_to_11">
		<inertial>
			<mass value="0.001"/>
			<inertia ixx="0.001" ixy="0" ixz="0" iyy="0.001" iyz="0" izz="0.001"/>
		</inertial>
	</link>
	<joint name="joint7_z_to_11" type="revolute">
		<safety_controller k_position="100.0" k_velocity="40.0" soft_lower_limit="-2.8973" soft_upper_limit="2.8973"/>
		<parent link="link7_y_to_11"/>
		<child link="link_7_to_11"/>
		<origin rpy="0 0 0" xyz="0 0 0"/>
		<axis xyz="0 0 1"/>
		<dynamics damping="10.0"/>
		<limit effort="10" lower="-3.1416" upper="3.1416" velocity="3"/>
		<limit effort="87" lower="-2.9671" upper="2.9671" velocity="2.1750"/>
	</joint>
	<joint name="joint7_x_to_19" type="revolute">
		<safety_controller k_position="100.0" k_velocity="40.0" soft_lower_limit="-2.8973" soft_upper_limit="2.8973"/>
		<parent link="link7_base"/>
		<child link="link7_x_to_19"/>
		<origin rpy="0 0 0" xyz="0 0 0"/>
		<axis xyz="1 0 0"/>
		<dynamics damping="10.0"/>
		<limit effort="10" lower="-3.1416" upper="3.1416" velocity="3"/>
		<limit effort="87" lower="-2.9671" upper="2.9671" velocity="2.1750"/>
	</joint>
	<link name="link7_x_to_19">
		<inertial>
			<mass value="0.001"/>
			<inertia ixx="0.001" ixy="0" ixz="0" iyy="0.001" iyz="0" izz="0.001"/>
		</inertial>
	</link>
	<joint name="joint7_y_to_19" type="revolute">
		<safety_controller k_position="100.0" k_velocity="40.0" soft_lower_limit="-2.8973" soft_upper_limit="2.8973"/>
		<parent link="link7_x_to_19"/>
		<child link="link7_y_to_19"/>
		<origin rpy="0 0 0" xyz="0 0 0"/>
		<axis xyz="0 1 0"/>
		<dynamics damping="10.0"/>
		<limit effort="10" lower="-3.1416" upper="3.1416" velocity="3"/>
		<limit effort="87" lower="-2.9671" upper="2.9671" velocity="2.1750"/>
	</joint>
	<link name="link7_y_to_19">
		<inertial>
			<mass value="0.001"/>
			<inertia ixx="0.001" ixy="0" ixz="0" iyy="0.001" iyz="0" izz="0.001"/>
		</inertial>
	</link>
	<joint name="joint7_z_to_19" type="revolute">
		<safety_controller k_position="100.0" k_velocity="40.0" soft_lower_limit="-2.8973" soft_upper_limit="2.8973"/>
		<parent link="link7_y_to_19"/>
		<child link="link_7_to_19"/>
		<origin rpy="0 0 0" xyz="0 0 0"/>
		<axis xyz="0 0 1"/>
		<dynamics damping="10.0"/>
		<limit effort="10" lower="-3.1416" upper="3.1416" velocity="3"/>
		<limit effort="87" lower="-2.9671" upper="2.9671" velocity="2.1750"/>
	</joint>
	<link name="link_7_to_11">
		<visual>
			<origin rpy="-0.36149180186543284 0.0 0.18121660444268664" xyz="-0.0028445269711724758 0.015524631543049085 0.04174235932873516"/>
			<geometry>
				<cylinder length="0.08925312499999997" radius="0.008800000000000002"/>
			</geometry>
			<material name="brown"/>
		</visual>
		<collision>
			<origin rpy="-0.36149180186543284 0.0 0.18121660444268664" xyz="-0.0028445269711724758 0.015524631543049085 0.04174235932873516"/>
			<geometry>
				<cylinder length="0.08925312499999997" radius="0.008800000000000002"/>
			</geometry>
		</collision>
	</link>
	<link name="link_7_to_19">
		<visual>
			<origin rpy="-1.3554403843944374 0.0 3.135873051083369" xyz="-0.00016207668899381397 -0.028336745678322662 0.006198712329851586"/>
			<geometry>
				<cylinder length="0.05801453125000002" radius="0.008"/>
			</geometry>
			<material name="brown"/>
		</visual>
		<collision>
			<origin rpy="-1.3554403843944374 0.0 3.135873051083369" xyz="-0.00016207668899381397 -0.028336745678322662 0.006198712329851586"/>
			<geometry>
				<cylinder length="0.05801453125000002" radius="0.008"/>
			</geometry>
		</collision>
	</link>
	<joint name="joint8_base" type="fixed">
		<parent link="link_4_to_8"/>
		<origin rpy="0 0 0" xyz="0.05145370668003468 0.12728141773382118 0.002584458319160099"/>
		<child link="link8_base"/>
	</joint>
	<link name="link8_base">
		<inertial>
			<mass value="0.001"/>
			<inertia ixx="0.001" ixy="0" ixz="0" iyy="0.001" iyz="0" izz="0.001"/>
		</inertial>
	</link>
	<joint name="joint8_x_to_14" type="revolute">
		<safety_controller k_position="100.0" k_velocity="40.0" soft_lower_limit="-2.8973" soft_upper_limit="2.8973"/>
		<parent link="link8_base"/>
		<child link="link8_x_to_14"/>
		<origin rpy="0 0 0" xyz="0 0 0"/>
		<axis xyz="1 0 0"/>
		<dynamics damping="10.0"/>
		<limit effort="10" lower="-3.1416" upper="3.1416" velocity="3"/>
		<limit effort="87" lower="-2.9671" upper="2.9671" velocity="2.1750"/>
	</joint>
	<link name="link8_x_to_14">
		<inertial>
			<mass value="0.001"/>
			<inertia ixx="0.001" ixy="0" ixz="0" iyy="0.001" iyz="0" izz="0.001"/>
		</inertial>
	</link>
	<joint name="joint8_y_to_14" type="revolute">
		<safety_controller k_position="100.0" k_velocity="40.0" soft_lower_limit="-2.8973" soft_upper_limit="2.8973"/>
		<parent link="link8_x_to_14"/>
		<child link="link8_y_to_14"/>
		<origin rpy="0 0 0" xyz="0 0 0"/>
		<axis xyz="0 1 0"/>
		<dynamics damping="10.0"/>
		<limit effort="10" lower="-3.1416" upper="3.1416" velocity="3"/>
		<limit effort="87" lower="-2.9671" upper="2.9671" velocity="2.1750"/>
	</joint>
	<link name="link8_y_to_14">
		<inertial>
			<mass value="0.001"/>
			<inertia ixx="0.001" ixy="0" ixz="0" iyy="0.001" iyz="0" izz="0.001"/>
		</inertial>
	</link>
	<joint name="joint8_z_to_14" type="revolute">
		<safety_controller k_position="100.0" k_velocity="40.0" soft_lower_limit="-2.8973" soft_upper_limit="2.8973"/>
		<parent link="link8_y_to_14"/>
		<child link="link_8_to_14"/>
		<origin rpy="0 0 0" xyz="0 0 0"/>
		<axis xyz="0 0 1"/>
		<dynamics damping="10.0"/>
		<limit effort="10" lower="-3.1416" upper="3.1416" velocity="3"/>
		<limit effort="87" lower="-2.9671" upper="2.9671" velocity="2.1750"/>
	</joint>
	<link name="link_8_to_14">
		<visual>
			<origin rpy="-1.3725450846027067 0.0 -0.3720199749763306" xyz="0.015903923111501767 0.04075955377676452 0.008789430365438389"/>
			<geometry>
				<cylinder length="0.08925312500000006" radius="0.008"/>
			</geometry>
			<material name="brown"/>
		</visual>
		<collision>
			<origin rpy="-1.3725450846027067 0.0 -0.3720199749763306" xyz="0.015903923111501767 0.04075955377676452 0.008789430365438389"/>
			<geometry>
				<cylinder length="0.08925312500000006" radius="0.008"/>
			</geometry>
		</collision>
	</link>
	<joint name="joint9_base" type="fixed">
		<parent link="link_5_to_9"/>
		<origin rpy="0 0 0" xyz="-0.022062347405256755 -0.08500869077755047 0.015902692901587523"/>
		<child link="link9_base"/>
	</joint>
	<link name="link9_base">
		<inertial>
			<mass value="0.001"/>
			<inertia ixx="0.001" ixy="0" ixz="0" iyy="0.001" iyz="0" izz="0.001"/>
		</inertial>
	</link>
	<joint name="joint9_x_to_17" type="revolute">
		<safety_controller k_position="100.0" k_velocity="40.0" soft_lower_limit="-2.8973" soft_upper_limit="2.8973"/>
		<parent link="link9_base"/>
		<child link="link9_x_to_17"/>
		<origin rpy="0 0 0" xyz="0 0 0"/>
		<axis xyz="1 0 0"/>
		<dynamics damping="10.0"/>
		<limit effort="10" lower="-3.1416" upper="3.1416" velocity="3"/>
		<limit effort="87" lower="-2.9671" upper="2.9671" velocity="2.1750"/>
	</joint>
	<link name="link9_x_to_17">
		<inertial>
			<mass value="0.001"/>
			<inertia ixx="0.001" ixy="0" ixz="0" iyy="0.001" iyz="0" izz="0.001"/>
		</inertial>
	</link>
	<joint name="joint9_y_to_17" type="revolute">
		<safety_controller k_position="100.0" k_velocity="40.0" soft_lower_limit="-2.8973" soft_upper_limit="2.8973"/>
		<parent link="link9_x_to_17"/>
		<child link="link9_y_to_17"/>
		<origin rpy="0 0 0" xyz="0 0 0"/>
		<axis xyz="0 1 0"/>
		<dynamics damping="10.0"/>
		<limit effort="10" lower="-3.1416" upper="3.1416" velocity="3"/>
		<limit effort="87" lower="-2.9671" upper="2.9671" velocity="2.1750"/>
	</joint>
	<link name="link9_y_to_17">
		<inertial>
			<mass value="0.001"/>
			<inertia ixx="0.001" ixy="0" ixz="0" iyy="0.001" iyz="0" izz="0.001"/>
		</inertial>
	</link>
	<joint name="joint9_z_to_17" type="revolute">
		<safety_controller k_position="100.0" k_velocity="40.0" soft_lower_limit="-2.8973" soft_upper_limit="2.8973"/>
		<parent link="link9_y_to_17"/>
		<child link="link_9_to_17"/>
		<origin rpy="0 0 0" xyz="0 0 0"/>
		<axis xyz="0 0 1"/>
		<dynamics damping="10.0"/>
		<limit effort="10" lower="-3.1416" upper="3.1416" velocity="3"/>
		<limit effort="87" lower="-2.9671" upper="2.9671" velocity="2.1750"/>
	</joint>
	<link name="link_9_to_17">
		<visual>
			<origin rpy="-1.2477052540002893 0.0 2.8059682673840194" xyz="-0.009059470217419121 -0.025971664158045638 0.00920978388892435"/>
			<geometry>
				<cylinder length="0.058014531250000015" radius="0.008"/>
			</geometry>
			<material name="brown"/>
		</visual>
		<collision>
			<origin rpy="-1.2477052540002893 0.0 2.8059682673840194" xyz="-0.009059470217419121 -0.025971664158045638 0.00920978388892435"/>
			<geometry>
				<cylinder length="0.058014531250000015" radius="0.008"/>
			</geometry>
		</collision>
	</link>
	<joint name="joint10_base" type="fixed">
		<parent link="link_6_to_10"/>
		<origin rpy="0 0 0" xyz="-0.07436172672912988 -0.047767655258252426 0.012438047726897827"/>
		<child link="link10_base"/>
	</joint>
	<link name="link10_base">
		<inertial>
			<mass value="0.001"/>
			<inertia ixx="0.001" ixy="0" ixz="0" iyy="0.001" iyz="0" izz="0.001"/>
		</inertial>
	</link>
	<joint name="joint10_x_to_18" type="revolute">
		<safety_controller k_position="100.0" k_velocity="40.0" soft_lower_limit="-2.8973" soft_upper_limit="2.8973"/>
		<parent link="link10_base"/>
		<child link="link10_x_to_18"/>
		<origin rpy="0 0 0" xyz="0 0 0"/>
		<axis xyz="1 0 0"/>
		<dynamics damping="10.0"/>
		<limit effort="10" lower="-3.1416" upper="3.1416" velocity="3"/>
		<limit effort="87" lower="-2.9671" upper="2.9671" velocity="2.1750"/>
	</joint>
	<link name="link10_x_to_18">
		<inertial>
			<mass value="0.001"/>
			<inertia ixx="0.001" ixy="0" ixz="0" iyy="0.001" iyz="0" izz="0.001"/>
		</inertial>
	</link>
	<joint name="joint10_y_to_18" type="revolute">
		<safety_controller k_position="100.0" k_velocity="40.0" soft_lower_limit="-2.8973" soft_upper_limit="2.8973"/>
		<parent link="link10_x_to_18"/>
		<child link="link10_y_to_18"/>
		<origin rpy="0 0 0" xyz="0 0 0"/>
		<axis xyz="0 1 0"/>
		<dynamics damping="10.0"/>
		<limit effort="10" lower="-3.1416" upper="3.1416" velocity="3"/>
		<limit effort="87" lower="-2.9671" upper="2.9671" velocity="2.1750"/>
	</joint>
	<link name="link10_y_to_18">
		<inertial>
			<mass value="0.001"/>
			<inertia ixx="0.001" ixy="0" ixz="0" iyy="0.001" iyz="0" izz="0.001"/>
		</inertial>
	</link>
	<joint name="joint10_z_to_18" type="revolute">
		<safety_controller k_position="100.0" k_velocity="40.0" soft_lower_limit="-2.8973" soft_upper_limit="2.8973"/>
		<parent link="link10_y_to_18"/>
		<child link="link_10_to_18"/>
		<origin rpy="0 0 0" xyz="0 0 0"/>
		<axis xyz="0 0 1"/>
		<dynamics damping="10.0"/>
		<limit effort="10" lower="-3.1416" upper="3.1416" velocity="3"/>
		<limit effort="87" lower="-2.9671" upper="2.9671" velocity="2.1750"/>
	</joint>
	<link name="link_10_to_18">
		<visual>
			<origin rpy="-1.471127662789665 0.0 1.4579811243917606" xyz="-0.02867982721889696 0.0032493172021255817 0.0028863311406516212"/>
			<geometry>
				<cylinder length="0.05801453125000003" radius="0.008"/>
			</geometry>
			<material name="brown"/>
		</visual>
		<collision>
			<origin rpy="-1.471127662789665 0.0 1.4579811243917606" xyz="-0.02867982721889696 0.0032493172021255817 0.0028863311406516212"/>
			<geometry>
				<cylinder length="0.05801453125000003" radius="0.008"/>
			</geometry>
		</collision>
	</link>
	<joint name="joint11_base" type="fixed">
		<parent link="link_7_to_11"/>
		<origin rpy="0 0 0" xyz="-0.0056890539423449515 0.03104926308609817 0.08348471865747031"/>
		<child link="link11_base"/>
	</joint>
	<link name="link11_base">
		<inertial>
			<mass value="0.001"/>
			<inertia ixx="0.001" ixy="0" ixz="0" iyy="0.001" iyz="0" izz="0.001"/>
		</inertial>
	</link>
	<joint name="joint11_x_to_20" type="revolute">
		<safety_controller k_position="100.0" k_velocity="40.0" soft_lower_limit="-2.8973" soft_upper_limit="2.8973"/>
		<parent link="link11_base"/>
		<child link="link11_x_to_20"/>
		<origin rpy="0 0 0" xyz="0 0 0"/>
		<axis xyz="1 0 0"/>
		<dynamics damping="10.0"/>
		<limit effort="10" lower="-3.1416" upper="3.1416" velocity="3"/>
		<limit effort="87" lower="-2.9671" upper="2.9671" velocity="2.1750"/>
	</joint>
	<link name="link11_x_to_20">
		<inertial>
			<mass value="0.001"/>
			<inertia ixx="0.001" ixy="0" ixz="0" iyy="0.001" iyz="0" izz="0.001"/>
		</inertial>
	</link>
	<joint name="joint11_y_to_20" type="revolute">
		<safety_controller k_position="100.0" k_velocity="40.0" soft_lower_limit="-2.8973" soft_upper_limit="2.8973"/>
		<parent link="link11_x_to_20"/>
		<child link="link11_y_to_20"/>
		<origin rpy="0 0 0" xyz="0 0 0"/>
		<axis xyz="0 1 0"/>
		<dynamics damping="10.0"/>
		<limit effort="10" lower="-3.1416" upper="3.1416" velocity="3"/>
		<limit effort="87" lower="-2.9671" upper="2.9671" velocity="2.1750"/>
	</joint>
	<link name="link11_y_to_20">
		<inertial>
			<mass value="0.001"/>
			<inertia ixx="0.001" ixy="0" ixz="0" iyy="0.001" iyz="0" izz="0.001"/>
		</inertial>
	</link>
	<joint name="joint11_z_to_20" type="revolute">
		<safety_controller k_position="100.0" k_velocity="40.0" soft_lower_limit="-2.8973" soft_upper_limit="2.8973"/>
		<parent link="link11_y_to_20"/>
		<child link="link_11_to_20"/>
		<origin rpy="0 0 0" xyz="0 0 0"/>
		<axis xyz="0 0 1"/>
		<dynamics damping="10.0"/>
		<limit effort="10" lower="-3.1416" upper="3.1416" velocity="3"/>
		<limit effort="87" lower="-2.9671" upper="2.9671" velocity="2.1750"/>
	</joint>
	<link name="link_11_to_20">
		<visual>
			<origin rpy="-1.2214740067865 0.0 0.42256581684304373" xyz="-0.011177478988749876 0.024857977676166924 0.009928059646605147"/>
			<geometry>
				<cylinder length="0.058014531250000036" radius="0.008"/>
			</geometry>
			<material name="brown"/>
		</visual>
		<collision>
			<origin rpy="-1.2214740067865 0.0 0.42256581684304373" xyz="-0.011177478988749876 0.024857977676166924 0.009928059646605147"/>
			<geometry>
				<cylinder length="0.058014531250000036" radius="0.008"/>
			</geometry>
		</collision>
	</link>
	<joint name="joint12_base" type="fixed">
		<parent link="link_4_to_12"/>
		<origin rpy="0 0 0" xyz="0.06720550166101652 -0.058597292738849845 0.00398724872992251"/>
		<child link="link12_tip"/>
	</joint>
	<link name="link12_tip">
		<visual>
			<origin rpy="0 0 0" xyz="0 0 0"/>
			<geometry>
				<box size="0.016 0.016 0.016"/>
			</geometry>
			<material name="green"/>
		</visual>
		<collision>
			<origin rpy="0 0 0" xyz="0 0 0"/>
			<geometry>
				<box size="0.016 0.016 0.016"/>
			</geometry>
		</collision>
	</link>
	<joint name="joint13_base" type="fixed">
		<parent link="link_1_to_13"/>
		<origin rpy="0 0 0" xyz="0.07046794794839348 0.05395719341972871 0.009434506477507043"/>
		<child link="link13_tip"/>
	</joint>
	<link name="link13_tip">
		<visual>
			<origin rpy="0 0 0" xyz="0 0 0"/>
			<geometry>
				<box size="0.016 0.016 0.016"/>
			</geometry>
			<material name="green"/>
		</visual>
		<collision>
			<origin rpy="0 0 0" xyz="0 0 0"/>
			<geometry>
				<box size="0.016 0.016 0.016"/>
			</geometry>
		</collision>
	</link>
	<joint name="joint14_base" type="fixed">
		<parent link="link_8_to_14"/>
		<origin rpy="0 0 0" xyz="0.03180784622300353 0.08151910755352904 0.017578860730876777"/>
		<child link="link14_tip"/>
	</joint>
	<link name="link14_tip">
		<visual>
			<origin rpy="0 0 0" xyz="0 0 0"/>
			<geometry>
				<box size="0.016 0.016 0.016"/>
			</geometry>
			<material name="green"/>
		</visual>
		<collision>
			<origin rpy="0 0 0" xyz="0 0 0"/>
			<geometry>
				<box size="0.016 0.016 0.016"/>
			</geometry>
		</collision>
	</link>
	<joint name="joint15_base" type="fixed">
		<parent link="link_2_to_15"/>
		<origin rpy="0 0 0" xyz="0.08307623678726558 0.012161696037683621 0.030274615654353076"/>
		<child link="link15_tip"/>
	</joint>
	<link name="link15_tip">
		<visual>
			<origin rpy="0 0 0" xyz="0 0 0"/>
			<geometry>
				<box size="0.016 0.016 0.016"/>
			</geometry>
			<material name="green"/>
		</visual>
		<collision>
			<origin rpy="0 0 0" xyz="0 0 0"/>
			<geometry>
				<box size="0.016 0.016 0.016"/>
			</geometry>
		</collision>
	</link>
	<joint name="joint16_base" type="fixed">
		<parent link="link_3_to_16"/>
		<origin rpy="0 0 0" xyz="0.061384032821377284 0.060222480595849504 -0.023903423765900822"/>
		<child link="link16_tip"/>
	</joint>
	<link name="link16_tip">
		<visual>
			<origin rpy="0 0 0" xyz="0 0 0"/>
			<geometry>
				<box size="0.016 0.016 0.016"/>
			</geometry>
			<material name="green"/>
		</visual>
		<collision>
			<origin rpy="0 0 0" xyz="0 0 0"/>
			<geometry>
				<box size="0.016 0.016 0.016"/>
			</geometry>
		</collision>
	</link>
	<joint name="joint17_base" type="fixed">
		<parent link="link_9_to_17"/>
		<origin rpy="0 0 0" xyz="-0.018118940434838242 -0.051943328316091275 0.0184195677778487"/>
		<child link="link17_tip"/>
	</joint>
	<link name="link17_tip">
		<visual>
			<origin rpy="0 0 0" xyz="0 0 0"/>
			<geometry>
				<box size="0.016 0.016 0.016"/>
			</geometry>
			<material name="green"/>
		</visual>
		<collision>
			<origin rpy="0 0 0" xyz="0 0 0"/>
			<geometry>
				<box size="0.016 0.016 0.016"/>
			</geometry>
		</collision>
	</link>
	<joint name="joint18_base" type="fixed">
		<parent link="link_10_to_18"/>
		<origin rpy="0 0 0" xyz="-0.05735965443779392 0.0064986344042511635 0.0057726622813032424"/>
		<child link="link18_tip"/>
	</joint>
	<link name="link18_tip">
		<visual>
			<origin rpy="0 0 0" xyz="0 0 0"/>
			<geometry>
				<box size="0.016 0.016 0.016"/>
			</geometry>
			<material name="green"/>
		</visual>
		<collision>
			<origin rpy="0 0 0" xyz="0 0 0"/>
			<geometry>
				<box size="0.016 0.016 0.016"/>
			</geometry>
		</collision>
	</link>
	<joint name="joint19_base" type="fixed">
		<parent link="link_7_to_19"/>
		<origin rpy="0 0 0" xyz="-0.00032415337798762794 -0.056673491356645324 0.012397424659703171"/>
		<child link="link19_tip"/>
	</joint>
	<link name="link19_tip">
		<visual>
			<origin rpy="0 0 0" xyz="0 0 0"/>
			<geometry>
				<box size="0.016 0.016 0.016"/>
			</geometry>
			<material name="green"/>
		</visual>
		<collision>
			<origin rpy="0 0 0" xyz="0 0 0"/>
			<geometry>
				<box size="0.016 0.016 0.016"/>
			</geometry>
		</collision>
	</link>
	<joint name="joint20_base" type="fixed">
		<parent link="link_11_to_20"/>
		<origin rpy="0 0 0" xyz="-0.022354957977499753 0.04971595535233385 0.019856119293210295"/>
		<child link="link20_tip"/>
	</joint>
	<link name="link20_tip">
		<visual>
			<origin rpy="0 0 0" xyz="0 0 0"/>
			<geometry>
				<box size="0.016 0.016 0.016"/>
			</geometry>
			<material name="green"/>
		</visual>
		<collision>
			<origin rpy="0 0 0" xyz="0 0 0"/>
			<geometry>
				<box size="0.016 0.016 0.016"/>
			</geometry>
		</collision>
	</link>
</robot>
