<?xml version="1.0" ?>
<robot name="pi_robot">

 <!-- * * * Color Definitions * * * -->
 <material name="blue">
 <color rgba="0 0 0.8 1"/>
 </material>

 <material name="green">
 <color rgba="0 0.6 0 0.8"/>
 </material>

 <material name="brown">
 <color rgba="0.3 0.15 0.05 1.0"/>
 </material>

 <!-- * * * Link Definitions * * * -->

 <link name="base_link">
 <visual>
 <origin xyz="0 0 0" rpy="0 0 0"/>
 <geometry>
 <box size="1 1 0.02"/>
 </geometry>
 <material name="green">
 </material>
 </visual>
 <collision>
 <origin xyz="0 0 0" rpy="0 0 0"/>
 <geometry>
 <box size="1 1 0.02"/>
 </geometry>
 </collision> 
 </link>

 <!-- spherical joint -->
<joint name="link1_jointx" type="revolute">
 <safety_controller k_position="100.0" k_velocity="40.0" soft_lower_limit="-2.8973" soft_upper_limit="2.8973"/>
 <parent link="base_link"/>
 <child link="link1x"/>
 <origin xyz="0 0 0.01" rpy="0 0 0"/>
 <axis xyz="1 0 0"/>
 <dynamics damping="10.0"/>
 <limit lower="-3.1416" upper="3.1416" effort="10" velocity="3"/>
 <limit effort="87" lower="-2.9671" upper="2.9671" velocity="2.1750"/>
 </joint> 

 <link name="link1x">
 <inertial>
 <mass value="0.001" />
 <inertia ixx="0.001" ixy="0" ixz="0" iyy="0.001" iyz="0" izz="0.001" />
 </inertial> 
 </link>

<joint name="link1_jointy" type="revolute">
 <safety_controller k_position="100.0" k_velocity="40.0" soft_lower_limit="-2.8973" soft_upper_limit="2.8973"/>
 <parent link="link1x"/>
 <child link="link1z"/>
 <origin xyz="0 0 0" rpy="0 0 0"/>
 <axis xyz="0 1 0"/>
 <dynamics damping="10.0"/>
 <limit lower="-3.1416" upper="3.1416" effort="10" velocity="3"/>
 <limit effort="87" lower="-2.9671" upper="2.9671" velocity="2.1750"/>
 </joint> 

 <link name="link1z">
 <inertial>
 <mass value="0.001" />
 <inertia ixx="0.001" ixy="0" ixz="0" iyy="0.001" iyz="0" izz="0.001" />
 </inertial> 
 </link> 

 <joint name="link1_jointz" type="revolute">
 <safety_controller k_position="100.0" k_velocity="40.0" soft_lower_limit="-2.8973" soft_upper_limit="2.8973"/>
 <parent link="link1z"/>
 <child link="link1"/>
 <origin xyz="0 0 0" rpy="0 0 0"/>
 <axis xyz="0 0 1"/>
 <dynamics damping="10.0"/>
 <limit lower="-3.1416" upper="3.1416" effort="10" velocity="3"/>
 <limit effort="87" lower="-2.9671" upper="2.9671" velocity="2.1750"/>
 </joint> 


<!-- link -->
 <link name="link1">
 <visual>
 <origin xyz="0 0 0.5" rpy="0 0 0"/>
 <geometry>
 <cylinder radius="0.1" length="1"/>
 </geometry>
 <material name="brown">
 </material>
 </visual>
 <collision>
 <origin xyz="0 0 0.5" rpy="0 0 0"/>
 <geometry>
 <cylinder radius="0.1" length="1"/>
 </geometry>
 </collision> 
 </link>

<!-- spherical joint -->

<joint name="link2_jointx" type="revolute">
 <safety_controller k_position="100.0" k_velocity="40.0" soft_lower_limit="-2.8973" soft_upper_limit="2.8973"/>
 <parent link="link1"/>
 <child link="link2x"/>
 <origin xyz="0 0 1" rpy="0 0 0"/>
 <axis xyz="1 0 0"/>
 <dynamics damping="10.0"/>
 <limit lower="-3.1416" upper="3.1416" effort="10" velocity="3"/>
 <limit effort="87" lower="-2.9671" upper="2.9671" velocity="2.1750"/>
 </joint> 

 <link name="link2x">
 <inertial>
 <mass value="0.001" />
 <inertia ixx="0.001" ixy="0" ixz="0" iyy="0.001" iyz="0" izz="0.001" />
 </inertial> 
 </link>

<joint name="link2_jointy" type="revolute">
 <safety_controller k_position="100.0" k_velocity="40.0" soft_lower_limit="-2.8973" soft_upper_limit="2.8973"/>
 <parent link="link2x"/>
 <child link="link2z"/>
 <origin xyz="0 0 0" rpy="0 0 0"/>
 <axis xyz="0 1 0"/>
 <dynamics damping="10.0"/>
 <limit lower="-3.1416" upper="3.1416" effort="10" velocity="3"/>
 <limit effort="87" lower="-2.9671" upper="2.9671" velocity="2.1750"/>
 </joint> 

 <link name="link2z">
 <inertial>
 <mass value="0.001" />
 <inertia ixx="0.001" ixy="0" ixz="0" iyy="0.001" iyz="0" izz="0.001" />
 </inertial> 
 </link> 

 <joint name="link2_jointz" type="revolute">
 <safety_controller k_position="100.0" k_velocity="40.0" soft_lower_limit="-2.8973" soft_upper_limit="2.8973"/>
 <parent link="link2z"/>
 <child link="link2"/>
 <origin xyz="0 0 0" rpy="0 0 0"/>
 <axis xyz="0 0 1"/>
 <dynamics damping="10.0"/>
 <limit lower="-3.1416" upper="3.1416" effort="10" velocity="3"/>
 <limit effort="87" lower="-2.9671" upper="2.9671" velocity="2.1750"/>
 </joint> 

<!-- link -->

 <link name="link2">
 <visual>
 <origin xyz="0 0 0.25" rpy="0 0 0"/>
 <geometry>
 <cylinder radius="0.075" length="0.5"/>
 </geometry>
 <material name="brown">
 </material>
 </visual>
 <collision>
 <origin xyz="0 0 0.25" rpy="0 0 0"/>
 <geometry>
 <cylinder radius="0.05" length="0.5"/>
 </geometry>
 </collision> 
 </link>
 
<!-- spherical joint -->
 
 <joint name="link3_jointx" type="revolute">
 <safety_controller k_position="100.0" k_velocity="40.0" soft_lower_limit="-2.8973" soft_upper_limit="2.8973"/>
 <parent link="link2"/>
 <child link="link3x"/>
 <origin xyz="0 0 0.5" rpy="0 0 0"/>
 <axis xyz="1 0 0"/>
 <dynamics damping="10.0"/>
 <limit lower="-3.1416" upper="3.1416" effort="10" velocity="3"/>
 <limit effort="87" lower="-2.9671" upper="2.9671" velocity="2.1750"/>
 </joint> 

 <link name="link3x">
 <inertial>
 <mass value="0.001" />
 <inertia ixx="0.001" ixy="0" ixz="0" iyy="0.001" iyz="0" izz="0.001" />
 </inertial> 
 </link>

<joint name="link3_jointy" type="revolute">
 <safety_controller k_position="100.0" k_velocity="40.0" soft_lower_limit="-2.8973" soft_upper_limit="2.8973"/>
 <parent link="link3x"/>
 <child link="link3z"/>
 <origin xyz="0 0 0" rpy="0 0 0"/>
 <axis xyz="0 1 0"/>
 <dynamics damping="10.0"/>
 <limit lower="-3.1416" upper="3.1416" effort="10" velocity="3"/>
 <limit effort="87" lower="-2.9671" upper="2.9671" velocity="2.1750"/>
 </joint> 

 <link name="link3z">
 <inertial>
 <mass value="0.001" />
 <inertia ixx="0.001" ixy="0" ixz="0" iyy="0.001" iyz="0" izz="0.001" />
 </inertial> 
 </link> 

 <joint name="link3_jointz" type="revolute">
 <safety_controller k_position="100.0" k_velocity="40.0" soft_lower_limit="-2.8973" soft_upper_limit="2.8973"/>
 <parent link="link3z"/>
 <child link="link3"/>
 <origin xyz="0 0 0" rpy="0 0 0"/>
 <axis xyz="0 0 1"/>
 <dynamics damping="10.0"/>
 <limit lower="-3.1416" upper="3.1416" effort="10" velocity="3"/>
 <limit effort="87" lower="-2.9671" upper="2.9671" velocity="2.1750"/>
 </joint> 

 <!-- link -->
 
 <link name="link3">
 <visual>
 <origin xyz="0 0 0.25" rpy="0 0 0"/>
 <geometry>
 <cylinder radius="0.05" length="0.5"/>
 </geometry>
 <material name="brown">
 </material>
 </visual>
 <collision>
 <origin xyz="0 0 0.25" rpy="0 0 0"/>
 <geometry>
 <cylinder radius="0.05" length="0.5"/>
 </geometry>
 </collision> 
 </link>
 
 <!-- spherical joint -->
 <joint name="link4_jointx" type="revolute">
 <safety_controller k_position="100.0" k_velocity="40.0" soft_lower_limit="-2.8973" soft_upper_limit="2.8973"/>
 <parent link="link3"/>
 <child link="link4x"/>
 <origin xyz="0 0 0.5" rpy="0 0 0"/>
 <axis xyz="1 0 0"/>
 <dynamics damping="10.0"/>
 <limit lower="-3.1416" upper="3.1416" effort="10" velocity="3"/>
 <limit effort="87" lower="-2.9671" upper="2.9671" velocity="2.1750"/>
 </joint> 

 <link name="link4x">
 <inertial>
 <mass value="0.001" />
 <inertia ixx="0.001" ixy="0" ixz="0" iyy="0.001" iyz="0" izz="0.001" />
 </inertial> 
 </link>

<joint name="link4_jointy" type="revolute">
 <safety_controller k_position="100.0" k_velocity="40.0" soft_lower_limit="-2.8973" soft_upper_limit="2.8973"/>
 <parent link="link4x"/>
 <child link="link4z"/>
 <origin xyz="0 0 0" rpy="0 0 0"/>
 <axis xyz="0 1 0"/>
 <dynamics damping="10.0"/>
 <limit lower="-3.1416" upper="3.1416" effort="10" velocity="3"/>
 <limit effort="87" lower="-2.9671" upper="2.9671" velocity="2.1750"/>
 </joint> 

 <link name="link4z">
 <inertial>
 <mass value="0.001" />
 <inertia ixx="0.001" ixy="0" ixz="0" iyy="0.001" iyz="0" izz="0.001" />
 </inertial> 
 </link> 

 <!-- repeat zjoint for link 4,5,6 as they branch from link4z -->
 <!-- ============================ layer 2 ============================= -->

 <joint name="link4_jointz" type="revolute">
 <safety_controller k_position="100.0" k_velocity="40.0" soft_lower_limit="-2.8973" soft_upper_limit="2.8973"/>
 <parent link="link4z"/>
 <child link="link4"/>
 <origin xyz="0 0 0" rpy="0 0 0"/>
 <axis xyz="0 0 1"/>
 <dynamics damping="10.0"/>
 <limit lower="-3.1416" upper="3.1416" effort="10" velocity="3"/>
 <limit effort="87" lower="-2.9671" upper="2.9671" velocity="2.1750"/>
 </joint> 
 
 <!-- link -->
 <!-- pi/4 = 0.78539816339 -->
 <!-- 0.25/sqrt(2) = 0.17677669529 -->
 <!-- 0.17677669529 /sqrt(2) = 0.12499999999 -->

 <link name="link4">
 <visual>
 <origin xyz="0.125 -0.17677669529 0.125" rpy= "0.78539816339  0.78539816339 0"/>
 <geometry>
 <cylinder radius="0.03" length="0.5"/>
 </geometry>
 <material name="brown">
 </material>
 </visual>
 <collision>
 <origin xyz="0.125 -0.17677669529 0.125" rpy= "0.78539816339  0.78539816339 0"/>
 <geometry>
 <cylinder radius="0.003" length="0.05"/>
 </geometry>
 </collision> 
 </link>

<joint name="link5_jointz" type="revolute">
 <safety_controller k_position="100.0" k_velocity="40.0" soft_lower_limit="-2.8973" soft_upper_limit="2.8973"/>
 <parent link="link4z"/>
 <child link="link5"/>
 <origin xyz="0 0 0" rpy="0 0 0"/>
 <axis xyz="0 0 1"/>
 <dynamics damping="10.0"/>
 <limit lower="-3.1416" upper="3.1416" effort="10" velocity="3"/>
 <limit effort="87" lower="-2.9671" upper="2.9671" velocity="2.1750"/>
 </joint> 
 <!-- link -->
 <!-- pi/4 = 0.78539816339 -->
 <!-- 0.25/sqrt(2) = 0.17677669529 -->
 <!-- 0.17677669529 /sqrt(2) = 0.12499999999 -->

 <link name="link5">
 <visual>
 <origin xyz="-0.125 -0.17677669529 0.125" rpy= "0.78539816339  -0.78539816339 0"/>
 <geometry>
 <cylinder radius="0.03" length="0.5"/>
 </geometry>
 <material name="brown">
 </material>
 </visual>
 <collision>
 <origin xyz="-0.125 -0.17677669529 0.125" rpy= "0.78539816339  -0.78539816339 0"/>
 <geometry>
 <cylinder radius="0.03" length="0.5"/>
 </geometry>
 </collision> 
 </link>



 <joint name="link6_jointz" type="revolute">
 <safety_controller k_position="100.0" k_velocity="40.0" soft_lower_limit="-2.8973" soft_upper_limit="2.8973"/>
 <parent link="link4z"/>
 <child link="link6"/>
 <origin xyz="0 0 0" rpy="0 0 0"/>
 <axis xyz="0 0 1"/>
 <dynamics damping="10.0"/>
 <limit lower="-3.1416" upper="3.1416" effort="10" velocity="3"/>
 <limit effort="87" lower="-2.9671" upper="2.9671" velocity="2.1750"/>
 </joint> 
 <!-- link -->
 <!-- pi/4 = 0.78539816339 -->
 <!-- 0.25/sqrt(2) = 0.17677669529 -->
 <!-- 0.17677669529 /sqrt(2) = 0.12499999999 -->

 <link name="link6">
 <visual>
 <origin xyz="-0.125 0.17677669529 0.125" rpy= "-0.78539816339  -0.78539816339 0"/>
 <geometry>
 <cylinder radius="0.03" length="0.5"/>
 </geometry>
 <material name="brown">
 </material>
 </visual>
 <collision>
 <origin xyz="-0.125 0.17677669529 0.125" rpy= "-0.78539816339  -0.78539816339 0"/>
 <geometry>
 <cylinder radius="0.03" length="0.5"/>
 </geometry>
 </collision> 
 </link>

 <!-- ============================ layer 3 ============================= -->
 <!-- ================== layer 4-7,8 ============= -->
 
<!-- spherical joint -->
 <!-- <origin xyz="0.125 -0.17677669529 0.125" * 2  -->


 <joint name="link7_jointx" type="revolute">
 <safety_controller k_position="100.0" k_velocity="40.0" soft_lower_limit="-2.8973" soft_upper_limit="2.8973"/>
 <parent link="link4"/>
 <child link="link7x"/>
 <origin xyz="0.25 -0.3535533906 0.25" rpy="0 0 0"/>
 <axis xyz="1 0 0"/>
 <dynamics damping="10.0"/>
 <limit lower="-3.1416" upper="3.1416" effort="10" velocity="3"/>
 <limit effort="87" lower="-2.9671" upper="2.9671" velocity="2.1750"/>
 </joint> 

 <link name="link7x">
 <inertial>
 <mass value="0.001" />
 <inertia ixx="0.001" ixy="0" ixz="0" iyy="0.001" iyz="0" izz="0.001" />
 </inertial> 
 </link>


<joint name="link7_jointy" type="revolute">
 <safety_controller k_position="100.0" k_velocity="40.0" soft_lower_limit="-2.8973" soft_upper_limit="2.8973"/>
 <parent link="link7x"/>
 <child link="link7z"/>
 <origin xyz="0 0 0" rpy="0 0 0"/>
 <axis xyz="0 1 0"/>
 <dynamics damping="10.0"/>
 <limit lower="-3.1416" upper="3.1416" effort="10" velocity="3"/>
 <limit effort="87" lower="-2.9671" upper="2.9671" velocity="2.1750"/>
 </joint> 

 <link name="link7z">
 <inertial>
 <mass value="0.001" />
 <inertia ixx="0.001" ixy="0" ixz="0" iyy="0.001" iyz="0" izz="0.001" />
 </inertial> 
 </link> 

 <joint name="link7_jointz" type="revolute">
 <safety_controller k_position="100.0" k_velocity="40.0" soft_lower_limit="-2.8973" soft_upper_limit="2.8973"/>
 <parent link="link7z"/>
 <child link="link7"/>
 <origin xyz="0 0 0" rpy="0 0 0"/>
 <axis xyz="0 0 1"/>
 <dynamics damping="10.0"/>
 <limit lower="-3.1416" upper="3.1416" effort="10" velocity="3"/>
 <limit effort="87" lower="-2.9671" upper="2.9671" velocity="2.1750"/>
 </joint> 

 <!-- link -->
 <link name="link7">
 <visual>
 <origin xyz="0.125 -0.17677669529 0.125" rpy= "0.78539816339 0.78539816339 0"/>
 <geometry>
 <cylinder radius="0.02" length="0.5"/>
 </geometry>
 <material name="brown">
 </material>
 </visual>
 <collision>
 <origin xyz="0.125 -0.17677669529 0.125" rpy= "0.78539816339 0.78539816339 0"/>
 <geometry>
 <cylinder radius="0.02" length="0.5"/>
 </geometry>
 </collision> 
 </link>

 <!-- fixed joint for leaf -->
 <joint name="link7L" type="fixed">
 <safety_controller k_position="100.0" k_velocity="40.0" soft_lower_limit="-2.8973" soft_upper_limit="2.8973"/>
 <parent link="link7"/>
 <child link="link7_leaf"/>
 <origin xyz="0.25 -0.3535533906 0.25" rpy="0 0 0"/>
 <axis xyz="0 0 1"/>
 <dynamics damping="10.0"/>
 <limit lower="-3.1416" upper="3.1416" effort="10" velocity="3"/>
 <limit effort="87" lower="-2.9671" upper="2.9671" velocity="2.1750"/>
 </joint> 

 <!-- leaf link --> 
 <link name="link7_leaf">
 <visual>
 <origin xyz="0 0 0" rpy="0 0 0"/>
 <geometry>
 <box size=".1 .1 .1"/>
 </geometry>
 <material name="green">
 </material>
 </visual>
 <collision>
 <origin xyz="0 0 0" rpy="0 0 0"/>
 <geometry>
 <box size=".1 .1 .1"/>
 </geometry>
 </collision> 
 </link>


 <joint name="link8_jointz" type="revolute">
 <safety_controller k_position="100.0" k_velocity="40.0" soft_lower_limit="-2.8973" soft_upper_limit="2.8973"/>
 <parent link="link7z"/>
 <child link="link8"/>
 <origin xyz="0 0 0" rpy="0 0 0"/>
 <axis xyz="0 0 1"/>
 <dynamics damping="10.0"/>
 <limit lower="-3.1416" upper="3.1416" effort="10" velocity="3"/>
 <limit effort="87" lower="-2.9671" upper="2.9671" velocity="2.1750"/>
 </joint> 

 <!-- link -->
 
 <link name="link8">
 <visual>
 <origin xyz="0 0 0.25 " rpy= "0 0 0"/>
 <geometry>
 <cylinder radius="0.02" length="0.5"/>
 </geometry>
 <material name="brown">
 </material>
 </visual>
 <collision>
 <origin xyz="0 0 0.25 " rpy= "0 0 0"/>
 <geometry>
 <cylinder radius="0.02" length="0.5"/>
 </geometry>
 </collision> 
 </link>


 <!-- fixed joint for leaf -->
 <joint name="link8L" type="fixed">
 <safety_controller k_position="100.0" k_velocity="40.0" soft_lower_limit="-2.8973" soft_upper_limit="2.8973"/>
 <parent link="link8"/>
 <child link="link8_leaf"/>
 <origin xyz="0 0 0.5" rpy="0 0 0"/>
 <axis xyz="0 0 1"/>
 <dynamics damping="10.0"/>
 <limit lower="-3.1416" upper="3.1416" effort="10" velocity="3"/>
 <limit effort="87" lower="-2.9671" upper="2.9671" velocity="2.1750"/>
 </joint> 


 <!-- leaf link --> 
 <link name="link8_leaf">
 <visual>
 <origin xyz="0 0 0" rpy="0 0 0"/>
 <geometry>
 <box size=".1 .1 .1"/>
 </geometry>
 <material name="green">
 </material>
 </visual>
 <collision>
 <origin xyz="0 0 0" rpy="0 0 0"/>
 <geometry>
 <box size=".1 .1 .1"/>
 </geometry>
 </collision> 
 </link>



 <!-- ================== layer 5-9,10 ============= -->
 
<!-- spherical joint -->
<!-- "-0.125 -0.17677669529 0.125" *2  -->
 <joint name="link9_jointx" type="revolute">
 <safety_controller k_position="100.0" k_velocity="40.0" soft_lower_limit="-2.8973" soft_upper_limit="2.8973"/>
 <parent link="link5"/>
 <child link="link9x"/>
 <origin xyz="-0.25 -0.35355339058  0.25" rpy="0 0 0"/>
 <axis xyz="1 0 0"/>
 <dynamics damping="10.0"/>
 <limit lower="-3.1416" upper="3.1416" effort="10" velocity="3"/>
 <limit effort="87" lower="-2.9671" upper="2.9671" velocity="2.1750"/>
 </joint> 



 <link name="link9x">
 <inertial>
 <mass value="0.001" />
 <inertia ixx="0.001" ixy="0" ixz="0" iyy="0.001" iyz="0" izz="0.001" />
 </inertial> 
 </link>

<joint name="link9_jointy" type="revolute">
 <safety_controller k_position="100.0" k_velocity="40.0" soft_lower_limit="-2.8973" soft_upper_limit="2.8973"/>
 <parent link="link9x"/>
 <child link="link9z"/>
 <origin xyz="0 0 0" rpy="0 0 0"/>
 <axis xyz="0 1 0"/>
 <dynamics damping="10.0"/>
 <limit lower="-3.1416" upper="3.1416" effort="10" velocity="3"/>
 <limit effort="87" lower="-2.9671" upper="2.9671" velocity="2.1750"/>
 </joint> 

 <link name="link9z">
 <inertial>
 <mass value="0.001" />
 <inertia ixx="0.001" ixy="0" ixz="0" iyy="0.001" iyz="0" izz="0.001" />
 </inertial> 
 </link> 

 <joint name="link9_jointz" type="revolute">
 <safety_controller k_position="100.0" k_velocity="40.0" soft_lower_limit="-2.8973" soft_upper_limit="2.8973"/>
 <parent link="link9z"/>
 <child link="link9"/>
 <origin xyz="0 0 0" rpy="0 0 0"/>
 <axis xyz="0 0 1"/>
 <dynamics damping="10.0"/>
 <limit lower="-3.1416" upper="3.1416" effort="10" velocity="3"/>
 <limit effort="87" lower="-2.9671" upper="2.9671" velocity="2.1750"/>
 </joint> 

 <!-- link -->
 
<link name="link9">
 <visual>
 <origin xyz="-0.125 -0.17677669529 0.125" rpy= "0.78539816339 -0.78539816339 0"/>
 <geometry>
 <cylinder radius="0.02" length="0.5"/>
 </geometry>
 <material name="brown">
 </material>
 </visual>
 <collision>
 <origin xyz="-0.125 -0.17677669529 0.125" rpy= "0.78539816339 -0.78539816339 0"/>
 <geometry>
 <cylinder radius="0.04" length="0.5"/>
 </geometry>
 </collision> 
 </link>

<!-- fixed joint for leaf -->
 <joint name="link9L" type="fixed">
 <safety_controller k_position="100.0" k_velocity="40.0" soft_lower_limit="-2.8973" soft_upper_limit="2.8973"/>
 <parent link="link9"/>
 <child link="link9_leaf"/>
 <origin xyz="-0.25 -0.35355339058  0.25" rpy="0 0 0"/>
 <axis xyz="0 0 1"/>
 <dynamics damping="10.0"/>
 <limit lower="-3.1416" upper="3.1416" effort="10" velocity="3"/>
 <limit effort="87" lower="-2.9671" upper="2.9671" velocity="2.1750"/>
 </joint> 


 <!-- leaf link --> 
 <link name="link9_leaf">
 <visual>
 <origin xyz="0 0 0" rpy="0 0 0"/>
 <geometry>
 <box size=".1 .1 .1"/>
 </geometry>
 <material name="green">
 </material>
 </visual>
 <collision>
 <origin xyz="0 0 0" rpy="0 0 0"/>
 <geometry>
 <box size=".1 .1 .1"/>
 </geometry>
 </collision> 
 </link>



 <joint name="link10_jointz" type="revolute">
 <safety_controller k_position="100.0" k_velocity="40.0" soft_lower_limit="-2.8973" soft_upper_limit="2.8973"/>
 <parent link="link9z"/>
 <child link="link10"/>
 <origin xyz="0 0 0" rpy="0 0 0"/>
 <axis xyz="0 0 1"/>
 <dynamics damping="10.0"/>
 <limit lower="-3.1416" upper="3.1416" effort="10" velocity="3"/>
 <limit effort="87" lower="-2.9671" upper="2.9671" velocity="2.1750"/>
 </joint> 

 <!-- link -->
 
 <link name="link10">
 <visual>
 <origin xyz="0 0 0.25 " rpy= "0 0 0"/>
 <geometry>
 <cylinder radius="0.02" length="0.5"/>
 </geometry>
 <material name="brown">
 </material>
 </visual>
 <collision>
 <origin xyz="0 0 0.25 " rpy= "0 0 0"/>
 <geometry>
 <cylinder radius="0.02" length="0.5"/>
 </geometry>
 </collision> 
 </link>


 <!-- fixed joint for leaf -->
 <joint name="link10L" type="fixed">
 <safety_controller k_position="100.0" k_velocity="40.0" soft_lower_limit="-2.8973" soft_upper_limit="2.8973"/>
 <parent link="link10"/>
 <child link="link10_leaf"/>
 <origin xyz="0 0 0.5" rpy="0 0 0"/>
 <axis xyz="0 0 1"/>
 <dynamics damping="10.0"/>
 <limit lower="-3.1416" upper="3.1416" effort="10" velocity="3"/>
 <limit effort="87" lower="-2.9671" upper="2.9671" velocity="2.1750"/>
 </joint> 

 <!-- leaf link --> 
 <link name="link10_leaf">
 <visual>
 <origin xyz="0 0 0" rpy="0 0 0"/>
 <geometry>
 <box size=".1 .1 .1"/>
 </geometry>
 <material name="green">
 </material>
 </visual>
 <collision>
 <origin xyz="0 0 0" rpy="0 0 0"/>
 <geometry>
 <box size=".1 .1 .1"/>
 </geometry>
 </collision> 
 </link>


<!-- ================== layer 6-11,12 ============= -->
 
<!-- spherical joint -->
<!-- -0.125 0.17677669529 0.125 * 2 -->

 <joint name="link11_jointx" type="revolute">
 <safety_controller k_position="100.0" k_velocity="40.0" soft_lower_limit="-2.8973" soft_upper_limit="2.8973"/>
 <parent link="link6"/>
 <child link="link11x"/>
 <origin xyz="-0.25 0.35355339058 0.25" rpy="0 0 0"/>
 <axis xyz="1 0 0"/>
 <dynamics damping="10.0"/>
 <limit lower="-3.1416" upper="3.1416" effort="10" velocity="3"/>
 <limit effort="87" lower="-2.9671" upper="2.9671" velocity="2.1750"/>
 </joint> 


 <link name="link11x">
 <inertial>
 <mass value="0.001" />
 <inertia ixx="0.001" ixy="0" ixz="0" iyy="0.001" iyz="0" izz="0.001" />
 </inertial> 
 </link>

<joint name="link11_jointy" type="revolute">
 <safety_controller k_position="100.0" k_velocity="40.0" soft_lower_limit="-2.8973" soft_upper_limit="2.8973"/>
 <parent link="link11x"/>
 <child link="link11z"/>
 <origin xyz="0 0 0" rpy="0 0 0"/>
 <axis xyz="0 1 0"/>
 <dynamics damping="10.0"/>
 <limit lower="-3.1416" upper="3.1416" effort="10" velocity="3"/>
 <limit effort="87" lower="-2.9671" upper="2.9671" velocity="2.1750"/>
 </joint> 

 <link name="link11z">
 <inertial>
 <mass value="0.001" />
 <inertia ixx="0.001" ixy="0" ixz="0" iyy="0.001" iyz="0" izz="0.001" />
 </inertial> 
 </link> 

 <joint name="link11_jointz" type="revolute">
 <safety_controller k_position="100.0" k_velocity="40.0" soft_lower_limit="-2.8973" soft_upper_limit="2.8973"/>
 <parent link="link11z"/>
 <child link="link11"/>
 <origin xyz="0 0 0" rpy="0 0 0"/>
 <axis xyz="0 0 1"/>
 <dynamics damping="10.0"/>
 <limit lower="-3.1416" upper="3.1416" effort="10" velocity="3"/>
 <limit effort="87" lower="-2.9671" upper="2.9671" velocity="2.1750"/>
 </joint> 

 <!-- link -->


 <link name="link11">
 <visual>
 <origin xyz="-0.125 0.17677669529 0.125" rpy= "-0.78539816339 -0.78539816339 0"/>
 <geometry>
 <cylinder radius="0.02" length="0.5"/>
 </geometry>
 <material name="brown">
 </material>
 </visual>
 <collision>
 <origin xyz="-0.125 0.17677669529 0.125" rpy= "-0.78539816339 -0.78539816339 0"/>
 <geometry>
 <cylinder radius="0.02" length="0.5"/>
 </geometry>
 </collision> 
 </link>


 <!-- fixed joint for leaf -->
 <joint name="link11L" type="fixed">
 <safety_controller k_position="100.0" k_velocity="40.0" soft_lower_limit="-2.8973" soft_upper_limit="2.8973"/>
 <parent link="link11"/>
 <child link="link11_leaf"/>
 <origin xyz="-0.25 0.35355339058 0.25" rpy="0 0 0"/>
 <axis xyz="0 0 1"/>
 <dynamics damping="10.0"/>
 <limit lower="-3.1416" upper="3.1416" effort="10" velocity="3"/>
 <limit effort="87" lower="-2.9671" upper="2.9671" velocity="2.1750"/>
 </joint> 



 <!-- leaf link --> 
 <link name="link11_leaf">
 <visual>
 <origin xyz="0 0 0" rpy="0 0 0"/>
 <geometry>
 <box size=".1 .1 .1"/>
 </geometry>
 <material name="green">
 </material>
 </visual>
 <collision>
 <origin xyz="0 0 0" rpy="0 0 0"/>
 <geometry>
 <box size=".1 .1 .1"/>
 </geometry>
 </collision> 
 </link>


 <joint name="link12_jointz" type="revolute">
 <safety_controller k_position="100.0" k_velocity="40.0" soft_lower_limit="-2.8973" soft_upper_limit="2.8973"/>
 <parent link="link11z"/>
 <child link="link12"/>
 <origin xyz="0 0 0" rpy="0 0 0"/>
 <axis xyz="0 0 1"/>
 <dynamics damping="10.0"/>
 <limit lower="-3.1416" upper="3.1416" effort="10" velocity="3"/>
 <limit effort="87" lower="-2.9671" upper="2.9671" velocity="2.1750"/>
 </joint> 

 <!-- link -->
 
 <link name="link12">
 <visual>
 <origin xyz="0 0 0.25 " rpy= "0 0 0"/>
 <geometry>
 <cylinder radius="0.02" length="0.5"/>
 </geometry>
 <material name="brown">
 </material>
 </visual>
 <collision>
 <origin xyz="0 0 0.25 " rpy= "0 0 0"/>
 <geometry>
 <cylinder radius="0.04" length="0.5"/>
 </geometry>
 </collision> 
 </link>

 <!-- fixed joint for leaf -->
 <joint name="link12L" type="fixed">
 <safety_controller k_position="100.0" k_velocity="40.0" soft_lower_limit="-2.8973" soft_upper_limit="2.8973"/>
 <parent link="link12"/>
 <child link="link12_leaf"/>
 <origin xyz="0 0 0.5" rpy="0 0 0"/>
 <axis xyz="0 0 1"/>
 <dynamics damping="10.0"/>
 <limit lower="-3.1416" upper="3.1416" effort="10" velocity="3"/>
 <limit effort="87" lower="-2.9671" upper="2.9671" velocity="2.1750"/>
 </joint> 

 <!-- leaf link --> 
 <link name="link12_leaf">
 <visual>
 <origin xyz="0 0 0" rpy="0 0 0"/>
 <geometry>
 <box size=".1 .1 .1"/>
 </geometry>
 <material name="green">
 </material>
 </visual>
 <collision>
 <origin xyz="0 0 0" rpy="0 0 0"/>
 <geometry>
 <box size=".1 .1 .1"/>
 </geometry>
 </collision> 
 </link>

</robot>

